{"asctime": "2024-05-20 T17:45:46+0530", "message": "An Error Occured ..", "exc_info": "Traceback (most recent call last):\n  File \"C:\\Celebal data\\Telecom Egypt\\fastapi\\Telecom%20Egypt%20Internal\\main.py\", line 563, in create_excel_for_powerbi\n    result_for_one_audio, arabic_result_for_one_audio = self.powerbi_report_keyword(powerbi_merged_jsonPath=powerbi_merged_path, audio_file=calls)\n    ^^^^^^^^^^^^^^^^^^^^^^^^^^^^^^^^^^^^^^^^^^^^^^^^^\nTypeError: cannot unpack non-iterable NoneType object", "location": "main.py-create_excel_for_powerbi"}
{"asctime": "2024-05-23 T18:26:40+0530", "message": "An Error Occured ..", "exc_info": "Traceback (most recent call last):\n  File \"C:\\Celebal data\\Telecom Egypt\\fastapi\\Telecom%20Egypt%20Internal\\src\\audio\\audio.py\", line 45, in audio_processing\n    sound = AudioSegment.from_mp3(input_path)\n            ^^^^^^^^^^^^^^^^^^^^^^^^^^^^^^^^^\n  File \"C:\\Celebal data\\Telecom Egypt\\fastapi\\Telecom%20Egypt%20Internal\\tel_venv\\Lib\\site-packages\\pydub\\audio_segment.py\", line 796, in from_mp3\n    return cls.from_file(file, 'mp3', parameters=parameters)\n           ^^^^^^^^^^^^^^^^^^^^^^^^^^^^^^^^^^^^^^^^^^^^^^^^^\n  File \"C:\\Celebal data\\Telecom Egypt\\fastapi\\Telecom%20Egypt%20Internal\\tel_venv\\Lib\\site-packages\\pydub\\audio_segment.py\", line 773, in from_file\n    raise CouldntDecodeError(\npydub.exceptions.CouldntDecodeError: Decoding failed. ffmpeg returned error code: 4294967295\n\nOutput from ffmpeg/avlib:\n\nffmpeg version 6.1.1-essentials_build-www.gyan.dev Copyright (c) 2000-2023 the FFmpeg developers\r\n  built with gcc 12.2.0 (Rev10, Built by MSYS2 project)\r\n  configuration: --enable-gpl --enable-version3 --enable-static --pkg-config=pkgconf --disable-w32threads --disable-autodetect --enable-fontconfig --enable-iconv --enable-gnutls --enable-libxml2 --enable-gmp --enable-bzlib --enable-lzma --enable-zlib --enable-libsrt --enable-libssh --enable-libzmq --enable-avisynth --enable-sdl2 --enable-libwebp --enable-libx264 --enable-libx265 --enable-libxvid --enable-libaom --enable-libopenjpeg --enable-libvpx --enable-mediafoundation --enable-libass --enable-libfreetype --enable-libfribidi --enable-libharfbuzz --enable-libvidstab --enable-libvmaf --enable-libzimg --enable-amf --enable-cuda-llvm --enable-cuvid --enable-ffnvcodec --enable-nvdec --enable-nvenc --enable-dxva2 --enable-d3d11va --enable-libvpl --enable-libgme --enable-libopenmpt --enable-libopencore-amrwb --enable-libmp3lame --enable-libtheora --enable-libvo-amrwbenc --enable-libgsm --enable-libopencore-amrnb --enable-libopus --enable-libspeex --enable-libvorbis --enable-librubberband\r\n  libavutil      58. 29.100 / 58. 29.100\r\n  libavcodec     60. 31.102 / 60. 31.102\r\n  libavformat    60. 16.100 / 60. 16.100\r\n  libavdevice    60.  3.100 / 60.  3.100\r\n  libavfilter     9. 12.100 /  9. 12.100\r\n  libswscale      7.  5.100 /  7.  5.100\r\n  libswresample   4. 12.100 /  4. 12.100\r\n  libpostproc    57.  3.100 / 57.  3.100\r\n[mp3 @ 00000220a76f67c0] Estimating duration from bitrate, this may be inaccurate\r\nInput #0, mp3, from 'C:\\Celebal data\\Telecom Egypt\\fastapi\\Telecom%20Egypt%20Internal/data/raw_data/Call 3.mp3':\r\n  Duration: 00:01:26.44, start: 0.000000, bitrate: 24 kb/s\r\n  Stream #0:0: Audio: mp3, 16000 Hz, stereo, fltp, 24 kb/s\r\nStream mapping:\r\n  Stream #0:0 -> #0:0 (mp3 (mp3float) -> pcm_s16le (native))\r\nPress [q] to stop, [?] for help\r\n\r\nEnter command: <target>|all <time>|-1 <command>[ <argument>]\r\n", "location": "audio.py - audio_processing"}
{"asctime": "2024-05-23 T18:26:40+0530", "message": "An Error Occured ..", "exc_info": "Traceback (most recent call last):\n  File \"C:\\Celebal data\\Telecom Egypt\\fastapi\\Telecom%20Egypt%20Internal\\tel_venv\\Lib\\site-packages\\mutagen\\_util.py\", line 251, in _openfile\n    fileobj = open(filename, \"rb+\" if writable else \"rb\")\n              ^^^^^^^^^^^^^^^^^^^^^^^^^^^^^^^^^^^^^^^^^^^\nFileNotFoundError: [Errno 2] No such file or directory: 'C:\\\\Celebal data\\\\Telecom Egypt\\\\fastapi\\\\Telecom%20Egypt%20Internal/data/processed_data/Call 3.wav'\n\nDuring handling of the above exception, another exception occurred:\n\nTraceback (most recent call last):\n  File \"C:\\Celebal data\\Telecom Egypt\\fastapi\\Telecom%20Egypt%20Internal\\main.py\", line 39, in add_to_mapping\n    audio_atrs = get_audio_attrs_for_report(audio_path=audio_file_path)\n                 ^^^^^^^^^^^^^^^^^^^^^^^^^^^^^^^^^^^^^^^^^^^^^^^^^^^^^^\n  File \"C:\\Celebal data\\Telecom Egypt\\fastapi\\Telecom%20Egypt%20Internal\\src\\audio\\audio.py\", line 120, in get_audio_attrs_for_report\n    duration = get_audio_duration_in_seconds(path= audio_path)\n               ^^^^^^^^^^^^^^^^^^^^^^^^^^^^^^^^^^^^^^^^^^^^^^^\n  File \"C:\\Celebal data\\Telecom Egypt\\fastapi\\Telecom%20Egypt%20Internal\\src\\audio\\audio.py\", line 87, in get_audio_duration_in_seconds\n    audio = WAVE(path)\n           ^^^^^^^^^^\n  File \"C:\\Celebal data\\Telecom Egypt\\fastapi\\Telecom%20Egypt%20Internal\\tel_venv\\Lib\\site-packages\\mutagen\\_file.py\", line 48, in __init__\n    self.load(*args, **kwargs)\n  File \"C:\\Celebal data\\Telecom Egypt\\fastapi\\Telecom%20Egypt%20Internal\\tel_venv\\Lib\\site-packages\\mutagen\\_util.py\", line 185, in wrapper\n    return func(*args, **kwargs)\n           ^^^^^^^^^^^^^^^^^^^^^\n  File \"C:\\Celebal data\\Telecom Egypt\\fastapi\\Telecom%20Egypt%20Internal\\tel_venv\\Lib\\site-packages\\mutagen\\_util.py\", line 154, in wrapper\n    with _openfile(self, filething, filename, fileobj,\n  File \"C:\\Users\\MaharshiJasraj\\AppData\\Local\\Programs\\Python\\Python311\\Lib\\contextlib.py\", line 137, in __enter__\n    return next(self.gen)\n           ^^^^^^^^^^^^^^\n  File \"C:\\Celebal data\\Telecom Egypt\\fastapi\\Telecom%20Egypt%20Internal\\tel_venv\\Lib\\site-packages\\mutagen\\_util.py\", line 272, in _openfile\n    raise MutagenError(e)\nmutagen.MutagenError: [Errno 2] No such file or directory: 'C:\\\\Celebal data\\\\Telecom Egypt\\\\fastapi\\\\Telecom%20Egypt%20Internal/data/processed_data/Call 3.wav'", "location": "main.py - add_to_mapping"}
{"asctime": "2024-05-23 T18:26:40+0530", "message": "An Error Occured ..", "exc_info": "Traceback (most recent call last):\n  File \"C:\\Celebal data\\Telecom Egypt\\fastapi\\Telecom%20Egypt%20Internal\\src\\adapters\\transcription.py\", line 45, in recognize_from_file\n    conversation_transcriber = speechsdk.transcription.ConversationTranscriber(speech_config=speech_config, audio_config=audio_config)\n                               ^^^^^^^^^^^^^^^^^^^^^^^^^^^^^^^^^^^^^^^^^^^^^^^^^^^^^^^^^^^^^^^^^^^^^^^^^^^^^^^^^^^^^^^^^^^^^^^^^^^^^^^\n  File \"C:\\Celebal data\\Telecom Egypt\\fastapi\\Telecom%20Egypt%20Internal\\tel_venv\\Lib\\site-packages\\azure\\cognitiveservices\\speech\\transcription.py\", line 136, in __init__\n    _call_hr_fn(\n  File \"C:\\Celebal data\\Telecom Egypt\\fastapi\\Telecom%20Egypt%20Internal\\tel_venv\\Lib\\site-packages\\azure\\cognitiveservices\\speech\\interop.py\", line 62, in _call_hr_fn\n    _raise_if_failed(hr)\n  File \"C:\\Celebal data\\Telecom Egypt\\fastapi\\Telecom%20Egypt%20Internal\\tel_venv\\Lib\\site-packages\\azure\\cognitiveservices\\speech\\interop.py\", line 55, in _raise_if_failed\n    __try_get_error(_spx_handle(hr))\n  File \"C:\\Celebal data\\Telecom Egypt\\fastapi\\Telecom%20Egypt%20Internal\\tel_venv\\Lib\\site-packages\\azure\\cognitiveservices\\speech\\interop.py\", line 50, in __try_get_error\n    raise RuntimeError(message)\nRuntimeError: Exception with error code: \n[CALL STACK BEGIN]\n\n    > pal_string_to_wstring\n    - pal_string_to_wstring\n    - pal_string_to_wstring\n    - pal_string_to_wstring\n    - pal_string_to_wstring\n    - pal_string_to_wstring\n    - pal_string_to_wstring\n    - pal_string_to_wstring\n    - pal_string_to_wstring\n    - pal_string_to_wstring\n    - pal_string_to_wstring\n    - pal_string_to_wstring\n    - pal_string_to_wstring\n    - pal_string_to_wstring\n    - pal_string_to_wstring\n    - recognizer_create_speech_recognizer_from_config\n\n[CALL STACK END]\n\nException with an error code: 0x8 (SPXERR_FILE_OPEN_FAILED)", "location": "transcription.py - recognize_from_file"}
{"asctime": "2024-05-23 T18:26:40+0530", "message": "An Error Occured ..", "exc_info": "Traceback (most recent call last):\n  File \"C:\\Celebal data\\Telecom Egypt\\fastapi\\Telecom%20Egypt%20Internal\\src\\adapters\\translator.py\", line 76, in get_translated_transcriptions\n    with open(transcription_jsonPath, 'r', encoding='utf-8') as file:\n         ^^^^^^^^^^^^^^^^^^^^^^^^^^^^^^^^^^^^^^^^^^^^^^^^^^^\nFileNotFoundError: [Errno 2] No such file or directory: 'C:\\\\Celebal data\\\\Telecom Egypt\\\\fastapi\\\\Telecom%20Egypt%20Internal/data/audio_analytics/Call 3/transcript_output.json'", "location": "main.py - get_translated_transcriptions"}
{"asctime": "2024-05-23 T18:26:40+0530", "message": "An Error Occured: expected str, bytes or os.PathLike object, not NoneType", "exc_info": "Traceback (most recent call last):\n  File \"C:\\Celebal data\\Telecom Egypt\\fastapi\\Telecom%20Egypt%20Internal\\main.py\", line 147, in get_kpis\n    with open(transcription_jsonPath, \"r\", encoding=\"utf-8\") as fp:\n         ^^^^^^^^^^^^^^^^^^^^^^^^^^^^^^^^^^^^^^^^^^^^^^^^^^^\nTypeError: expected str, bytes or os.PathLike object, not NoneType", "location": "main.py - pipeline_after_transcription"}
{"asctime": "2024-05-23 T18:26:40+0530", "message": "An Error Occured: 'NoneType' object is not subscriptable", "exc_info": "Traceback (most recent call last):\n  File \"C:\\Celebal data\\Telecom Egypt\\fastapi\\Telecom%20Egypt%20Internal\\main.py\", line 233, in pipeline_after_transcription\n    merged_output[\"result\"][\"summary\"] = result[\"summary\"]\n                                         ~~~~~~^^^^^^^^^^^\nTypeError: 'NoneType' object is not subscriptable", "location": "main.py - pipeline_after_transcription"}
