{"asctime": "2024-06-08 T15:00:36+0530", "message": "An Error Occured: 'NoneType' object is not subscriptable", "exc_info": "Traceback (most recent call last):\n  File \"C:\\Celebal data\\Clients\\Telecom Egypt\\Extract summary\\summary_pipeline\\main.py\", line 304, in pipeline_after_transcription\n    merged_output[\"result\"][\"summary\"] = result[\"summary\"]\n                                         ~~~~~~^^^^^^^^^^^\nTypeError: 'NoneType' object is not subscriptable", "location": "main.py - pipeline_after_transcription"}{"asctime": "2024-06-08 T15:39:35+0530", "message": "An Error Occured ..", "exc_info": "Traceback (most recent call last):\n  File \"C:\\Users\\AnshulBhardwaj\\Desktop\\telecomnew\\Telecom%20Egypt%20Internal\\src\\audio\\audio.py\", line 45, in audio_processing\n    sound = AudioSegment.from_mp3(input_path)\n            ^^^^^^^^^^^^^^^^^^^^^^^^^^^^^^^^^\n  File \"C:\\Users\\AnshulBhardwaj\\Desktop\\telecomnew\\Telecom%20Egypt%20Internal\\venv\\Lib\\site-packages\\pydub\\audio_segment.py\", line 796, in from_mp3\n    return cls.from_file(file, 'mp3', parameters=parameters)\n           ^^^^^^^^^^^^^^^^^^^^^^^^^^^^^^^^^^^^^^^^^^^^^^^^^\n  File \"C:\\Users\\AnshulBhardwaj\\Desktop\\telecomnew\\Telecom%20Egypt%20Internal\\venv\\Lib\\site-packages\\pydub\\audio_segment.py\", line 651, in from_file\n    file, close_file = _fd_or_path_or_tempfile(file, 'rb', tempfile=False)\n                       ^^^^^^^^^^^^^^^^^^^^^^^^^^^^^^^^^^^^^^^^^^^^^^^^^^^\n  File \"C:\\Users\\AnshulBhardwaj\\Desktop\\telecomnew\\Telecom%20Egypt%20Internal\\venv\\Lib\\site-packages\\pydub\\utils.py\", line 60, in _fd_or_path_or_tempfile\n    fd = open(fd, mode=mode)\n         ^^^^^^^^^^^^^^^^^^^\nFileNotFoundError: [Errno 2] No such file or directory: 'C:\\\\Users\\\\AnshulBhardwaj\\\\Desktop\\\\telecomnew\\\\Telecom%20Egypt%20Internal/source/calls/dir2/160588653.wav'", "location": "audio.py - audio_processing"}
{"asctime": "2024-06-08 T15:39:35+0530", "message": "An Error Occured ..", "exc_info": "Traceback (most recent call last):\n  File \"C:\\Users\\AnshulBhardwaj\\Desktop\\telecomnew\\Telecom%20Egypt%20Internal\\venv\\Lib\\site-packages\\mutagen\\_util.py\", line 251, in _openfile\n    fileobj = open(filename, \"rb+\" if writable else \"rb\")\n              ^^^^^^^^^^^^^^^^^^^^^^^^^^^^^^^^^^^^^^^^^^^\nFileNotFoundError: [Errno 2] No such file or directory: 'C:\\\\Users\\\\AnshulBhardwaj\\\\Desktop\\\\telecomnew\\\\Telecom%20Egypt%20Internal/data/processed_data/160588653.wav'\n\nDuring handling of the above exception, another exception occurred:\n\nTraceback (most recent call last):\n  File \"C:\\Users\\AnshulBhardwaj\\Desktop\\telecomnew\\Telecom%20Egypt%20Internal\\main.py\", line 41, in add_to_mapping\n    audio_atrs = get_audio_attrs_for_report(audio_path=audio_file_path)\n                 ^^^^^^^^^^^^^^^^^^^^^^^^^^^^^^^^^^^^^^^^^^^^^^^^^^^^^^\n  File \"C:\\Users\\AnshulBhardwaj\\Desktop\\telecomnew\\Telecom%20Egypt%20Internal\\src\\audio\\audio.py\", line 125, in get_audio_attrs_for_report\n    duration = get_audio_duration_in_seconds(path= audio_path)\n               ^^^^^^^^^^^^^^^^^^^^^^^^^^^^^^^^^^^^^^^^^^^^^^^\n  File \"C:\\Users\\AnshulBhardwaj\\Desktop\\telecomnew\\Telecom%20Egypt%20Internal\\src\\audio\\audio.py\", line 90, in get_audio_duration_in_seconds\n    audio = WAVE(path)\n           ^^^^^^^^^^\n  File \"C:\\Users\\AnshulBhardwaj\\Desktop\\telecomnew\\Telecom%20Egypt%20Internal\\venv\\Lib\\site-packages\\mutagen\\_file.py\", line 48, in __init__\n    self.load(*args, **kwargs)\n  File \"C:\\Users\\AnshulBhardwaj\\Desktop\\telecomnew\\Telecom%20Egypt%20Internal\\venv\\Lib\\site-packages\\mutagen\\_util.py\", line 185, in wrapper\n    return func(*args, **kwargs)\n           ^^^^^^^^^^^^^^^^^^^^^\n  File \"C:\\Users\\AnshulBhardwaj\\Desktop\\telecomnew\\Telecom%20Egypt%20Internal\\venv\\Lib\\site-packages\\mutagen\\_util.py\", line 154, in wrapper\n    with _openfile(self, filething, filename, fileobj,\n  File \"C:\\Users\\AnshulBhardwaj\\AppData\\Local\\Programs\\Python\\Python311\\Lib\\contextlib.py\", line 137, in __enter__\n    return next(self.gen)\n           ^^^^^^^^^^^^^^\n  File \"C:\\Users\\AnshulBhardwaj\\Desktop\\telecomnew\\Telecom%20Egypt%20Internal\\venv\\Lib\\site-packages\\mutagen\\_util.py\", line 272, in _openfile\n    raise MutagenError(e)\nmutagen.MutagenError: [Errno 2] No such file or directory: 'C:\\\\Users\\\\AnshulBhardwaj\\\\Desktop\\\\telecomnew\\\\Telecom%20Egypt%20Internal/data/processed_data/160588653.wav'", "location": "main.py - add_to_mapping"}
{"asctime": "2024-06-08 T15:39:35+0530", "message": "An Error Occured ..", "exc_info": "Traceback (most recent call last):\n  File \"C:\\Users\\AnshulBhardwaj\\Desktop\\telecomnew\\Telecom%20Egypt%20Internal\\src\\adapters\\transcription.py\", line 44, in recognize_from_file\n    conversation_transcriber = speechsdk.transcription.ConversationTranscriber(speech_config=speech_config, audio_config=audio_config)\n                               ^^^^^^^^^^^^^^^^^^^^^^^^^^^^^^^^^^^^^^^^^^^^^^^^^^^^^^^^^^^^^^^^^^^^^^^^^^^^^^^^^^^^^^^^^^^^^^^^^^^^^^^\n  File \"C:\\Users\\AnshulBhardwaj\\Desktop\\telecomnew\\Telecom%20Egypt%20Internal\\venv\\Lib\\site-packages\\azure\\cognitiveservices\\speech\\transcription.py\", line 136, in __init__\n    _call_hr_fn(\n  File \"C:\\Users\\AnshulBhardwaj\\Desktop\\telecomnew\\Telecom%20Egypt%20Internal\\venv\\Lib\\site-packages\\azure\\cognitiveservices\\speech\\interop.py\", line 62, in _call_hr_fn\n    _raise_if_failed(hr)\n  File \"C:\\Users\\AnshulBhardwaj\\Desktop\\telecomnew\\Telecom%20Egypt%20Internal\\venv\\Lib\\site-packages\\azure\\cognitiveservices\\speech\\interop.py\", line 55, in _raise_if_failed\n    __try_get_error(_spx_handle(hr))\n  File \"C:\\Users\\AnshulBhardwaj\\Desktop\\telecomnew\\Telecom%20Egypt%20Internal\\venv\\Lib\\site-packages\\azure\\cognitiveservices\\speech\\interop.py\", line 50, in __try_get_error\n    raise RuntimeError(message)\nRuntimeError: Exception with error code: \n[CALL STACK BEGIN]\n\n    > pal_string_to_wstring\n    - pal_string_to_wstring\n    - pal_string_to_wstring\n    - pal_string_to_wstring\n    - pal_string_to_wstring\n    - pal_string_to_wstring\n    - pal_string_to_wstring\n    - pal_string_to_wstring\n    - pal_string_to_wstring\n    - pal_string_to_wstring\n    - pal_string_to_wstring\n    - pal_string_to_wstring\n    - pal_string_to_wstring\n    - pal_string_to_wstring\n    - pal_string_to_wstring\n    - recognizer_create_speech_recognizer_from_config\n\n[CALL STACK END]\n\nException with an error code: 0x8 (SPXERR_FILE_OPEN_FAILED)", "location": "transcription.py - recognize_from_file"}
{"asctime": "2024-06-08 T15:39:35+0530", "message": "An Error Occured ..", "exc_info": "Traceback (most recent call last):\n  File \"C:\\Users\\AnshulBhardwaj\\Desktop\\telecomnew\\Telecom%20Egypt%20Internal\\src\\adapters\\translator.py\", line 75, in get_translated_transcriptions\n    with open(transcription_jsonPath, 'r', encoding='utf-8') as file:\n         ^^^^^^^^^^^^^^^^^^^^^^^^^^^^^^^^^^^^^^^^^^^^^^^^^^^\nFileNotFoundError: [Errno 2] No such file or directory: 'C:\\\\Users\\\\AnshulBhardwaj\\\\Desktop\\\\telecomnew\\\\Telecom%20Egypt%20Internal/data/audio_analytics/160588653/transcript_output.json'", "location": "main.py - get_translated_transcriptions"}
{"asctime": "2024-06-08 T15:39:35+0530", "message": "An Error Occured: expected str, bytes or os.PathLike object, not NoneType", "exc_info": "Traceback (most recent call last):\n  File \"C:\\Users\\AnshulBhardwaj\\Desktop\\telecomnew\\Telecom%20Egypt%20Internal\\main.py\", line 183, in get_kpis\n    with open(transcription_jsonPath, \"r\", encoding=\"utf-8\") as fp:\n         ^^^^^^^^^^^^^^^^^^^^^^^^^^^^^^^^^^^^^^^^^^^^^^^^^^^\nTypeError: expected str, bytes or os.PathLike object, not NoneType", "location": "main.py - pipeline_after_transcription"}
{"asctime": "2024-06-08 T15:39:35+0530", "message": "An Error Occured: [Errno 2] No such file or directory: 'C:\\\\Users\\\\AnshulBhardwaj\\\\Desktop\\\\telecomnew\\\\Telecom%20Egypt%20Internal/data/audio_analytics/160588653/transcript_output.json'", "exc_info": "Traceback (most recent call last):\n  File \"C:\\Users\\AnshulBhardwaj\\Desktop\\telecomnew\\Telecom%20Egypt%20Internal\\main.py\", line 229, in get_kpis_arabic\n    with open(transciption_jsonpath_arabic, \"r\", encoding=\"utf-8\") as fp:\n         ^^^^^^^^^^^^^^^^^^^^^^^^^^^^^^^^^^^^^^^^^^^^^^^^^^^^^^^^^\nFileNotFoundError: [Errno 2] No such file or directory: 'C:\\\\Users\\\\AnshulBhardwaj\\\\Desktop\\\\telecomnew\\\\Telecom%20Egypt%20Internal/data/audio_analytics/160588653/transcript_output.json'", "location": "main.py - pipeline_after_transcription"}
{"asctime": "2024-06-08 T15:39:35+0530", "message": "An Error Occured: 'NoneType' object is not subscriptable", "exc_info": "Traceback (most recent call last):\n  File \"C:\\Users\\AnshulBhardwaj\\Desktop\\telecomnew\\Telecom%20Egypt%20Internal\\main.py\", line 304, in pipeline_after_transcription\n    merged_output[\"result\"][\"summary\"] = result[\"summary\"]\n                                         ~~~~~~^^^^^^^^^^^\nTypeError: 'NoneType' object is not subscriptable", "location": "main.py - pipeline_after_transcription"}
{"asctime": "2024-06-08 T15:39:35+0530", "message": "An Error Occured ..", "exc_info": "Traceback (most recent call last):\n  File \"C:\\Users\\AnshulBhardwaj\\Desktop\\telecomnew\\Telecom%20Egypt%20Internal\\src\\audio\\audio.py\", line 45, in audio_processing\n    sound = AudioSegment.from_mp3(input_path)\n            ^^^^^^^^^^^^^^^^^^^^^^^^^^^^^^^^^\n  File \"C:\\Users\\AnshulBhardwaj\\Desktop\\telecomnew\\Telecom%20Egypt%20Internal\\venv\\Lib\\site-packages\\pydub\\audio_segment.py\", line 796, in from_mp3\n    return cls.from_file(file, 'mp3', parameters=parameters)\n           ^^^^^^^^^^^^^^^^^^^^^^^^^^^^^^^^^^^^^^^^^^^^^^^^^\n  File \"C:\\Users\\AnshulBhardwaj\\Desktop\\telecomnew\\Telecom%20Egypt%20Internal\\venv\\Lib\\site-packages\\pydub\\audio_segment.py\", line 651, in from_file\n    file, close_file = _fd_or_path_or_tempfile(file, 'rb', tempfile=False)\n                       ^^^^^^^^^^^^^^^^^^^^^^^^^^^^^^^^^^^^^^^^^^^^^^^^^^^\n  File \"C:\\Users\\AnshulBhardwaj\\Desktop\\telecomnew\\Telecom%20Egypt%20Internal\\venv\\Lib\\site-packages\\pydub\\utils.py\", line 60, in _fd_or_path_or_tempfile\n    fd = open(fd, mode=mode)\n         ^^^^^^^^^^^^^^^^^^^\nFileNotFoundError: [Errno 2] No such file or directory: 'C:\\\\Users\\\\AnshulBhardwaj\\\\Desktop\\\\telecomnew\\\\Telecom%20Egypt%20Internal/source/calls/dir2/160675031.wav'", "location": "audio.py - audio_processing"}
{"asctime": "2024-06-08 T15:39:35+0530", "message": "An Error Occured ..", "exc_info": "Traceback (most recent call last):\n  File \"C:\\Users\\AnshulBhardwaj\\Desktop\\telecomnew\\Telecom%20Egypt%20Internal\\venv\\Lib\\site-packages\\mutagen\\_util.py\", line 251, in _openfile\n    fileobj = open(filename, \"rb+\" if writable else \"rb\")\n              ^^^^^^^^^^^^^^^^^^^^^^^^^^^^^^^^^^^^^^^^^^^\nFileNotFoundError: [Errno 2] No such file or directory: 'C:\\\\Users\\\\AnshulBhardwaj\\\\Desktop\\\\telecomnew\\\\Telecom%20Egypt%20Internal/data/processed_data/160675031.wav'\n\nDuring handling of the above exception, another exception occurred:\n\nTraceback (most recent call last):\n  File \"C:\\Users\\AnshulBhardwaj\\Desktop\\telecomnew\\Telecom%20Egypt%20Internal\\main.py\", line 41, in add_to_mapping\n    audio_atrs = get_audio_attrs_for_report(audio_path=audio_file_path)\n                 ^^^^^^^^^^^^^^^^^^^^^^^^^^^^^^^^^^^^^^^^^^^^^^^^^^^^^^\n  File \"C:\\Users\\AnshulBhardwaj\\Desktop\\telecomnew\\Telecom%20Egypt%20Internal\\src\\audio\\audio.py\", line 125, in get_audio_attrs_for_report\n    duration = get_audio_duration_in_seconds(path= audio_path)\n               ^^^^^^^^^^^^^^^^^^^^^^^^^^^^^^^^^^^^^^^^^^^^^^^\n  File \"C:\\Users\\AnshulBhardwaj\\Desktop\\telecomnew\\Telecom%20Egypt%20Internal\\src\\audio\\audio.py\", line 90, in get_audio_duration_in_seconds\n    audio = WAVE(path)\n           ^^^^^^^^^^\n  File \"C:\\Users\\AnshulBhardwaj\\Desktop\\telecomnew\\Telecom%20Egypt%20Internal\\venv\\Lib\\site-packages\\mutagen\\_file.py\", line 48, in __init__\n    self.load(*args, **kwargs)\n  File \"C:\\Users\\AnshulBhardwaj\\Desktop\\telecomnew\\Telecom%20Egypt%20Internal\\venv\\Lib\\site-packages\\mutagen\\_util.py\", line 185, in wrapper\n    return func(*args, **kwargs)\n           ^^^^^^^^^^^^^^^^^^^^^\n  File \"C:\\Users\\AnshulBhardwaj\\Desktop\\telecomnew\\Telecom%20Egypt%20Internal\\venv\\Lib\\site-packages\\mutagen\\_util.py\", line 154, in wrapper\n    with _openfile(self, filething, filename, fileobj,\n  File \"C:\\Users\\AnshulBhardwaj\\AppData\\Local\\Programs\\Python\\Python311\\Lib\\contextlib.py\", line 137, in __enter__\n    return next(self.gen)\n           ^^^^^^^^^^^^^^\n  File \"C:\\Users\\AnshulBhardwaj\\Desktop\\telecomnew\\Telecom%20Egypt%20Internal\\venv\\Lib\\site-packages\\mutagen\\_util.py\", line 272, in _openfile\n    raise MutagenError(e)\nmutagen.MutagenError: [Errno 2] No such file or directory: 'C:\\\\Users\\\\AnshulBhardwaj\\\\Desktop\\\\telecomnew\\\\Telecom%20Egypt%20Internal/data/processed_data/160675031.wav'", "location": "main.py - add_to_mapping"}
{"asctime": "2024-06-08 T15:39:35+0530", "message": "An Error Occured ..", "exc_info": "Traceback (most recent call last):\n  File \"C:\\Users\\AnshulBhardwaj\\Desktop\\telecomnew\\Telecom%20Egypt%20Internal\\src\\adapters\\transcription.py\", line 44, in recognize_from_file\n    conversation_transcriber = speechsdk.transcription.ConversationTranscriber(speech_config=speech_config, audio_config=audio_config)\n                               ^^^^^^^^^^^^^^^^^^^^^^^^^^^^^^^^^^^^^^^^^^^^^^^^^^^^^^^^^^^^^^^^^^^^^^^^^^^^^^^^^^^^^^^^^^^^^^^^^^^^^^^\n  File \"C:\\Users\\AnshulBhardwaj\\Desktop\\telecomnew\\Telecom%20Egypt%20Internal\\venv\\Lib\\site-packages\\azure\\cognitiveservices\\speech\\transcription.py\", line 136, in __init__\n    _call_hr_fn(\n  File \"C:\\Users\\AnshulBhardwaj\\Desktop\\telecomnew\\Telecom%20Egypt%20Internal\\venv\\Lib\\site-packages\\azure\\cognitiveservices\\speech\\interop.py\", line 62, in _call_hr_fn\n    _raise_if_failed(hr)\n  File \"C:\\Users\\AnshulBhardwaj\\Desktop\\telecomnew\\Telecom%20Egypt%20Internal\\venv\\Lib\\site-packages\\azure\\cognitiveservices\\speech\\interop.py\", line 55, in _raise_if_failed\n    __try_get_error(_spx_handle(hr))\n  File \"C:\\Users\\AnshulBhardwaj\\Desktop\\telecomnew\\Telecom%20Egypt%20Internal\\venv\\Lib\\site-packages\\azure\\cognitiveservices\\speech\\interop.py\", line 50, in __try_get_error\n    raise RuntimeError(message)\nRuntimeError: Exception with error code: \n[CALL STACK BEGIN]\n\n    > pal_string_to_wstring\n    - pal_string_to_wstring\n    - pal_string_to_wstring\n    - pal_string_to_wstring\n    - pal_string_to_wstring\n    - pal_string_to_wstring\n    - pal_string_to_wstring\n    - pal_string_to_wstring\n    - pal_string_to_wstring\n    - pal_string_to_wstring\n    - pal_string_to_wstring\n    - pal_string_to_wstring\n    - pal_string_to_wstring\n    - pal_string_to_wstring\n    - pal_string_to_wstring\n    - recognizer_create_speech_recognizer_from_config\n\n[CALL STACK END]\n\nException with an error code: 0x8 (SPXERR_FILE_OPEN_FAILED)", "location": "transcription.py - recognize_from_file"}
{"asctime": "2024-06-08 T16:22:23+0530", "message": "An Error Occured: 'summary'", "exc_info": "Traceback (most recent call last):\n  File \"C:\\Users\\AnshulBhardwaj\\Desktop\\telecomnew\\Telecom%20Egypt%20Internal\\main.py\", line 201, in get_kpis\n    result[\"summary\"] = summarisation_result[\"summary\"]\n                        ~~~~~~~~~~~~~~~~~~~~^^^^^^^^^^^\nKeyError: 'summary'", "location": "main.py - pipeline_after_transcription"}
{"asctime": "2024-06-08 T16:22:23+0530", "message": "An Error Occured: 'summary'", "exc_info": "Traceback (most recent call last):\n  File \"C:\\Users\\AnshulBhardwaj\\Desktop\\telecomnew\\Telecom%20Egypt%20Internal\\main.py\", line 245, in get_kpis_arabic\n    arabic_summarisation_result = trans_obj.get_translated_transcriptions_pipeline(eng_summ_result[\"summary\"], \"en\", \"ar-EG\")\n                                                                                   ~~~~~~~~~~~~~~~^^^^^^^^^^^\nKeyError: 'summary'", "location": "main.py - pipeline_after_transcription"}
{"asctime": "2024-06-08 T16:22:23+0530", "message": "An Error Occured: 'NoneType' object is not subscriptable", "exc_info": "Traceback (most recent call last):\n  File \"C:\\Users\\AnshulBhardwaj\\Desktop\\telecomnew\\Telecom%20Egypt%20Internal\\main.py\", line 308, in pipeline_after_transcription\n    merged_output[\"result\"][\"summary\"] = result[\"summary\"]\n                                         ~~~~~~^^^^^^^^^^^\nTypeError: 'NoneType' object is not subscriptable", "location": "main.py - pipeline_after_transcription"}
{"asctime": "2024-06-08 T16:22:24+0530", "message": "An Error Occured: 'summary'", "exc_info": "Traceback (most recent call last):\n  File \"C:\\Users\\AnshulBhardwaj\\Desktop\\telecomnew\\Telecom%20Egypt%20Internal\\main.py\", line 201, in get_kpis\n    result[\"summary\"] = summarisation_result[\"summary\"]\n                        ~~~~~~~~~~~~~~~~~~~~^^^^^^^^^^^\nKeyError: 'summary'", "location": "main.py - pipeline_after_transcription"}
{"asctime": "2024-06-08 T16:22:24+0530", "message": "An Error Occured: 'summary'", "exc_info": "Traceback (most recent call last):\n  File \"C:\\Users\\AnshulBhardwaj\\Desktop\\telecomnew\\Telecom%20Egypt%20Internal\\main.py\", line 245, in get_kpis_arabic\n    arabic_summarisation_result = trans_obj.get_translated_transcriptions_pipeline(eng_summ_result[\"summary\"], \"en\", \"ar-EG\")\n                                                                                   ~~~~~~~~~~~~~~~^^^^^^^^^^^\nKeyError: 'summary'", "location": "main.py - pipeline_after_transcription"}
{"asctime": "2024-06-08 T16:22:24+0530", "message": "An Error Occured: 'NoneType' object is not subscriptable", "exc_info": "Traceback (most recent call last):\n  File \"C:\\Users\\AnshulBhardwaj\\Desktop\\telecomnew\\Telecom%20Egypt%20Internal\\main.py\", line 308, in pipeline_after_transcription\n    merged_output[\"result\"][\"summary\"] = result[\"summary\"]\n                                         ~~~~~~^^^^^^^^^^^\nTypeError: 'NoneType' object is not subscriptable", "location": "main.py - pipeline_after_transcription"}
{"asctime": "2024-06-08 T16:22:26+0530", "message": "An Error Occured: 'summary'", "exc_info": "Traceback (most recent call last):\n  File \"C:\\Users\\AnshulBhardwaj\\Desktop\\telecomnew\\Telecom%20Egypt%20Internal\\main.py\", line 201, in get_kpis\n    result[\"summary\"] = summarisation_result[\"summary\"]\n                        ~~~~~~~~~~~~~~~~~~~~^^^^^^^^^^^\nKeyError: 'summary'", "location": "main.py - pipeline_after_transcription"}
{"asctime": "2024-06-08 T16:22:26+0530", "message": "An Error Occured: 'summary'", "exc_info": "Traceback (most recent call last):\n  File \"C:\\Users\\AnshulBhardwaj\\Desktop\\telecomnew\\Telecom%20Egypt%20Internal\\main.py\", line 245, in get_kpis_arabic\n    arabic_summarisation_result = trans_obj.get_translated_transcriptions_pipeline(eng_summ_result[\"summary\"], \"en\", \"ar-EG\")\n                                                                                   ~~~~~~~~~~~~~~~^^^^^^^^^^^\nKeyError: 'summary'", "location": "main.py - pipeline_after_transcription"}
{"asctime": "2024-06-08 T16:22:26+0530", "message": "An Error Occured: 'NoneType' object is not subscriptable", "exc_info": "Traceback (most recent call last):\n  File \"C:\\Users\\AnshulBhardwaj\\Desktop\\telecomnew\\Telecom%20Egypt%20Internal\\main.py\", line 308, in pipeline_after_transcription\n    merged_output[\"result\"][\"summary\"] = result[\"summary\"]\n                                         ~~~~~~^^^^^^^^^^^\nTypeError: 'NoneType' object is not subscriptable", "location": "main.py - pipeline_after_transcription"}
{"asctime": "2024-06-08 T16:22:27+0530", "message": "An Error Occured: 'summary'", "exc_info": "Traceback (most recent call last):\n  File \"C:\\Users\\AnshulBhardwaj\\Desktop\\telecomnew\\Telecom%20Egypt%20Internal\\main.py\", line 201, in get_kpis\n    result[\"summary\"] = summarisation_result[\"summary\"]\n                        ~~~~~~~~~~~~~~~~~~~~^^^^^^^^^^^\nKeyError: 'summary'", "location": "main.py - pipeline_after_transcription"}
{"asctime": "2024-06-08 T16:22:27+0530", "message": "An Error Occured: 'summary'", "exc_info": "Traceback (most recent call last):\n  File \"C:\\Users\\AnshulBhardwaj\\Desktop\\telecomnew\\Telecom%20Egypt%20Internal\\main.py\", line 245, in get_kpis_arabic\n    arabic_summarisation_result = trans_obj.get_translated_transcriptions_pipeline(eng_summ_result[\"summary\"], \"en\", \"ar-EG\")\n                                                                                   ~~~~~~~~~~~~~~~^^^^^^^^^^^\nKeyError: 'summary'", "location": "main.py - pipeline_after_transcription"}
{"asctime": "2024-06-08 T16:22:27+0530", "message": "An Error Occured: 'NoneType' object is not subscriptable", "exc_info": "Traceback (most recent call last):\n  File \"C:\\Users\\AnshulBhardwaj\\Desktop\\telecomnew\\Telecom%20Egypt%20Internal\\main.py\", line 308, in pipeline_after_transcription\n    merged_output[\"result\"][\"summary\"] = result[\"summary\"]\n                                         ~~~~~~^^^^^^^^^^^\nTypeError: 'NoneType' object is not subscriptable", "location": "main.py - pipeline_after_transcription"}
{"asctime": "2024-06-08 T16:22:29+0530", "message": "An Error Occured: 'summary'", "exc_info": "Traceback (most recent call last):\n  File \"C:\\Users\\AnshulBhardwaj\\Desktop\\telecomnew\\Telecom%20Egypt%20Internal\\main.py\", line 201, in get_kpis\n    result[\"summary\"] = summarisation_result[\"summary\"]\n                        ~~~~~~~~~~~~~~~~~~~~^^^^^^^^^^^\nKeyError: 'summary'", "location": "main.py - pipeline_after_transcription"}
{"asctime": "2024-06-08 T16:22:29+0530", "message": "An Error Occured: 'summary'", "exc_info": "Traceback (most recent call last):\n  File \"C:\\Users\\AnshulBhardwaj\\Desktop\\telecomnew\\Telecom%20Egypt%20Internal\\main.py\", line 245, in get_kpis_arabic\n    arabic_summarisation_result = trans_obj.get_translated_transcriptions_pipeline(eng_summ_result[\"summary\"], \"en\", \"ar-EG\")\n                                                                                   ~~~~~~~~~~~~~~~^^^^^^^^^^^\nKeyError: 'summary'", "location": "main.py - pipeline_after_transcription"}
{"asctime": "2024-06-08 T16:22:29+0530", "message": "An Error Occured: 'NoneType' object is not subscriptable", "exc_info": "Traceback (most recent call last):\n  File \"C:\\Users\\AnshulBhardwaj\\Desktop\\telecomnew\\Telecom%20Egypt%20Internal\\main.py\", line 308, in pipeline_after_transcription\n    merged_output[\"result\"][\"summary\"] = result[\"summary\"]\n                                         ~~~~~~^^^^^^^^^^^\nTypeError: 'NoneType' object is not subscriptable", "location": "main.py - pipeline_after_transcription"}
{"asctime": "2024-06-08 T16:36:36+0530", "message": "An Error Occured: 'summary'", "exc_info": "Traceback (most recent call last):\n  File \"C:\\Users\\AnshulBhardwaj\\Desktop\\telecomnew\\Telecom%20Egypt%20Internal\\main.py\", line 201, in get_kpis\n    result[\"summary\"] = summarisation_result[\"summary\"]\n                        ~~~~~~~~~~~~~~~~~~~~^^^^^^^^^^^\nKeyError: 'summary'", "location": "main.py - pipeline_after_transcription"}
{"asctime": "2024-06-08 T16:36:36+0530", "message": "An Error Occured: 'summary'", "exc_info": "Traceback (most recent call last):\n  File \"C:\\Users\\AnshulBhardwaj\\Desktop\\telecomnew\\Telecom%20Egypt%20Internal\\main.py\", line 245, in get_kpis_arabic\n    arabic_summarisation_result = trans_obj.get_translated_transcriptions_pipeline(eng_summ_result[\"summary\"], \"en\", \"ar-EG\")\n                                                                                   ~~~~~~~~~~~~~~~^^^^^^^^^^^\nKeyError: 'summary'", "location": "main.py - pipeline_after_transcription"}
{"asctime": "2024-06-08 T16:36:36+0530", "message": "An Error Occured: 'NoneType' object is not subscriptable", "exc_info": "Traceback (most recent call last):\n  File \"C:\\Users\\AnshulBhardwaj\\Desktop\\telecomnew\\Telecom%20Egypt%20Internal\\main.py\", line 308, in pipeline_after_transcription\n    merged_output[\"result\"][\"summary\"] = result[\"summary\"]\n                                         ~~~~~~^^^^^^^^^^^\nTypeError: 'NoneType' object is not subscriptable", "location": "main.py - pipeline_after_transcription"}
{"asctime": "2024-06-08 T16:36:41+0530", "message": "An Error Occured: 'summary'", "exc_info": "Traceback (most recent call last):\n  File \"C:\\Users\\AnshulBhardwaj\\Desktop\\telecomnew\\Telecom%20Egypt%20Internal\\main.py\", line 201, in get_kpis\n    result[\"summary\"] = summarisation_result[\"summary\"]\n                        ~~~~~~~~~~~~~~~~~~~~^^^^^^^^^^^\nKeyError: 'summary'", "location": "main.py - pipeline_after_transcription"}
{"asctime": "2024-06-08 T16:36:41+0530", "message": "An Error Occured: 'summary'", "exc_info": "Traceback (most recent call last):\n  File \"C:\\Users\\AnshulBhardwaj\\Desktop\\telecomnew\\Telecom%20Egypt%20Internal\\main.py\", line 245, in get_kpis_arabic\n    arabic_summarisation_result = trans_obj.get_translated_transcriptions_pipeline(eng_summ_result[\"summary\"], \"en\", \"ar-EG\")\n                                                                                   ~~~~~~~~~~~~~~~^^^^^^^^^^^\nKeyError: 'summary'", "location": "main.py - pipeline_after_transcription"}
{"asctime": "2024-06-08 T16:36:41+0530", "message": "An Error Occured: 'NoneType' object is not subscriptable", "exc_info": "Traceback (most recent call last):\n  File \"C:\\Users\\AnshulBhardwaj\\Desktop\\telecomnew\\Telecom%20Egypt%20Internal\\main.py\", line 308, in pipeline_after_transcription\n    merged_output[\"result\"][\"summary\"] = result[\"summary\"]\n                                         ~~~~~~^^^^^^^^^^^\nTypeError: 'NoneType' object is not subscriptable", "location": "main.py - pipeline_after_transcription"}
{"asctime": "2024-06-08 T16:36:43+0530", "message": "An Error Occured: 'summary'", "exc_info": "Traceback (most recent call last):\n  File \"C:\\Users\\AnshulBhardwaj\\Desktop\\telecomnew\\Telecom%20Egypt%20Internal\\main.py\", line 201, in get_kpis\n    result[\"summary\"] = summarisation_result[\"summary\"]\n                        ~~~~~~~~~~~~~~~~~~~~^^^^^^^^^^^\nKeyError: 'summary'", "location": "main.py - pipeline_after_transcription"}
{"asctime": "2024-06-08 T16:36:43+0530", "message": "An Error Occured: 'summary'", "exc_info": "Traceback (most recent call last):\n  File \"C:\\Users\\AnshulBhardwaj\\Desktop\\telecomnew\\Telecom%20Egypt%20Internal\\main.py\", line 245, in get_kpis_arabic\n    arabic_summarisation_result = trans_obj.get_translated_transcriptions_pipeline(eng_summ_result[\"summary\"], \"en\", \"ar-EG\")\n                                                                                   ~~~~~~~~~~~~~~~^^^^^^^^^^^\nKeyError: 'summary'", "location": "main.py - pipeline_after_transcription"}
{"asctime": "2024-06-08 T16:36:43+0530", "message": "An Error Occured: 'NoneType' object is not subscriptable", "exc_info": "Traceback (most recent call last):\n  File \"C:\\Users\\AnshulBhardwaj\\Desktop\\telecomnew\\Telecom%20Egypt%20Internal\\main.py\", line 308, in pipeline_after_transcription\n    merged_output[\"result\"][\"summary\"] = result[\"summary\"]\n                                         ~~~~~~^^^^^^^^^^^\nTypeError: 'NoneType' object is not subscriptable", "location": "main.py - pipeline_after_transcription"}
{"asctime": "2024-06-08 T16:36:45+0530", "message": "An Error Occured: 'summary'", "exc_info": "Traceback (most recent call last):\n  File \"C:\\Users\\AnshulBhardwaj\\Desktop\\telecomnew\\Telecom%20Egypt%20Internal\\main.py\", line 201, in get_kpis\n    result[\"summary\"] = summarisation_result[\"summary\"]\n                        ~~~~~~~~~~~~~~~~~~~~^^^^^^^^^^^\nKeyError: 'summary'", "location": "main.py - pipeline_after_transcription"}
{"asctime": "2024-06-08 T16:36:45+0530", "message": "An Error Occured: 'summary'", "exc_info": "Traceback (most recent call last):\n  File \"C:\\Users\\AnshulBhardwaj\\Desktop\\telecomnew\\Telecom%20Egypt%20Internal\\main.py\", line 245, in get_kpis_arabic\n    arabic_summarisation_result = trans_obj.get_translated_transcriptions_pipeline(eng_summ_result[\"summary\"], \"en\", \"ar-EG\")\n                                                                                   ~~~~~~~~~~~~~~~^^^^^^^^^^^\nKeyError: 'summary'", "location": "main.py - pipeline_after_transcription"}
{"asctime": "2024-06-08 T16:36:45+0530", "message": "An Error Occured: 'NoneType' object is not subscriptable", "exc_info": "Traceback (most recent call last):\n  File \"C:\\Users\\AnshulBhardwaj\\Desktop\\telecomnew\\Telecom%20Egypt%20Internal\\main.py\", line 308, in pipeline_after_transcription\n    merged_output[\"result\"][\"summary\"] = result[\"summary\"]\n                                         ~~~~~~^^^^^^^^^^^\nTypeError: 'NoneType' object is not subscriptable", "location": "main.py - pipeline_after_transcription"}
{"asctime": "2024-06-08 T16:36:47+0530", "message": "An Error Occured: 'summary'", "exc_info": "Traceback (most recent call last):\n  File \"C:\\Users\\AnshulBhardwaj\\Desktop\\telecomnew\\Telecom%20Egypt%20Internal\\main.py\", line 201, in get_kpis\n    result[\"summary\"] = summarisation_result[\"summary\"]\n                        ~~~~~~~~~~~~~~~~~~~~^^^^^^^^^^^\nKeyError: 'summary'", "location": "main.py - pipeline_after_transcription"}
{"asctime": "2024-06-08 T16:36:47+0530", "message": "An Error Occured: 'summary'", "exc_info": "Traceback (most recent call last):\n  File \"C:\\Users\\AnshulBhardwaj\\Desktop\\telecomnew\\Telecom%20Egypt%20Internal\\main.py\", line 245, in get_kpis_arabic\n    arabic_summarisation_result = trans_obj.get_translated_transcriptions_pipeline(eng_summ_result[\"summary\"], \"en\", \"ar-EG\")\n                                                                                   ~~~~~~~~~~~~~~~^^^^^^^^^^^\nKeyError: 'summary'", "location": "main.py - pipeline_after_transcription"}
{"asctime": "2024-06-08 T16:36:47+0530", "message": "An Error Occured: 'NoneType' object is not subscriptable", "exc_info": "Traceback (most recent call last):\n  File \"C:\\Users\\AnshulBhardwaj\\Desktop\\telecomnew\\Telecom%20Egypt%20Internal\\main.py\", line 308, in pipeline_after_transcription\n    merged_output[\"result\"][\"summary\"] = result[\"summary\"]\n                                         ~~~~~~^^^^^^^^^^^\nTypeError: 'NoneType' object is not subscriptable", "location": "main.py - pipeline_after_transcription"}
{"asctime": "2024-06-08 T16:36:49+0530", "message": "An Error Occured: 'summary'", "exc_info": "Traceback (most recent call last):\n  File \"C:\\Users\\AnshulBhardwaj\\Desktop\\telecomnew\\Telecom%20Egypt%20Internal\\main.py\", line 201, in get_kpis\n    result[\"summary\"] = summarisation_result[\"summary\"]\n                        ~~~~~~~~~~~~~~~~~~~~^^^^^^^^^^^\nKeyError: 'summary'", "location": "main.py - pipeline_after_transcription"}
{"asctime": "2024-06-08 T16:36:49+0530", "message": "An Error Occured: 'summary'", "exc_info": "Traceback (most recent call last):\n  File \"C:\\Users\\AnshulBhardwaj\\Desktop\\telecomnew\\Telecom%20Egypt%20Internal\\main.py\", line 245, in get_kpis_arabic\n    arabic_summarisation_result = trans_obj.get_translated_transcriptions_pipeline(eng_summ_result[\"summary\"], \"en\", \"ar-EG\")\n                                                                                   ~~~~~~~~~~~~~~~^^^^^^^^^^^\nKeyError: 'summary'", "location": "main.py - pipeline_after_transcription"}
{"asctime": "2024-06-08 T16:36:49+0530", "message": "An Error Occured: 'NoneType' object is not subscriptable", "exc_info": "Traceback (most recent call last):\n  File \"C:\\Users\\AnshulBhardwaj\\Desktop\\telecomnew\\Telecom%20Egypt%20Internal\\main.py\", line 308, in pipeline_after_transcription\n    merged_output[\"result\"][\"summary\"] = result[\"summary\"]\n                                         ~~~~~~^^^^^^^^^^^\nTypeError: 'NoneType' object is not subscriptable", "location": "main.py - pipeline_after_transcription"}
{"asctime": "2024-06-08 T16:38:47+0530", "message": "An Error Occured ..", "exc_info": "Traceback (most recent call last):\n  File \"C:\\Users\\AnshulBhardwaj\\Desktop\\telecomnew\\Telecom%20Egypt%20Internal\\app.py\", line 28, in Process_Audio_files\n    log_Garbage_Collector()\n  File \"C:\\Users\\AnshulBhardwaj\\Desktop\\telecomnew\\Telecom%20Egypt%20Internal\\logs\\logger.py\", line 66, in log_Garbage_Collector\n    remove_old_logs_from_top(error_log_path)\n  File \"C:\\Users\\AnshulBhardwaj\\Desktop\\telecomnew\\Telecom%20Egypt%20Internal\\logs\\logger.py\", line 58, in remove_old_logs_from_top\n    if not is_log_old(line):\n           ^^^^^^^^^^^^^^^^\n  File \"C:\\Users\\AnshulBhardwaj\\Desktop\\telecomnew\\Telecom%20Egypt%20Internal\\logs\\logger.py\", line 44, in is_log_old\n    log_data = json.loads(log_line)\n               ^^^^^^^^^^^^^^^^^^^^\n  File \"C:\\Users\\AnshulBhardwaj\\AppData\\Local\\Programs\\Python\\Python311\\Lib\\json\\__init__.py\", line 346, in loads\n    return _default_decoder.decode(s)\n           ^^^^^^^^^^^^^^^^^^^^^^^^^^\n  File \"C:\\Users\\AnshulBhardwaj\\AppData\\Local\\Programs\\Python\\Python311\\Lib\\json\\decoder.py\", line 340, in decode\n    raise JSONDecodeError(\"Extra data\", s, end)\njson.decoder.JSONDecodeError: Extra data: line 1 column 533 (char 532)", "location": "App.py - Process_Audio_files"}
{"asctime": "2024-06-08 T16:40:47+0530", "message": "An Error Occured ..", "exc_info": "Traceback (most recent call last):\n  File \"C:\\Users\\AnshulBhardwaj\\Desktop\\telecomnew\\Telecom%20Egypt%20Internal\\app.py\", line 28, in Process_Audio_files\n    log_Garbage_Collector()\n  File \"C:\\Users\\AnshulBhardwaj\\Desktop\\telecomnew\\Telecom%20Egypt%20Internal\\logs\\logger.py\", line 67, in log_Garbage_Collector\n    remove_old_logs_from_top(error_log_path)\n  File \"C:\\Users\\AnshulBhardwaj\\Desktop\\telecomnew\\Telecom%20Egypt%20Internal\\logs\\logger.py\", line 59, in remove_old_logs_from_top\n    if not is_log_old(line):\n           ^^^^^^^^^^^^^^^^\n  File \"C:\\Users\\AnshulBhardwaj\\Desktop\\telecomnew\\Telecom%20Egypt%20Internal\\logs\\logger.py\", line 44, in is_log_old\n    log_data = json.loads(log_line)\n               ^^^^^^^^^^^^^^^^^^^^\n  File \"C:\\Users\\AnshulBhardwaj\\AppData\\Local\\Programs\\Python\\Python311\\Lib\\json\\__init__.py\", line 346, in loads\n    return _default_decoder.decode(s)\n           ^^^^^^^^^^^^^^^^^^^^^^^^^^\n  File \"C:\\Users\\AnshulBhardwaj\\AppData\\Local\\Programs\\Python\\Python311\\Lib\\json\\decoder.py\", line 340, in decode\n    raise JSONDecodeError(\"Extra data\", s, end)\njson.decoder.JSONDecodeError: Extra data: line 1 column 533 (char 532)", "location": "App.py - Process_Audio_files"}
{"asctime": "2024-06-08 T16:46:55+0530", "message": "An Error Occured: 'Main' object has no attribute 'merge_sentiment_with_transcription'", "exc_info": "Traceback (most recent call last):\n  File \"C:\\Users\\AnshulBhardwaj\\Desktop\\telecomnew\\Telecom%20Egypt%20Internal\\main.py\", line 352, in pipeline_after_transcription\n    self.merge_sentiment_with_transcription(\n    ^^^^^^^^^^^^^^^^^^^^^^^^^^^^^^^^^^^^^^^\nAttributeError: 'Main' object has no attribute 'merge_sentiment_with_transcription'", "location": "main.py - pipeline_after_transcription"}
{"asctime": "2024-06-08 T16:47:48+0530", "message": "An Error Occured: 'Main' object has no attribute 'merge_sentiment_with_transcription'", "exc_info": "Traceback (most recent call last):\n  File \"C:\\Users\\AnshulBhardwaj\\Desktop\\telecomnew\\Telecom%20Egypt%20Internal\\main.py\", line 352, in pipeline_after_transcription\n    self.merge_sentiment_with_transcription(\n    ^^^^^^^^^^^^^^^^^^^^^^^^^^^^^^^^^^^^^^^\nAttributeError: 'Main' object has no attribute 'merge_sentiment_with_transcription'", "location": "main.py - pipeline_after_transcription"}
{"asctime": "2024-06-08 T16:48:55+0530", "message": "An Error Occured: 'Main' object has no attribute 'merge_sentiment_with_transcription'", "exc_info": "Traceback (most recent call last):\n  File \"C:\\Users\\AnshulBhardwaj\\Desktop\\telecomnew\\Telecom%20Egypt%20Internal\\main.py\", line 352, in pipeline_after_transcription\n    self.merge_sentiment_with_transcription(\n    ^^^^^^^^^^^^^^^^^^^^^^^^^^^^^^^^^^^^^^^\nAttributeError: 'Main' object has no attribute 'merge_sentiment_with_transcription'", "location": "main.py - pipeline_after_transcription"}
{"asctime": "2024-06-08 T18:08:18+0530", "message": "An Error Occured: 'keyPhrases_ls'", "exc_info": "Traceback (most recent call last):\n  File \"C:\\Users\\AnshulBhardwaj\\Desktop\\telecomnew\\Telecom%20Egypt%20Internal\\main.py\", line 389, in pipeline_after_transcription\n    result[\"keyPhrases_ls\"], merged_output[\"result\"][\"transcripts\"]\n    ~~~~~~^^^^^^^^^^^^^^^^^\nKeyError: 'keyPhrases_ls'", "location": "main.py - pipeline_after_transcription"}
{"asctime": "2024-06-08 T18:10:24+0530", "message": "An Error Occured: 'keyPhrases_ls'", "exc_info": "Traceback (most recent call last):\n  File \"C:\\Users\\AnshulBhardwaj\\Desktop\\telecomnew\\Telecom%20Egypt%20Internal\\main.py\", line 389, in pipeline_after_transcription\n    result[\"keyPhrases_ls\"], merged_output[\"result\"][\"transcripts\"]\n    ~~~~~~^^^^^^^^^^^^^^^^^\nKeyError: 'keyPhrases_ls'", "location": "main.py - pipeline_after_transcription"}
{"asctime": "2024-06-08 T18:11:29+0530", "message": "An Error Occured: 'keyPhrases_ls'", "exc_info": "Traceback (most recent call last):\n  File \"C:\\Users\\AnshulBhardwaj\\Desktop\\telecomnew\\Telecom%20Egypt%20Internal\\main.py\", line 389, in pipeline_after_transcription\n    result[\"keyPhrases_ls\"], merged_output[\"result\"][\"transcripts\"]\n    ~~~~~~^^^^^^^^^^^^^^^^^\nKeyError: 'keyPhrases_ls'", "location": "main.py - pipeline_after_transcription"}
{"asctime": "2024-06-08 T18:42:32+0530", "message": "An Error Occured: '161316483'", "exc_info": "Traceback (most recent call last):\n  File \"C:\\Users\\AnshulBhardwaj\\Desktop\\telecomnew\\Telecom%20Egypt%20Internal\\main.py\", line 293, in add_summarization_to_mapping\n    call_dict[call_audio_name][summarized_key] = summarized_text\n    ~~~~~~~~~^^^^^^^^^^^^^^^^^\nKeyError: '161316483'", "location": "main.py - add_summarization_to_mapping"}
{"asctime": "2024-06-08 T18:42:32+0530", "message": "An Error Occured: '161316483'", "exc_info": "Traceback (most recent call last):\n  File \"C:\\Users\\AnshulBhardwaj\\Desktop\\telecomnew\\Telecom%20Egypt%20Internal\\main.py\", line 293, in add_summarization_to_mapping\n    call_dict[call_audio_name][summarized_key] = summarized_text\n    ~~~~~~~~~^^^^^^^^^^^^^^^^^\nKeyError: '161316483'", "location": "main.py - add_summarization_to_mapping"}
{"asctime": "2024-06-08 T18:42:32+0530", "message": "An Error Occured: 'keyPhrases_ls'", "exc_info": "Traceback (most recent call last):\n  File \"C:\\Users\\AnshulBhardwaj\\Desktop\\telecomnew\\Telecom%20Egypt%20Internal\\main.py\", line 423, in pipeline_after_transcription\n    result[\"keyPhrases_ls\"], merged_output[\"result\"][\"transcripts\"]\n    ~~~~~~^^^^^^^^^^^^^^^^^\nKeyError: 'keyPhrases_ls'", "location": "main.py - pipeline_after_transcription"}
{"asctime": "2024-06-08 T18:43:36+0530", "message": "An Error Occured: '161560999'", "exc_info": "Traceback (most recent call last):\n  File \"C:\\Users\\AnshulBhardwaj\\Desktop\\telecomnew\\Telecom%20Egypt%20Internal\\main.py\", line 293, in add_summarization_to_mapping\n    call_dict[call_audio_name][summarized_key] = summarized_text\n    ~~~~~~~~~^^^^^^^^^^^^^^^^^\nKeyError: '161560999'", "location": "main.py - add_summarization_to_mapping"}
{"asctime": "2024-06-08 T18:43:36+0530", "message": "An Error Occured: '161560999'", "exc_info": "Traceback (most recent call last):\n  File \"C:\\Users\\AnshulBhardwaj\\Desktop\\telecomnew\\Telecom%20Egypt%20Internal\\main.py\", line 293, in add_summarization_to_mapping\n    call_dict[call_audio_name][summarized_key] = summarized_text\n    ~~~~~~~~~^^^^^^^^^^^^^^^^^\nKeyError: '161560999'", "location": "main.py - add_summarization_to_mapping"}
{"asctime": "2024-06-08 T18:43:36+0530", "message": "An Error Occured: 'keyPhrases_ls'", "exc_info": "Traceback (most recent call last):\n  File \"C:\\Users\\AnshulBhardwaj\\Desktop\\telecomnew\\Telecom%20Egypt%20Internal\\main.py\", line 423, in pipeline_after_transcription\n    result[\"keyPhrases_ls\"], merged_output[\"result\"][\"transcripts\"]\n    ~~~~~~^^^^^^^^^^^^^^^^^\nKeyError: 'keyPhrases_ls'", "location": "main.py - pipeline_after_transcription"}
{"asctime": "2024-06-08 T18:59:55+0530", "message": "An Error Occured: '161560999'", "exc_info": "Traceback (most recent call last):\n  File \"C:\\Users\\AnshulBhardwaj\\Desktop\\telecomnew\\Telecom%20Egypt%20Internal\\main.py\", line 294, in add_summarization_to_mapping\n    call_dict[call_audio_name][summarized_key] = summarized_text\n    ~~~~~~~~~^^^^^^^^^^^^^^^^^\nKeyError: '161560999'", "location": "main.py - add_summarization_to_mapping"}
{"asctime": "2024-06-08 T18:59:55+0530", "message": "An Error Occured: '161560999'", "exc_info": "Traceback (most recent call last):\n  File \"C:\\Users\\AnshulBhardwaj\\Desktop\\telecomnew\\Telecom%20Egypt%20Internal\\main.py\", line 294, in add_summarization_to_mapping\n    call_dict[call_audio_name][summarized_key] = summarized_text\n    ~~~~~~~~~^^^^^^^^^^^^^^^^^\nKeyError: '161560999'", "location": "main.py - add_summarization_to_mapping"}
{"asctime": "2024-06-08 T18:59:55+0530", "message": "An Error Occured: 'keyPhrases_ls'", "exc_info": "Traceback (most recent call last):\n  File \"C:\\Users\\AnshulBhardwaj\\Desktop\\telecomnew\\Telecom%20Egypt%20Internal\\main.py\", line 424, in pipeline_after_transcription\n    result[\"keyPhrases_ls\"], merged_output[\"result\"][\"transcripts\"]\n    ~~~~~~^^^^^^^^^^^^^^^^^\nKeyError: 'keyPhrases_ls'", "location": "main.py - pipeline_after_transcription"}
{"asctime": "2024-06-08 T19:03:06+0530", "message": "An Error Occured: '161560999'", "exc_info": "Traceback (most recent call last):\n  File \"C:\\Users\\AnshulBhardwaj\\Desktop\\telecomnew\\Telecom%20Egypt%20Internal\\main.py\", line 294, in add_summarization_to_mapping\n    call_dict[call_audio_name][summarized_key] = summarized_text\n    ~~~~~~~~~^^^^^^^^^^^^^^^^^\nKeyError: '161560999'", "location": "main.py - add_summarization_to_mapping"}
{"asctime": "2024-06-08 T19:03:06+0530", "message": "An Error Occured: '161560999'", "exc_info": "Traceback (most recent call last):\n  File \"C:\\Users\\AnshulBhardwaj\\Desktop\\telecomnew\\Telecom%20Egypt%20Internal\\main.py\", line 294, in add_summarization_to_mapping\n    call_dict[call_audio_name][summarized_key] = summarized_text\n    ~~~~~~~~~^^^^^^^^^^^^^^^^^\nKeyError: '161560999'", "location": "main.py - add_summarization_to_mapping"}
{"asctime": "2024-06-08 T19:03:06+0530", "message": "An Error Occured: 'keyPhrases_ls'", "exc_info": "Traceback (most recent call last):\n  File \"C:\\Users\\AnshulBhardwaj\\Desktop\\telecomnew\\Telecom%20Egypt%20Internal\\main.py\", line 427, in pipeline_after_transcription\n    result[\"keyPhrases_ls\"], merged_output[\"result\"][\"transcripts\"]\n    ~~~~~~^^^^^^^^^^^^^^^^^\nKeyError: 'keyPhrases_ls'", "location": "main.py - pipeline_after_transcription"}
{"asctime": "2024-06-08 T19:07:05+0530", "message": "An Error Occured: '161560999'", "exc_info": "Traceback (most recent call last):\n  File \"C:\\Users\\AnshulBhardwaj\\Desktop\\telecomnew\\Telecom%20Egypt%20Internal\\main.py\", line 294, in add_summarization_to_mapping\n    call_dict[call_audio_name][summarized_key] = summarized_text\n    ~~~~~~~~~^^^^^^^^^^^^^^^^^\nKeyError: '161560999'", "location": "main.py - add_summarization_to_mapping"}
{"asctime": "2024-06-08 T19:07:05+0530", "message": "An Error Occured: '161560999'", "exc_info": "Traceback (most recent call last):\n  File \"C:\\Users\\AnshulBhardwaj\\Desktop\\telecomnew\\Telecom%20Egypt%20Internal\\main.py\", line 294, in add_summarization_to_mapping\n    call_dict[call_audio_name][summarized_key] = summarized_text\n    ~~~~~~~~~^^^^^^^^^^^^^^^^^\nKeyError: '161560999'", "location": "main.py - add_summarization_to_mapping"}
{"asctime": "2024-06-08 T19:07:05+0530", "message": "An Error Occured: 'keyPhrases_ls'", "exc_info": "Traceback (most recent call last):\n  File \"C:\\Users\\AnshulBhardwaj\\Desktop\\telecomnew\\Telecom%20Egypt%20Internal\\main.py\", line 427, in pipeline_after_transcription\n    result[\"keyPhrases_ls\"], merged_output[\"result\"][\"transcripts\"]\n    ~~~~~~^^^^^^^^^^^^^^^^^\nKeyError: 'keyPhrases_ls'", "location": "main.py - pipeline_after_transcription"}
{"asctime": "2024-06-08 T19:09:20+0530", "message": "An Error Occured: '161560999'", "exc_info": "Traceback (most recent call last):\n  File \"C:\\Users\\AnshulBhardwaj\\Desktop\\telecomnew\\Telecom%20Egypt%20Internal\\main.py\", line 294, in add_summarization_to_mapping\n    call_dict[call_audio_name][summarized_key] = summarized_text\n    ~~~~~~~~~^^^^^^^^^^^^^^^^^\nKeyError: '161560999'", "location": "main.py - add_summarization_to_mapping"}
{"asctime": "2024-06-08 T19:09:20+0530", "message": "An Error Occured: '161560999'", "exc_info": "Traceback (most recent call last):\n  File \"C:\\Users\\AnshulBhardwaj\\Desktop\\telecomnew\\Telecom%20Egypt%20Internal\\main.py\", line 294, in add_summarization_to_mapping\n    call_dict[call_audio_name][summarized_key] = summarized_text\n    ~~~~~~~~~^^^^^^^^^^^^^^^^^\nKeyError: '161560999'", "location": "main.py - add_summarization_to_mapping"}
{"asctime": "2024-06-08 T19:09:20+0530", "message": "An Error Occured: 'keyPhrases_ls'", "exc_info": "Traceback (most recent call last):\n  File \"C:\\Users\\AnshulBhardwaj\\Desktop\\telecomnew\\Telecom%20Egypt%20Internal\\main.py\", line 427, in pipeline_after_transcription\n    result[\"keyPhrases_ls\"], merged_output[\"result\"][\"transcripts\"]\n    ~~~~~~^^^^^^^^^^^^^^^^^\nKeyError: 'keyPhrases_ls'", "location": "main.py - pipeline_after_transcription"}
{"asctime": "2024-06-08 T19:14:12+0530", "message": "An Error Occured: 'keyPhrases_ls'", "exc_info": "Traceback (most recent call last):\n  File \"C:\\Users\\AnshulBhardwaj\\Desktop\\telecomnew\\Telecom%20Egypt%20Internal\\main.py\", line 427, in pipeline_after_transcription\n    result[\"keyPhrases_ls\"], merged_output[\"result\"][\"transcripts\"]\n    ~~~~~~^^^^^^^^^^^^^^^^^\nKeyError: 'keyPhrases_ls'", "location": "main.py - pipeline_after_transcription"}
{"asctime": "2024-06-08 T19:17:51+0530", "message": "An Error Occured: 'keyPhrases_ls'", "exc_info": "Traceback (most recent call last):\n  File \"C:\\Users\\AnshulBhardwaj\\Desktop\\telecomnew\\Telecom%20Egypt%20Internal\\main.py\", line 427, in pipeline_after_transcription\n    result[\"keyPhrases_ls\"], merged_output[\"result\"][\"transcripts\"]\n    ~~~~~~^^^^^^^^^^^^^^^^^\nKeyError: 'keyPhrases_ls'", "location": "main.py - pipeline_after_transcription"}
{"asctime": "2024-06-08 T19:24:23+0530", "message": "An Error Occured: 'keyPhrases_ls'", "exc_info": "Traceback (most recent call last):\n  File \"C:\\Users\\AnshulBhardwaj\\Desktop\\telecomnew\\Telecom%20Egypt%20Internal\\main.py\", line 427, in pipeline_after_transcription\n    result[\"keyPhrases_ls\"], merged_output[\"result\"][\"transcripts\"]\n    ~~~~~~^^^^^^^^^^^^^^^^^\nKeyError: 'keyPhrases_ls'", "location": "main.py - pipeline_after_transcription"}
{"asctime": "2024-06-08 T19:47:43+0530", "message": "An Error Occured: string indices must be integers, not 'str'", "exc_info": "Traceback (most recent call last):\n  File \"C:\\Users\\AnshulBhardwaj\\Desktop\\telecomnew\\Telecom%20Egypt%20Internal\\main.py\", line 323, in add_mapping_to_excel\n    call_id_ls.append(call_data['id'])\n                      ~~~~~~~~~^^^^^^\nTypeError: string indices must be integers, not 'str'", "location": "main.py - add_mapping_to_excel"}
{"asctime": "2024-06-08 T19:47:43+0530", "message": "An Error Occured: 'keyPhrases_ls'", "exc_info": "Traceback (most recent call last):\n  File \"C:\\Users\\AnshulBhardwaj\\Desktop\\telecomnew\\Telecom%20Egypt%20Internal\\main.py\", line 479, in pipeline_after_transcription\n    result[\"keyPhrases_ls\"], merged_output[\"result\"][\"transcripts\"]\n    ~~~~~~^^^^^^^^^^^^^^^^^\nKeyError: 'keyPhrases_ls'", "location": "main.py - pipeline_after_transcription"}
{"asctime": "2024-06-08 T19:52:09+0530", "message": "An Error Occured: 'keyPhrases_ls'", "exc_info": "Traceback (most recent call last):\n  File \"C:\\Users\\AnshulBhardwaj\\Desktop\\telecomnew\\Telecom%20Egypt%20Internal\\main.py\", line 480, in pipeline_after_transcription\n    result[\"keyPhrases_ls\"], merged_output[\"result\"][\"transcripts\"]\n    ~~~~~~^^^^^^^^^^^^^^^^^\nKeyError: 'keyPhrases_ls'", "location": "main.py - pipeline_after_transcription"}
{"asctime": "2024-06-09 T02:08:34+0530", "message": "An Error Occured: 'keyPhrases_ls'", "exc_info": "Traceback (most recent call last):\n  File \"C:\\Celebal data\\Clients\\Telecom Egypt\\Extract summary\\telecomnew\\telecomnew\\08.06.24_telEg_summ_pipeline\\main.py\", line 480, in pipeline_after_transcription\n    result[\"keyPhrases_ls\"], merged_output[\"result\"][\"transcripts\"]\n    ~~~~~~^^^^^^^^^^^^^^^^^\nKeyError: 'keyPhrases_ls'", "location": "main.py - pipeline_after_transcription"}
{"asctime": "2024-06-09 T02:09:29+0530", "message": "An Error Occured: 'keyPhrases_ls'", "exc_info": "Traceback (most recent call last):\n  File \"C:\\Celebal data\\Clients\\Telecom Egypt\\Extract summary\\telecomnew\\telecomnew\\08.06.24_telEg_summ_pipeline\\main.py\", line 480, in pipeline_after_transcription\n    result[\"keyPhrases_ls\"], merged_output[\"result\"][\"transcripts\"]\n    ~~~~~~^^^^^^^^^^^^^^^^^\nKeyError: 'keyPhrases_ls'", "location": "main.py - pipeline_after_transcription"}
{"asctime": "2024-06-09 T02:10:33+0530", "message": "An Error Occured: 'keyPhrases_ls'", "exc_info": "Traceback (most recent call last):\n  File \"C:\\Celebal data\\Clients\\Telecom Egypt\\Extract summary\\telecomnew\\telecomnew\\08.06.24_telEg_summ_pipeline\\main.py\", line 480, in pipeline_after_transcription\n    result[\"keyPhrases_ls\"], merged_output[\"result\"][\"transcripts\"]\n    ~~~~~~^^^^^^^^^^^^^^^^^\nKeyError: 'keyPhrases_ls'", "location": "main.py - pipeline_after_transcription"}
{"asctime": "2024-06-09 T02:11:23+0530", "message": "An Error Occured: HTTPSConnectionPool(host='demo-langservice-mij.cognitiveservices.azure.com', port=443): Max retries exceeded with url: /language/analyze-text/jobs?api-version=2023-04-01 (Caused by NameResolutionError(\"<urllib3.connection.HTTPSConnection object at 0x00000236B6BCC950>: Failed to resolve 'demo-langservice-mij.cognitiveservices.azure.com' ([Errno 11001] getaddrinfo failed)\"))", "exc_info": "Traceback (most recent call last):\n  File \"C:\\Celebal data\\Clients\\Telecom Egypt\\Extract summary\\telecomnew\\telecomnew\\08.06.24_telEg_summ_pipeline\\tempvenv\\Lib\\site-packages\\urllib3\\connection.py\", line 198, in _new_conn\n    sock = connection.create_connection(\n           ^^^^^^^^^^^^^^^^^^^^^^^^^^^^^\n  File \"C:\\Celebal data\\Clients\\Telecom Egypt\\Extract summary\\telecomnew\\telecomnew\\08.06.24_telEg_summ_pipeline\\tempvenv\\Lib\\site-packages\\urllib3\\util\\connection.py\", line 60, in create_connection\n    for res in socket.getaddrinfo(host, port, family, socket.SOCK_STREAM):\n               ^^^^^^^^^^^^^^^^^^^^^^^^^^^^^^^^^^^^^^^^^^^^^^^^^^^^^^^^^^\n  File \"C:\\Users\\MaharshiJasraj\\AppData\\Local\\Programs\\Python\\Python311\\Lib\\socket.py\", line 962, in getaddrinfo\n    for res in _socket.getaddrinfo(host, port, family, type, proto, flags):\n               ^^^^^^^^^^^^^^^^^^^^^^^^^^^^^^^^^^^^^^^^^^^^^^^^^^^^^^^^^^^\nsocket.gaierror: [Errno 11001] getaddrinfo failed\n\nThe above exception was the direct cause of the following exception:\n\nTraceback (most recent call last):\n  File \"C:\\Celebal data\\Clients\\Telecom Egypt\\Extract summary\\telecomnew\\telecomnew\\08.06.24_telEg_summ_pipeline\\tempvenv\\Lib\\site-packages\\urllib3\\connectionpool.py\", line 793, in urlopen\n    response = self._make_request(\n               ^^^^^^^^^^^^^^^^^^^\n  File \"C:\\Celebal data\\Clients\\Telecom Egypt\\Extract summary\\telecomnew\\telecomnew\\08.06.24_telEg_summ_pipeline\\tempvenv\\Lib\\site-packages\\urllib3\\connectionpool.py\", line 491, in _make_request\n    raise new_e\n  File \"C:\\Celebal data\\Clients\\Telecom Egypt\\Extract summary\\telecomnew\\telecomnew\\08.06.24_telEg_summ_pipeline\\tempvenv\\Lib\\site-packages\\urllib3\\connectionpool.py\", line 467, in _make_request\n    self._validate_conn(conn)\n  File \"C:\\Celebal data\\Clients\\Telecom Egypt\\Extract summary\\telecomnew\\telecomnew\\08.06.24_telEg_summ_pipeline\\tempvenv\\Lib\\site-packages\\urllib3\\connectionpool.py\", line 1099, in _validate_conn\n    conn.connect()\n  File \"C:\\Celebal data\\Clients\\Telecom Egypt\\Extract summary\\telecomnew\\telecomnew\\08.06.24_telEg_summ_pipeline\\tempvenv\\Lib\\site-packages\\urllib3\\connection.py\", line 616, in connect\n    self.sock = sock = self._new_conn()\n                       ^^^^^^^^^^^^^^^^\n  File \"C:\\Celebal data\\Clients\\Telecom Egypt\\Extract summary\\telecomnew\\telecomnew\\08.06.24_telEg_summ_pipeline\\tempvenv\\Lib\\site-packages\\urllib3\\connection.py\", line 205, in _new_conn\n    raise NameResolutionError(self.host, self, e) from e\nurllib3.exceptions.NameResolutionError: <urllib3.connection.HTTPSConnection object at 0x00000236B6BCC950>: Failed to resolve 'demo-langservice-mij.cognitiveservices.azure.com' ([Errno 11001] getaddrinfo failed)\n\nThe above exception was the direct cause of the following exception:\n\nTraceback (most recent call last):\n  File \"C:\\Celebal data\\Clients\\Telecom Egypt\\Extract summary\\telecomnew\\telecomnew\\08.06.24_telEg_summ_pipeline\\tempvenv\\Lib\\site-packages\\requests\\adapters.py\", line 667, in send\n    resp = conn.urlopen(\n           ^^^^^^^^^^^^^\n  File \"C:\\Celebal data\\Clients\\Telecom Egypt\\Extract summary\\telecomnew\\telecomnew\\08.06.24_telEg_summ_pipeline\\tempvenv\\Lib\\site-packages\\urllib3\\connectionpool.py\", line 847, in urlopen\n    retries = retries.increment(\n              ^^^^^^^^^^^^^^^^^^\n  File \"C:\\Celebal data\\Clients\\Telecom Egypt\\Extract summary\\telecomnew\\telecomnew\\08.06.24_telEg_summ_pipeline\\tempvenv\\Lib\\site-packages\\urllib3\\util\\retry.py\", line 515, in increment\n    raise MaxRetryError(_pool, url, reason) from reason  # type: ignore[arg-type]\n    ^^^^^^^^^^^^^^^^^^^^^^^^^^^^^^^^^^^^^^^^^^^^^^^^^^^\nurllib3.exceptions.MaxRetryError: HTTPSConnectionPool(host='demo-langservice-mij.cognitiveservices.azure.com', port=443): Max retries exceeded with url: /language/analyze-text/jobs?api-version=2023-04-01 (Caused by NameResolutionError(\"<urllib3.connection.HTTPSConnection object at 0x00000236B6BCC950>: Failed to resolve 'demo-langservice-mij.cognitiveservices.azure.com' ([Errno 11001] getaddrinfo failed)\"))\n\nDuring handling of the above exception, another exception occurred:\n\nTraceback (most recent call last):\n  File \"C:\\Celebal data\\Clients\\Telecom Egypt\\Extract summary\\telecomnew\\telecomnew\\08.06.24_telEg_summ_pipeline\\main.py\", line 197, in get_kpis\n    summarisation_result = summarisation_obj.abstractive_summarisation_helper(call)\n                           ^^^^^^^^^^^^^^^^^^^^^^^^^^^^^^^^^^^^^^^^^^^^^^^^^^^^^^^^\n  File \"C:\\Celebal data\\Clients\\Telecom Egypt\\Extract summary\\telecomnew\\telecomnew\\08.06.24_telEg_summ_pipeline\\src\\adapters\\summarisation.py\", line 239, in abstractive_summarisation_helper\n    res = requests.post(url = self.url, headers= headers, json= data)\n          ^^^^^^^^^^^^^^^^^^^^^^^^^^^^^^^^^^^^^^^^^^^^^^^^^^^^^^^^^^^\n  File \"C:\\Celebal data\\Clients\\Telecom Egypt\\Extract summary\\telecomnew\\telecomnew\\08.06.24_telEg_summ_pipeline\\tempvenv\\Lib\\site-packages\\requests\\api.py\", line 115, in post\n    return request(\"post\", url, data=data, json=json, **kwargs)\n           ^^^^^^^^^^^^^^^^^^^^^^^^^^^^^^^^^^^^^^^^^^^^^^^^^^^^\n  File \"C:\\Celebal data\\Clients\\Telecom Egypt\\Extract summary\\telecomnew\\telecomnew\\08.06.24_telEg_summ_pipeline\\tempvenv\\Lib\\site-packages\\requests\\api.py\", line 59, in request\n    return session.request(method=method, url=url, **kwargs)\n           ^^^^^^^^^^^^^^^^^^^^^^^^^^^^^^^^^^^^^^^^^^^^^^^^^\n  File \"C:\\Celebal data\\Clients\\Telecom Egypt\\Extract summary\\telecomnew\\telecomnew\\08.06.24_telEg_summ_pipeline\\tempvenv\\Lib\\site-packages\\requests\\sessions.py\", line 589, in request\n    resp = self.send(prep, **send_kwargs)\n           ^^^^^^^^^^^^^^^^^^^^^^^^^^^^^^\n  File \"C:\\Celebal data\\Clients\\Telecom Egypt\\Extract summary\\telecomnew\\telecomnew\\08.06.24_telEg_summ_pipeline\\tempvenv\\Lib\\site-packages\\requests\\sessions.py\", line 703, in send\n    r = adapter.send(request, **kwargs)\n        ^^^^^^^^^^^^^^^^^^^^^^^^^^^^^^^\n  File \"C:\\Celebal data\\Clients\\Telecom Egypt\\Extract summary\\telecomnew\\telecomnew\\08.06.24_telEg_summ_pipeline\\tempvenv\\Lib\\site-packages\\requests\\adapters.py\", line 700, in send\n    raise ConnectionError(e, request=request)\nrequests.exceptions.ConnectionError: HTTPSConnectionPool(host='demo-langservice-mij.cognitiveservices.azure.com', port=443): Max retries exceeded with url: /language/analyze-text/jobs?api-version=2023-04-01 (Caused by NameResolutionError(\"<urllib3.connection.HTTPSConnection object at 0x00000236B6BCC950>: Failed to resolve 'demo-langservice-mij.cognitiveservices.azure.com' ([Errno 11001] getaddrinfo failed)\"))", "location": "main.py - pipeline_after_transcription"}
{"asctime": "2024-06-09 T02:11:24+0530", "message": "An Error Occured: 'NoneType' object is not subscriptable", "exc_info": "Traceback (most recent call last):\n  File \"C:\\Celebal data\\Clients\\Telecom Egypt\\Extract summary\\telecomnew\\telecomnew\\08.06.24_telEg_summ_pipeline\\main.py\", line 293, in add_summarization_to_mapping\n    print(f\"adding the data to the mapping for key : {summarized_key} with value {summarized_text['summary']}\")\n                                                                                  ~~~~~~~~~~~~~~~^^^^^^^^^^^\nTypeError: 'NoneType' object is not subscriptable", "location": "main.py - add_summarization_to_mapping"}
{"asctime": "2024-06-09 T02:11:24+0530", "message": "An Error Occurred: 'summarization_en'", "exc_info": "Traceback (most recent call last):\n  File \"C:\\Celebal data\\Clients\\Telecom Egypt\\Extract summary\\telecomnew\\telecomnew\\08.06.24_telEg_summ_pipeline\\main.py\", line 331, in add_mapping_to_excel\n    summarization_en_ls.append(call_data['summarization_en'])\n                               ~~~~~~~~~^^^^^^^^^^^^^^^^^^^^\nKeyError: 'summarization_en'", "location": "main.py - add_mapping_to_excel"}
{"asctime": "2024-06-09 T02:11:24+0530", "message": "An Error Occured: 'NoneType' object is not subscriptable", "exc_info": "Traceback (most recent call last):\n  File \"C:\\Celebal data\\Clients\\Telecom Egypt\\Extract summary\\telecomnew\\telecomnew\\08.06.24_telEg_summ_pipeline\\main.py\", line 399, in pipeline_after_transcription\n    merged_output[\"result\"][\"summary\"] = result[\"summary\"]\n                                         ~~~~~~^^^^^^^^^^^\nTypeError: 'NoneType' object is not subscriptable", "location": "main.py - pipeline_after_transcription"}
{"asctime": "2024-06-09 T02:12:27+0530", "message": "An Error Occurred: 'summarization_en'", "exc_info": "Traceback (most recent call last):\n  File \"C:\\Celebal data\\Clients\\Telecom Egypt\\Extract summary\\telecomnew\\telecomnew\\08.06.24_telEg_summ_pipeline\\main.py\", line 331, in add_mapping_to_excel\n    summarization_en_ls.append(call_data['summarization_en'])\n                               ~~~~~~~~~^^^^^^^^^^^^^^^^^^^^\nKeyError: 'summarization_en'", "location": "main.py - add_mapping_to_excel"}
{"asctime": "2024-06-09 T02:12:27+0530", "message": "An Error Occured: 'keyPhrases_ls'", "exc_info": "Traceback (most recent call last):\n  File \"C:\\Celebal data\\Clients\\Telecom Egypt\\Extract summary\\telecomnew\\telecomnew\\08.06.24_telEg_summ_pipeline\\main.py\", line 480, in pipeline_after_transcription\n    result[\"keyPhrases_ls\"], merged_output[\"result\"][\"transcripts\"]\n    ~~~~~~^^^^^^^^^^^^^^^^^\nKeyError: 'keyPhrases_ls'", "location": "main.py - pipeline_after_transcription"}
{"asctime": "2024-06-09 T02:13:46+0530", "message": "An Error Occurred: 'summarization_en'", "exc_info": "Traceback (most recent call last):\n  File \"C:\\Celebal data\\Clients\\Telecom Egypt\\Extract summary\\telecomnew\\telecomnew\\08.06.24_telEg_summ_pipeline\\main.py\", line 331, in add_mapping_to_excel\n    Comment_ls.append(call_data['Comment'])\n                               ^^^^^^^^^^^^^\nKeyError: 'summarization_en'", "location": "main.py - add_mapping_to_excel"}
{"asctime": "2024-06-09 T02:13:46+0530", "message": "An Error Occured: 'keyPhrases_ls'", "exc_info": "Traceback (most recent call last):\n  File \"C:\\Celebal data\\Clients\\Telecom Egypt\\Extract summary\\telecomnew\\telecomnew\\08.06.24_telEg_summ_pipeline\\main.py\", line 480, in pipeline_after_transcription\n    self.merge_keyphrases_with_transcription(\n        ^^^^^^^^^^^^^^^^^^^^^^^\nKeyError: 'keyPhrases_ls'", "location": "main.py - pipeline_after_transcription"}
{"asctime": "2024-06-09 T02:14:47+0530", "message": "An Error Occured: HTTPSConnectionPool(host='demo-langservice-mij.cognitiveservices.azure.com', port=443): Max retries exceeded with url: /language/analyze-text/jobs?api-version=2023-04-01 (Caused by NameResolutionError(\"<urllib3.connection.HTTPSConnection object at 0x00000236B6C3ED10>: Failed to resolve 'demo-langservice-mij.cognitiveservices.azure.com' ([Errno 11001] getaddrinfo failed)\"))", "exc_info": "Traceback (most recent call last):\n  File \"C:\\Celebal data\\Clients\\Telecom Egypt\\Extract summary\\telecomnew\\telecomnew\\08.06.24_telEg_summ_pipeline\\tempvenv\\Lib\\site-packages\\urllib3\\connection.py\", line 198, in _new_conn\n    sock = connection.create_connection(\n           ^^^^^^^^^^^^^^^^^^^^^^^^^^^^^\n  File \"C:\\Celebal data\\Clients\\Telecom Egypt\\Extract summary\\telecomnew\\telecomnew\\08.06.24_telEg_summ_pipeline\\tempvenv\\Lib\\site-packages\\urllib3\\util\\connection.py\", line 60, in create_connection\n    for res in socket.getaddrinfo(host, port, family, socket.SOCK_STREAM):\n               ^^^^^^^^^^^^^^^^^^^^^^^^^^^^^^^^^^^^^^^^^^^^^^^^^^^^^^^^^^\n  File \"C:\\Users\\MaharshiJasraj\\AppData\\Local\\Programs\\Python\\Python311\\Lib\\socket.py\", line 962, in getaddrinfo\n    for res in _socket.getaddrinfo(host, port, family, type, proto, flags):\n               ^^^^^^^^^^^^^^^^^^^^^^^^^^^^^^^^^^^^^^^^^^^^^^^^^^^^^^^^^^^\nsocket.gaierror: [Errno 11001] getaddrinfo failed\n\nThe above exception was the direct cause of the following exception:\n\nTraceback (most recent call last):\n  File \"C:\\Celebal data\\Clients\\Telecom Egypt\\Extract summary\\telecomnew\\telecomnew\\08.06.24_telEg_summ_pipeline\\tempvenv\\Lib\\site-packages\\urllib3\\connectionpool.py\", line 793, in urlopen\n    response = self._make_request(\n               ^^^^^^^^^^^^^^^^^^^\n  File \"C:\\Celebal data\\Clients\\Telecom Egypt\\Extract summary\\telecomnew\\telecomnew\\08.06.24_telEg_summ_pipeline\\tempvenv\\Lib\\site-packages\\urllib3\\connectionpool.py\", line 491, in _make_request\n    raise new_e\n  File \"C:\\Celebal data\\Clients\\Telecom Egypt\\Extract summary\\telecomnew\\telecomnew\\08.06.24_telEg_summ_pipeline\\tempvenv\\Lib\\site-packages\\urllib3\\connectionpool.py\", line 467, in _make_request\n    self._validate_conn(conn)\n  File \"C:\\Celebal data\\Clients\\Telecom Egypt\\Extract summary\\telecomnew\\telecomnew\\08.06.24_telEg_summ_pipeline\\tempvenv\\Lib\\site-packages\\urllib3\\connectionpool.py\", line 1099, in _validate_conn\n    conn.connect()\n  File \"C:\\Celebal data\\Clients\\Telecom Egypt\\Extract summary\\telecomnew\\telecomnew\\08.06.24_telEg_summ_pipeline\\tempvenv\\Lib\\site-packages\\urllib3\\connection.py\", line 616, in connect\n    self.sock = sock = self._new_conn()\n                       ^^^^^^^^^^^^^^^^\n  File \"C:\\Celebal data\\Clients\\Telecom Egypt\\Extract summary\\telecomnew\\telecomnew\\08.06.24_telEg_summ_pipeline\\tempvenv\\Lib\\site-packages\\urllib3\\connection.py\", line 205, in _new_conn\n    raise NameResolutionError(self.host, self, e) from e\nurllib3.exceptions.NameResolutionError: <urllib3.connection.HTTPSConnection object at 0x00000236B6C3ED10>: Failed to resolve 'demo-langservice-mij.cognitiveservices.azure.com' ([Errno 11001] getaddrinfo failed)\n\nThe above exception was the direct cause of the following exception:\n\nTraceback (most recent call last):\n  File \"C:\\Celebal data\\Clients\\Telecom Egypt\\Extract summary\\telecomnew\\telecomnew\\08.06.24_telEg_summ_pipeline\\tempvenv\\Lib\\site-packages\\requests\\adapters.py\", line 667, in send\n    resp = conn.urlopen(\n           ^^^^^^^^^^^^^\n  File \"C:\\Celebal data\\Clients\\Telecom Egypt\\Extract summary\\telecomnew\\telecomnew\\08.06.24_telEg_summ_pipeline\\tempvenv\\Lib\\site-packages\\urllib3\\connectionpool.py\", line 847, in urlopen\n    retries = retries.increment(\n              ^^^^^^^^^^^^^^^^^^\n  File \"C:\\Celebal data\\Clients\\Telecom Egypt\\Extract summary\\telecomnew\\telecomnew\\08.06.24_telEg_summ_pipeline\\tempvenv\\Lib\\site-packages\\urllib3\\util\\retry.py\", line 515, in increment\n    raise MaxRetryError(_pool, url, reason) from reason  # type: ignore[arg-type]\n    ^^^^^^^^^^^^^^^^^^^^^^^^^^^^^^^^^^^^^^^^^^^^^^^^^^^\nurllib3.exceptions.MaxRetryError: HTTPSConnectionPool(host='demo-langservice-mij.cognitiveservices.azure.com', port=443): Max retries exceeded with url: /language/analyze-text/jobs?api-version=2023-04-01 (Caused by NameResolutionError(\"<urllib3.connection.HTTPSConnection object at 0x00000236B6C3ED10>: Failed to resolve 'demo-langservice-mij.cognitiveservices.azure.com' ([Errno 11001] getaddrinfo failed)\"))\n\nDuring handling of the above exception, another exception occurred:\n\nTraceback (most recent call last):\n  File \"C:\\Celebal data\\Clients\\Telecom Egypt\\Extract summary\\telecomnew\\telecomnew\\08.06.24_telEg_summ_pipeline\\main.py\", line 197, in get_kpis\n    summarisation_obj = Summarization()\n                           ^^^^^^^^^^^^^\n  File \"C:\\Celebal data\\Clients\\Telecom Egypt\\Extract summary\\telecomnew\\telecomnew\\08.06.24_telEg_summ_pipeline\\src\\adapters\\summarisation.py\", line 239, in abstractive_summarisation_helper\n    res = requests.post(url = self.url, headers= headers, json= data)\n          ^^^^^^^^^^^^^^^^^^^^^^^^^^^^^^^^^^^^^^^^^^^^^^^^^^^^^^^^^^^\n  File \"C:\\Celebal data\\Clients\\Telecom Egypt\\Extract summary\\telecomnew\\telecomnew\\08.06.24_telEg_summ_pipeline\\tempvenv\\Lib\\site-packages\\requests\\api.py\", line 115, in post\n    return request(\"post\", url, data=data, json=json, **kwargs)\n           ^^^^^^^^^^^^^^^^^^^^^^^^^^^^^^^^^^^^^^^^^^^^^^^^^^^^\n  File \"C:\\Celebal data\\Clients\\Telecom Egypt\\Extract summary\\telecomnew\\telecomnew\\08.06.24_telEg_summ_pipeline\\tempvenv\\Lib\\site-packages\\requests\\api.py\", line 59, in request\n    return session.request(method=method, url=url, **kwargs)\n           ^^^^^^^^^^^^^^^^^^^^^^^^^^^^^^^^^^^^^^^^^^^^^^^^^\n  File \"C:\\Celebal data\\Clients\\Telecom Egypt\\Extract summary\\telecomnew\\telecomnew\\08.06.24_telEg_summ_pipeline\\tempvenv\\Lib\\site-packages\\requests\\sessions.py\", line 589, in request\n    resp = self.send(prep, **send_kwargs)\n           ^^^^^^^^^^^^^^^^^^^^^^^^^^^^^^\n  File \"C:\\Celebal data\\Clients\\Telecom Egypt\\Extract summary\\telecomnew\\telecomnew\\08.06.24_telEg_summ_pipeline\\tempvenv\\Lib\\site-packages\\requests\\sessions.py\", line 703, in send\n    r = adapter.send(request, **kwargs)\n        ^^^^^^^^^^^^^^^^^^^^^^^^^^^^^^^\n  File \"C:\\Celebal data\\Clients\\Telecom Egypt\\Extract summary\\telecomnew\\telecomnew\\08.06.24_telEg_summ_pipeline\\tempvenv\\Lib\\site-packages\\requests\\adapters.py\", line 700, in send\n    raise ConnectionError(e, request=request)\nrequests.exceptions.ConnectionError: HTTPSConnectionPool(host='demo-langservice-mij.cognitiveservices.azure.com', port=443): Max retries exceeded with url: /language/analyze-text/jobs?api-version=2023-04-01 (Caused by NameResolutionError(\"<urllib3.connection.HTTPSConnection object at 0x00000236B6C3ED10>: Failed to resolve 'demo-langservice-mij.cognitiveservices.azure.com' ([Errno 11001] getaddrinfo failed)\"))", "location": "main.py - pipeline_after_transcription"}
{"asctime": "2024-06-09 T02:14:47+0530", "message": "An Error Occured: 'NoneType' object is not subscriptable", "exc_info": "Traceback (most recent call last):\n  File \"C:\\Celebal data\\Clients\\Telecom Egypt\\Extract summary\\telecomnew\\telecomnew\\08.06.24_telEg_summ_pipeline\\main.py\", line 293, in add_summarization_to_mapping\nTypeError: 'NoneType' object is not subscriptable", "location": "main.py - add_summarization_to_mapping"}
{"asctime": "2024-06-09 T02:14:47+0530", "message": "An Error Occurred: 'summarization_en'", "exc_info": "Traceback (most recent call last):\n  File \"C:\\Celebal data\\Clients\\Telecom Egypt\\Extract summary\\telecomnew\\telecomnew\\08.06.24_telEg_summ_pipeline\\main.py\", line 331, in add_mapping_to_excel\n    Comment_ls.append(call_data['Comment'])\n                               ^^^^^^^^^^^^^\nKeyError: 'summarization_en'", "location": "main.py - add_mapping_to_excel"}
{"asctime": "2024-06-09 T02:14:47+0530", "message": "An Error Occured: 'NoneType' object is not subscriptable", "exc_info": "Traceback (most recent call last):\n  File \"C:\\Celebal data\\Clients\\Telecom Egypt\\Extract summary\\telecomnew\\telecomnew\\08.06.24_telEg_summ_pipeline\\main.py\", line 399, in pipeline_after_transcription\nTypeError: 'NoneType' object is not subscriptable", "location": "main.py - pipeline_after_transcription"}
{"asctime": "2024-06-09 T02:15:48+0530", "message": "An Error Occured: HTTPSConnectionPool(host='demo-langservice-mij.cognitiveservices.azure.com', port=443): Max retries exceeded with url: /language/analyze-text/jobs?api-version=2023-04-01 (Caused by NameResolutionError(\"<urllib3.connection.HTTPSConnection object at 0x00000236B6C3DE10>: Failed to resolve 'demo-langservice-mij.cognitiveservices.azure.com' ([Errno 11001] getaddrinfo failed)\"))", "exc_info": "Traceback (most recent call last):\n  File \"C:\\Celebal data\\Clients\\Telecom Egypt\\Extract summary\\telecomnew\\telecomnew\\08.06.24_telEg_summ_pipeline\\tempvenv\\Lib\\site-packages\\urllib3\\connection.py\", line 198, in _new_conn\n    sock = connection.create_connection(\n           ^^^^^^^^^^^^^^^^^^^^^^^^^^^^^\n  File \"C:\\Celebal data\\Clients\\Telecom Egypt\\Extract summary\\telecomnew\\telecomnew\\08.06.24_telEg_summ_pipeline\\tempvenv\\Lib\\site-packages\\urllib3\\util\\connection.py\", line 60, in create_connection\n    for res in socket.getaddrinfo(host, port, family, socket.SOCK_STREAM):\n               ^^^^^^^^^^^^^^^^^^^^^^^^^^^^^^^^^^^^^^^^^^^^^^^^^^^^^^^^^^\n  File \"C:\\Users\\MaharshiJasraj\\AppData\\Local\\Programs\\Python\\Python311\\Lib\\socket.py\", line 962, in getaddrinfo\n    for res in _socket.getaddrinfo(host, port, family, type, proto, flags):\n               ^^^^^^^^^^^^^^^^^^^^^^^^^^^^^^^^^^^^^^^^^^^^^^^^^^^^^^^^^^^\nsocket.gaierror: [Errno 11001] getaddrinfo failed\n\nThe above exception was the direct cause of the following exception:\n\nTraceback (most recent call last):\n  File \"C:\\Celebal data\\Clients\\Telecom Egypt\\Extract summary\\telecomnew\\telecomnew\\08.06.24_telEg_summ_pipeline\\tempvenv\\Lib\\site-packages\\urllib3\\connectionpool.py\", line 793, in urlopen\n    response = self._make_request(\n               ^^^^^^^^^^^^^^^^^^^\n  File \"C:\\Celebal data\\Clients\\Telecom Egypt\\Extract summary\\telecomnew\\telecomnew\\08.06.24_telEg_summ_pipeline\\tempvenv\\Lib\\site-packages\\urllib3\\connectionpool.py\", line 491, in _make_request\n    raise new_e\n  File \"C:\\Celebal data\\Clients\\Telecom Egypt\\Extract summary\\telecomnew\\telecomnew\\08.06.24_telEg_summ_pipeline\\tempvenv\\Lib\\site-packages\\urllib3\\connectionpool.py\", line 467, in _make_request\n    self._validate_conn(conn)\n  File \"C:\\Celebal data\\Clients\\Telecom Egypt\\Extract summary\\telecomnew\\telecomnew\\08.06.24_telEg_summ_pipeline\\tempvenv\\Lib\\site-packages\\urllib3\\connectionpool.py\", line 1099, in _validate_conn\n    conn.connect()\n  File \"C:\\Celebal data\\Clients\\Telecom Egypt\\Extract summary\\telecomnew\\telecomnew\\08.06.24_telEg_summ_pipeline\\tempvenv\\Lib\\site-packages\\urllib3\\connection.py\", line 616, in connect\n    self.sock = sock = self._new_conn()\n                       ^^^^^^^^^^^^^^^^\n  File \"C:\\Celebal data\\Clients\\Telecom Egypt\\Extract summary\\telecomnew\\telecomnew\\08.06.24_telEg_summ_pipeline\\tempvenv\\Lib\\site-packages\\urllib3\\connection.py\", line 205, in _new_conn\n    raise NameResolutionError(self.host, self, e) from e\nurllib3.exceptions.NameResolutionError: <urllib3.connection.HTTPSConnection object at 0x00000236B6C3DE10>: Failed to resolve 'demo-langservice-mij.cognitiveservices.azure.com' ([Errno 11001] getaddrinfo failed)\n\nThe above exception was the direct cause of the following exception:\n\nTraceback (most recent call last):\n  File \"C:\\Celebal data\\Clients\\Telecom Egypt\\Extract summary\\telecomnew\\telecomnew\\08.06.24_telEg_summ_pipeline\\tempvenv\\Lib\\site-packages\\requests\\adapters.py\", line 667, in send\n    resp = conn.urlopen(\n           ^^^^^^^^^^^^^\n  File \"C:\\Celebal data\\Clients\\Telecom Egypt\\Extract summary\\telecomnew\\telecomnew\\08.06.24_telEg_summ_pipeline\\tempvenv\\Lib\\site-packages\\urllib3\\connectionpool.py\", line 847, in urlopen\n    retries = retries.increment(\n              ^^^^^^^^^^^^^^^^^^\n  File \"C:\\Celebal data\\Clients\\Telecom Egypt\\Extract summary\\telecomnew\\telecomnew\\08.06.24_telEg_summ_pipeline\\tempvenv\\Lib\\site-packages\\urllib3\\util\\retry.py\", line 515, in increment\n    raise MaxRetryError(_pool, url, reason) from reason  # type: ignore[arg-type]\n    ^^^^^^^^^^^^^^^^^^^^^^^^^^^^^^^^^^^^^^^^^^^^^^^^^^^\nurllib3.exceptions.MaxRetryError: HTTPSConnectionPool(host='demo-langservice-mij.cognitiveservices.azure.com', port=443): Max retries exceeded with url: /language/analyze-text/jobs?api-version=2023-04-01 (Caused by NameResolutionError(\"<urllib3.connection.HTTPSConnection object at 0x00000236B6C3DE10>: Failed to resolve 'demo-langservice-mij.cognitiveservices.azure.com' ([Errno 11001] getaddrinfo failed)\"))\n\nDuring handling of the above exception, another exception occurred:\n\nTraceback (most recent call last):\n  File \"C:\\Celebal data\\Clients\\Telecom Egypt\\Extract summary\\telecomnew\\telecomnew\\08.06.24_telEg_summ_pipeline\\main.py\", line 197, in get_kpis\n    summarisation_obj = Summarization()\n                           ^^^^^^^^^^^^^\n  File \"C:\\Celebal data\\Clients\\Telecom Egypt\\Extract summary\\telecomnew\\telecomnew\\08.06.24_telEg_summ_pipeline\\src\\adapters\\summarisation.py\", line 239, in abstractive_summarisation_helper\n    res = requests.post(url = self.url, headers= headers, json= data)\n          ^^^^^^^^^^^^^^^^^^^^^^^^^^^^^^^^^^^^^^^^^^^^^^^^^^^^^^^^^^^\n  File \"C:\\Celebal data\\Clients\\Telecom Egypt\\Extract summary\\telecomnew\\telecomnew\\08.06.24_telEg_summ_pipeline\\tempvenv\\Lib\\site-packages\\requests\\api.py\", line 115, in post\n    return request(\"post\", url, data=data, json=json, **kwargs)\n           ^^^^^^^^^^^^^^^^^^^^^^^^^^^^^^^^^^^^^^^^^^^^^^^^^^^^\n  File \"C:\\Celebal data\\Clients\\Telecom Egypt\\Extract summary\\telecomnew\\telecomnew\\08.06.24_telEg_summ_pipeline\\tempvenv\\Lib\\site-packages\\requests\\api.py\", line 59, in request\n    return session.request(method=method, url=url, **kwargs)\n           ^^^^^^^^^^^^^^^^^^^^^^^^^^^^^^^^^^^^^^^^^^^^^^^^^\n  File \"C:\\Celebal data\\Clients\\Telecom Egypt\\Extract summary\\telecomnew\\telecomnew\\08.06.24_telEg_summ_pipeline\\tempvenv\\Lib\\site-packages\\requests\\sessions.py\", line 589, in request\n    resp = self.send(prep, **send_kwargs)\n           ^^^^^^^^^^^^^^^^^^^^^^^^^^^^^^\n  File \"C:\\Celebal data\\Clients\\Telecom Egypt\\Extract summary\\telecomnew\\telecomnew\\08.06.24_telEg_summ_pipeline\\tempvenv\\Lib\\site-packages\\requests\\sessions.py\", line 703, in send\n    r = adapter.send(request, **kwargs)\n        ^^^^^^^^^^^^^^^^^^^^^^^^^^^^^^^\n  File \"C:\\Celebal data\\Clients\\Telecom Egypt\\Extract summary\\telecomnew\\telecomnew\\08.06.24_telEg_summ_pipeline\\tempvenv\\Lib\\site-packages\\requests\\adapters.py\", line 700, in send\n    raise ConnectionError(e, request=request)\nrequests.exceptions.ConnectionError: HTTPSConnectionPool(host='demo-langservice-mij.cognitiveservices.azure.com', port=443): Max retries exceeded with url: /language/analyze-text/jobs?api-version=2023-04-01 (Caused by NameResolutionError(\"<urllib3.connection.HTTPSConnection object at 0x00000236B6C3DE10>: Failed to resolve 'demo-langservice-mij.cognitiveservices.azure.com' ([Errno 11001] getaddrinfo failed)\"))", "location": "main.py - pipeline_after_transcription"}
{"asctime": "2024-06-09 T02:15:49+0530", "message": "An Error Occured: 'NoneType' object is not subscriptable", "exc_info": "Traceback (most recent call last):\n  File \"C:\\Celebal data\\Clients\\Telecom Egypt\\Extract summary\\telecomnew\\telecomnew\\08.06.24_telEg_summ_pipeline\\main.py\", line 293, in add_summarization_to_mapping\nTypeError: 'NoneType' object is not subscriptable", "location": "main.py - add_summarization_to_mapping"}
{"asctime": "2024-06-09 T02:15:49+0530", "message": "An Error Occurred: 'summarization_en'", "exc_info": "Traceback (most recent call last):\n  File \"C:\\Celebal data\\Clients\\Telecom Egypt\\Extract summary\\telecomnew\\telecomnew\\08.06.24_telEg_summ_pipeline\\main.py\", line 331, in add_mapping_to_excel\n    Comment_ls.append(call_data['Comment'])\n                               ^^^^^^^^^^^^^\nKeyError: 'summarization_en'", "location": "main.py - add_mapping_to_excel"}
{"asctime": "2024-06-09 T02:15:49+0530", "message": "An Error Occured: 'NoneType' object is not subscriptable", "exc_info": "Traceback (most recent call last):\n  File \"C:\\Celebal data\\Clients\\Telecom Egypt\\Extract summary\\telecomnew\\telecomnew\\08.06.24_telEg_summ_pipeline\\main.py\", line 399, in pipeline_after_transcription\nTypeError: 'NoneType' object is not subscriptable", "location": "main.py - pipeline_after_transcription"}
{"asctime": "2024-06-09 T02:16:41+0530", "message": "An Error Occurred: 'summarization_en'", "exc_info": "Traceback (most recent call last):\n  File \"C:\\Celebal data\\Clients\\Telecom Egypt\\Extract summary\\telecomnew\\telecomnew\\08.06.24_telEg_summ_pipeline\\main.py\", line 331, in add_mapping_to_excel\n    Comment_ls.append(call_data['Comment'])\n                               ^^^^^^^^^^^^^\nKeyError: 'summarization_en'", "location": "main.py - add_mapping_to_excel"}
{"asctime": "2024-06-09 T02:16:41+0530", "message": "An Error Occured: 'keyPhrases_ls'", "exc_info": "Traceback (most recent call last):\n  File \"C:\\Celebal data\\Clients\\Telecom Egypt\\Extract summary\\telecomnew\\telecomnew\\08.06.24_telEg_summ_pipeline\\main.py\", line 480, in pipeline_after_transcription\n    self.merge_keyphrases_with_transcription(\n        ^^^^^^^^^^^^^^^^^^^^^^^\nKeyError: 'keyPhrases_ls'", "location": "main.py - pipeline_after_transcription"}
{"asctime": "2024-06-09 T02:17:42+0530", "message": "An Error Occured: HTTPSConnectionPool(host='demo-langservice-mij.cognitiveservices.azure.com', port=443): Max retries exceeded with url: /language/analyze-text/jobs?api-version=2023-04-01 (Caused by NameResolutionError(\"<urllib3.connection.HTTPSConnection object at 0x00000236B6BD8D50>: Failed to resolve 'demo-langservice-mij.cognitiveservices.azure.com' ([Errno 11001] getaddrinfo failed)\"))", "exc_info": "Traceback (most recent call last):\n  File \"C:\\Celebal data\\Clients\\Telecom Egypt\\Extract summary\\telecomnew\\telecomnew\\08.06.24_telEg_summ_pipeline\\tempvenv\\Lib\\site-packages\\urllib3\\connection.py\", line 198, in _new_conn\n    sock = connection.create_connection(\n           ^^^^^^^^^^^^^^^^^^^^^^^^^^^^^\n  File \"C:\\Celebal data\\Clients\\Telecom Egypt\\Extract summary\\telecomnew\\telecomnew\\08.06.24_telEg_summ_pipeline\\tempvenv\\Lib\\site-packages\\urllib3\\util\\connection.py\", line 60, in create_connection\n    for res in socket.getaddrinfo(host, port, family, socket.SOCK_STREAM):\n               ^^^^^^^^^^^^^^^^^^^^^^^^^^^^^^^^^^^^^^^^^^^^^^^^^^^^^^^^^^\n  File \"C:\\Users\\MaharshiJasraj\\AppData\\Local\\Programs\\Python\\Python311\\Lib\\socket.py\", line 962, in getaddrinfo\n    for res in _socket.getaddrinfo(host, port, family, type, proto, flags):\n               ^^^^^^^^^^^^^^^^^^^^^^^^^^^^^^^^^^^^^^^^^^^^^^^^^^^^^^^^^^^\nsocket.gaierror: [Errno 11001] getaddrinfo failed\n\nThe above exception was the direct cause of the following exception:\n\nTraceback (most recent call last):\n  File \"C:\\Celebal data\\Clients\\Telecom Egypt\\Extract summary\\telecomnew\\telecomnew\\08.06.24_telEg_summ_pipeline\\tempvenv\\Lib\\site-packages\\urllib3\\connectionpool.py\", line 793, in urlopen\n    response = self._make_request(\n               ^^^^^^^^^^^^^^^^^^^\n  File \"C:\\Celebal data\\Clients\\Telecom Egypt\\Extract summary\\telecomnew\\telecomnew\\08.06.24_telEg_summ_pipeline\\tempvenv\\Lib\\site-packages\\urllib3\\connectionpool.py\", line 491, in _make_request\n    raise new_e\n  File \"C:\\Celebal data\\Clients\\Telecom Egypt\\Extract summary\\telecomnew\\telecomnew\\08.06.24_telEg_summ_pipeline\\tempvenv\\Lib\\site-packages\\urllib3\\connectionpool.py\", line 467, in _make_request\n    self._validate_conn(conn)\n  File \"C:\\Celebal data\\Clients\\Telecom Egypt\\Extract summary\\telecomnew\\telecomnew\\08.06.24_telEg_summ_pipeline\\tempvenv\\Lib\\site-packages\\urllib3\\connectionpool.py\", line 1099, in _validate_conn\n    conn.connect()\n  File \"C:\\Celebal data\\Clients\\Telecom Egypt\\Extract summary\\telecomnew\\telecomnew\\08.06.24_telEg_summ_pipeline\\tempvenv\\Lib\\site-packages\\urllib3\\connection.py\", line 616, in connect\n    self.sock = sock = self._new_conn()\n                       ^^^^^^^^^^^^^^^^\n  File \"C:\\Celebal data\\Clients\\Telecom Egypt\\Extract summary\\telecomnew\\telecomnew\\08.06.24_telEg_summ_pipeline\\tempvenv\\Lib\\site-packages\\urllib3\\connection.py\", line 205, in _new_conn\n    raise NameResolutionError(self.host, self, e) from e\nurllib3.exceptions.NameResolutionError: <urllib3.connection.HTTPSConnection object at 0x00000236B6BD8D50>: Failed to resolve 'demo-langservice-mij.cognitiveservices.azure.com' ([Errno 11001] getaddrinfo failed)\n\nThe above exception was the direct cause of the following exception:\n\nTraceback (most recent call last):\n  File \"C:\\Celebal data\\Clients\\Telecom Egypt\\Extract summary\\telecomnew\\telecomnew\\08.06.24_telEg_summ_pipeline\\tempvenv\\Lib\\site-packages\\requests\\adapters.py\", line 667, in send\n    resp = conn.urlopen(\n           ^^^^^^^^^^^^^\n  File \"C:\\Celebal data\\Clients\\Telecom Egypt\\Extract summary\\telecomnew\\telecomnew\\08.06.24_telEg_summ_pipeline\\tempvenv\\Lib\\site-packages\\urllib3\\connectionpool.py\", line 847, in urlopen\n    retries = retries.increment(\n              ^^^^^^^^^^^^^^^^^^\n  File \"C:\\Celebal data\\Clients\\Telecom Egypt\\Extract summary\\telecomnew\\telecomnew\\08.06.24_telEg_summ_pipeline\\tempvenv\\Lib\\site-packages\\urllib3\\util\\retry.py\", line 515, in increment\n    raise MaxRetryError(_pool, url, reason) from reason  # type: ignore[arg-type]\n    ^^^^^^^^^^^^^^^^^^^^^^^^^^^^^^^^^^^^^^^^^^^^^^^^^^^\nurllib3.exceptions.MaxRetryError: HTTPSConnectionPool(host='demo-langservice-mij.cognitiveservices.azure.com', port=443): Max retries exceeded with url: /language/analyze-text/jobs?api-version=2023-04-01 (Caused by NameResolutionError(\"<urllib3.connection.HTTPSConnection object at 0x00000236B6BD8D50>: Failed to resolve 'demo-langservice-mij.cognitiveservices.azure.com' ([Errno 11001] getaddrinfo failed)\"))\n\nDuring handling of the above exception, another exception occurred:\n\nTraceback (most recent call last):\n  File \"C:\\Celebal data\\Clients\\Telecom Egypt\\Extract summary\\telecomnew\\telecomnew\\08.06.24_telEg_summ_pipeline\\main.py\", line 197, in get_kpis\n    summarisation_obj = Summarization()\n                           ^^^^^^^^^^^^^\n  File \"C:\\Celebal data\\Clients\\Telecom Egypt\\Extract summary\\telecomnew\\telecomnew\\08.06.24_telEg_summ_pipeline\\src\\adapters\\summarisation.py\", line 239, in abstractive_summarisation_helper\n    res = requests.post(url = self.url, headers= headers, json= data)\n          ^^^^^^^^^^^^^^^^^^^^^^^^^^^^^^^^^^^^^^^^^^^^^^^^^^^^^^^^^^^\n  File \"C:\\Celebal data\\Clients\\Telecom Egypt\\Extract summary\\telecomnew\\telecomnew\\08.06.24_telEg_summ_pipeline\\tempvenv\\Lib\\site-packages\\requests\\api.py\", line 115, in post\n    return request(\"post\", url, data=data, json=json, **kwargs)\n           ^^^^^^^^^^^^^^^^^^^^^^^^^^^^^^^^^^^^^^^^^^^^^^^^^^^^\n  File \"C:\\Celebal data\\Clients\\Telecom Egypt\\Extract summary\\telecomnew\\telecomnew\\08.06.24_telEg_summ_pipeline\\tempvenv\\Lib\\site-packages\\requests\\api.py\", line 59, in request\n    return session.request(method=method, url=url, **kwargs)\n           ^^^^^^^^^^^^^^^^^^^^^^^^^^^^^^^^^^^^^^^^^^^^^^^^^\n  File \"C:\\Celebal data\\Clients\\Telecom Egypt\\Extract summary\\telecomnew\\telecomnew\\08.06.24_telEg_summ_pipeline\\tempvenv\\Lib\\site-packages\\requests\\sessions.py\", line 589, in request\n    resp = self.send(prep, **send_kwargs)\n           ^^^^^^^^^^^^^^^^^^^^^^^^^^^^^^\n  File \"C:\\Celebal data\\Clients\\Telecom Egypt\\Extract summary\\telecomnew\\telecomnew\\08.06.24_telEg_summ_pipeline\\tempvenv\\Lib\\site-packages\\requests\\sessions.py\", line 703, in send\n    r = adapter.send(request, **kwargs)\n        ^^^^^^^^^^^^^^^^^^^^^^^^^^^^^^^\n  File \"C:\\Celebal data\\Clients\\Telecom Egypt\\Extract summary\\telecomnew\\telecomnew\\08.06.24_telEg_summ_pipeline\\tempvenv\\Lib\\site-packages\\requests\\adapters.py\", line 700, in send\n    raise ConnectionError(e, request=request)\nrequests.exceptions.ConnectionError: HTTPSConnectionPool(host='demo-langservice-mij.cognitiveservices.azure.com', port=443): Max retries exceeded with url: /language/analyze-text/jobs?api-version=2023-04-01 (Caused by NameResolutionError(\"<urllib3.connection.HTTPSConnection object at 0x00000236B6BD8D50>: Failed to resolve 'demo-langservice-mij.cognitiveservices.azure.com' ([Errno 11001] getaddrinfo failed)\"))", "location": "main.py - pipeline_after_transcription"}
{"asctime": "2024-06-09 T02:17:42+0530", "message": "An Error Occured: 'NoneType' object is not subscriptable", "exc_info": "Traceback (most recent call last):\n  File \"C:\\Celebal data\\Clients\\Telecom Egypt\\Extract summary\\telecomnew\\telecomnew\\08.06.24_telEg_summ_pipeline\\main.py\", line 293, in add_summarization_to_mapping\nTypeError: 'NoneType' object is not subscriptable", "location": "main.py - add_summarization_to_mapping"}
{"asctime": "2024-06-09 T02:17:42+0530", "message": "An Error Occurred: 'summarization_en'", "exc_info": "Traceback (most recent call last):\n  File \"C:\\Celebal data\\Clients\\Telecom Egypt\\Extract summary\\telecomnew\\telecomnew\\08.06.24_telEg_summ_pipeline\\main.py\", line 331, in add_mapping_to_excel\n    Comment_ls.append(call_data['Comment'])\n                               ^^^^^^^^^^^^^\nKeyError: 'summarization_en'", "location": "main.py - add_mapping_to_excel"}
{"asctime": "2024-06-09 T02:17:42+0530", "message": "An Error Occured: 'NoneType' object is not subscriptable", "exc_info": "Traceback (most recent call last):\n  File \"C:\\Celebal data\\Clients\\Telecom Egypt\\Extract summary\\telecomnew\\telecomnew\\08.06.24_telEg_summ_pipeline\\main.py\", line 399, in pipeline_after_transcription\nTypeError: 'NoneType' object is not subscriptable", "location": "main.py - pipeline_after_transcription"}
{"asctime": "2024-06-09 T02:27:26+0530", "message": "An Error Occured: HTTPSConnectionPool(host='demo-langservice-mij.cognitiveservices.azure.com', port=443): Max retries exceeded with url: /language/analyze-text/jobs?api-version=2023-04-01 (Caused by NameResolutionError(\"<urllib3.connection.HTTPSConnection object at 0x000002BDBDA1FE50>: Failed to resolve 'demo-langservice-mij.cognitiveservices.azure.com' ([Errno 11001] getaddrinfo failed)\"))", "exc_info": "Traceback (most recent call last):\n  File \"C:\\Celebal data\\Clients\\Telecom Egypt\\Extract summary\\telecomnew\\telecomnew\\08.06.24_telEg_summ_pipeline\\tempvenv\\Lib\\site-packages\\urllib3\\connection.py\", line 198, in _new_conn\n    sock = connection.create_connection(\n           ^^^^^^^^^^^^^^^^^^^^^^^^^^^^^\n  File \"C:\\Celebal data\\Clients\\Telecom Egypt\\Extract summary\\telecomnew\\telecomnew\\08.06.24_telEg_summ_pipeline\\tempvenv\\Lib\\site-packages\\urllib3\\util\\connection.py\", line 60, in create_connection\n    for res in socket.getaddrinfo(host, port, family, socket.SOCK_STREAM):\n               ^^^^^^^^^^^^^^^^^^^^^^^^^^^^^^^^^^^^^^^^^^^^^^^^^^^^^^^^^^\n  File \"C:\\Users\\MaharshiJasraj\\AppData\\Local\\Programs\\Python\\Python311\\Lib\\socket.py\", line 962, in getaddrinfo\n    for res in _socket.getaddrinfo(host, port, family, type, proto, flags):\n               ^^^^^^^^^^^^^^^^^^^^^^^^^^^^^^^^^^^^^^^^^^^^^^^^^^^^^^^^^^^\nsocket.gaierror: [Errno 11001] getaddrinfo failed\n\nThe above exception was the direct cause of the following exception:\n\nTraceback (most recent call last):\n  File \"C:\\Celebal data\\Clients\\Telecom Egypt\\Extract summary\\telecomnew\\telecomnew\\08.06.24_telEg_summ_pipeline\\tempvenv\\Lib\\site-packages\\urllib3\\connectionpool.py\", line 793, in urlopen\n    response = self._make_request(\n               ^^^^^^^^^^^^^^^^^^^\n  File \"C:\\Celebal data\\Clients\\Telecom Egypt\\Extract summary\\telecomnew\\telecomnew\\08.06.24_telEg_summ_pipeline\\tempvenv\\Lib\\site-packages\\urllib3\\connectionpool.py\", line 491, in _make_request\n    raise new_e\n  File \"C:\\Celebal data\\Clients\\Telecom Egypt\\Extract summary\\telecomnew\\telecomnew\\08.06.24_telEg_summ_pipeline\\tempvenv\\Lib\\site-packages\\urllib3\\connectionpool.py\", line 467, in _make_request\n    self._validate_conn(conn)\n  File \"C:\\Celebal data\\Clients\\Telecom Egypt\\Extract summary\\telecomnew\\telecomnew\\08.06.24_telEg_summ_pipeline\\tempvenv\\Lib\\site-packages\\urllib3\\connectionpool.py\", line 1099, in _validate_conn\n    conn.connect()\n  File \"C:\\Celebal data\\Clients\\Telecom Egypt\\Extract summary\\telecomnew\\telecomnew\\08.06.24_telEg_summ_pipeline\\tempvenv\\Lib\\site-packages\\urllib3\\connection.py\", line 616, in connect\n    self.sock = sock = self._new_conn()\n                       ^^^^^^^^^^^^^^^^\n  File \"C:\\Celebal data\\Clients\\Telecom Egypt\\Extract summary\\telecomnew\\telecomnew\\08.06.24_telEg_summ_pipeline\\tempvenv\\Lib\\site-packages\\urllib3\\connection.py\", line 205, in _new_conn\n    raise NameResolutionError(self.host, self, e) from e\nurllib3.exceptions.NameResolutionError: <urllib3.connection.HTTPSConnection object at 0x000002BDBDA1FE50>: Failed to resolve 'demo-langservice-mij.cognitiveservices.azure.com' ([Errno 11001] getaddrinfo failed)\n\nThe above exception was the direct cause of the following exception:\n\nTraceback (most recent call last):\n  File \"C:\\Celebal data\\Clients\\Telecom Egypt\\Extract summary\\telecomnew\\telecomnew\\08.06.24_telEg_summ_pipeline\\tempvenv\\Lib\\site-packages\\requests\\adapters.py\", line 667, in send\n    resp = conn.urlopen(\n           ^^^^^^^^^^^^^\n  File \"C:\\Celebal data\\Clients\\Telecom Egypt\\Extract summary\\telecomnew\\telecomnew\\08.06.24_telEg_summ_pipeline\\tempvenv\\Lib\\site-packages\\urllib3\\connectionpool.py\", line 847, in urlopen\n    retries = retries.increment(\n              ^^^^^^^^^^^^^^^^^^\n  File \"C:\\Celebal data\\Clients\\Telecom Egypt\\Extract summary\\telecomnew\\telecomnew\\08.06.24_telEg_summ_pipeline\\tempvenv\\Lib\\site-packages\\urllib3\\util\\retry.py\", line 515, in increment\n    raise MaxRetryError(_pool, url, reason) from reason  # type: ignore[arg-type]\n    ^^^^^^^^^^^^^^^^^^^^^^^^^^^^^^^^^^^^^^^^^^^^^^^^^^^\nurllib3.exceptions.MaxRetryError: HTTPSConnectionPool(host='demo-langservice-mij.cognitiveservices.azure.com', port=443): Max retries exceeded with url: /language/analyze-text/jobs?api-version=2023-04-01 (Caused by NameResolutionError(\"<urllib3.connection.HTTPSConnection object at 0x000002BDBDA1FE50>: Failed to resolve 'demo-langservice-mij.cognitiveservices.azure.com' ([Errno 11001] getaddrinfo failed)\"))\n\nDuring handling of the above exception, another exception occurred:\n\nTraceback (most recent call last):\n  File \"C:\\Celebal data\\Clients\\Telecom Egypt\\Extract summary\\telecomnew\\telecomnew\\08.06.24_telEg_summ_pipeline\\main.py\", line 198, in get_kpis\n    summarisation_result = summarisation_obj.abstractive_summarisation_helper(call)\n                           ^^^^^^^^^^^^^^^^^^^^^^^^^^^^^^^^^^^^^^^^^^^^^^^^^^^^^^^^\n  File \"C:\\Celebal data\\Clients\\Telecom Egypt\\Extract summary\\telecomnew\\telecomnew\\08.06.24_telEg_summ_pipeline\\src\\adapters\\summarisation.py\", line 239, in abstractive_summarisation_helper\n    res = requests.post(url = self.url, headers= headers, json= data)\n          ^^^^^^^^^^^^^^^^^^^^^^^^^^^^^^^^^^^^^^^^^^^^^^^^^^^^^^^^^^^\n  File \"C:\\Celebal data\\Clients\\Telecom Egypt\\Extract summary\\telecomnew\\telecomnew\\08.06.24_telEg_summ_pipeline\\tempvenv\\Lib\\site-packages\\requests\\api.py\", line 115, in post\n    return request(\"post\", url, data=data, json=json, **kwargs)\n           ^^^^^^^^^^^^^^^^^^^^^^^^^^^^^^^^^^^^^^^^^^^^^^^^^^^^\n  File \"C:\\Celebal data\\Clients\\Telecom Egypt\\Extract summary\\telecomnew\\telecomnew\\08.06.24_telEg_summ_pipeline\\tempvenv\\Lib\\site-packages\\requests\\api.py\", line 59, in request\n    return session.request(method=method, url=url, **kwargs)\n           ^^^^^^^^^^^^^^^^^^^^^^^^^^^^^^^^^^^^^^^^^^^^^^^^^\n  File \"C:\\Celebal data\\Clients\\Telecom Egypt\\Extract summary\\telecomnew\\telecomnew\\08.06.24_telEg_summ_pipeline\\tempvenv\\Lib\\site-packages\\requests\\sessions.py\", line 589, in request\n    resp = self.send(prep, **send_kwargs)\n           ^^^^^^^^^^^^^^^^^^^^^^^^^^^^^^\n  File \"C:\\Celebal data\\Clients\\Telecom Egypt\\Extract summary\\telecomnew\\telecomnew\\08.06.24_telEg_summ_pipeline\\tempvenv\\Lib\\site-packages\\requests\\sessions.py\", line 703, in send\n    r = adapter.send(request, **kwargs)\n        ^^^^^^^^^^^^^^^^^^^^^^^^^^^^^^^\n  File \"C:\\Celebal data\\Clients\\Telecom Egypt\\Extract summary\\telecomnew\\telecomnew\\08.06.24_telEg_summ_pipeline\\tempvenv\\Lib\\site-packages\\requests\\adapters.py\", line 700, in send\n    raise ConnectionError(e, request=request)\nrequests.exceptions.ConnectionError: HTTPSConnectionPool(host='demo-langservice-mij.cognitiveservices.azure.com', port=443): Max retries exceeded with url: /language/analyze-text/jobs?api-version=2023-04-01 (Caused by NameResolutionError(\"<urllib3.connection.HTTPSConnection object at 0x000002BDBDA1FE50>: Failed to resolve 'demo-langservice-mij.cognitiveservices.azure.com' ([Errno 11001] getaddrinfo failed)\"))", "location": "main.py - pipeline_after_transcription"}
{"asctime": "2024-06-09 T02:27:26+0530", "message": "An Error Occured: 'Main' object has no attribute 'summarisation_result'", "exc_info": "Traceback (most recent call last):\n  File \"C:\\Celebal data\\Clients\\Telecom Egypt\\Extract summary\\telecomnew\\telecomnew\\08.06.24_telEg_summ_pipeline\\main.py\", line 244, in get_kpis_arabic\n    eng_summ_result = self.summarisation_result\n                      ^^^^^^^^^^^^^^^^^^^^^^^^^\nAttributeError: 'Main' object has no attribute 'summarisation_result'", "location": "main.py - pipeline_after_transcription"}
{"asctime": "2024-06-09 T02:27:26+0530", "message": "An Error Occured: 'NoneType' object is not subscriptable", "exc_info": "Traceback (most recent call last):\n  File \"C:\\Celebal data\\Clients\\Telecom Egypt\\Extract summary\\telecomnew\\telecomnew\\08.06.24_telEg_summ_pipeline\\main.py\", line 294, in add_summarization_to_mapping\n    print(f\"adding the data to the mapping for key : {summarized_key} with value {summarized_text['summary']}\")\n                                                                                  ~~~~~~~~~~~~~~~^^^^^^^^^^^\nTypeError: 'NoneType' object is not subscriptable", "location": "main.py - add_summarization_to_mapping"}
{"asctime": "2024-06-09 T02:27:26+0530", "message": "An Error Occured: 'NoneType' object is not subscriptable", "exc_info": "Traceback (most recent call last):\n  File \"C:\\Celebal data\\Clients\\Telecom Egypt\\Extract summary\\telecomnew\\telecomnew\\08.06.24_telEg_summ_pipeline\\main.py\", line 294, in add_summarization_to_mapping\n    print(f\"adding the data to the mapping for key : {summarized_key} with value {summarized_text['summary']}\")\n                                                                                  ~~~~~~~~~~~~~~~^^^^^^^^^^^\nTypeError: 'NoneType' object is not subscriptable", "location": "main.py - add_summarization_to_mapping"}
{"asctime": "2024-06-09 T02:27:26+0530", "message": "An Error Occured: 'NoneType' object is not subscriptable", "exc_info": "Traceback (most recent call last):\n  File \"C:\\Celebal data\\Clients\\Telecom Egypt\\Extract summary\\telecomnew\\telecomnew\\08.06.24_telEg_summ_pipeline\\main.py\", line 400, in pipeline_after_transcription\n    merged_output[\"result\"][\"summary\"] = result[\"summary\"]\n                                         ~~~~~~^^^^^^^^^^^\nTypeError: 'NoneType' object is not subscriptable", "location": "main.py - pipeline_after_transcription"}
{"asctime": "2024-06-09 T02:29:17+0530", "message": "An Error Occured: HTTPSConnectionPool(host='demo-langservice-mij.cognitiveservices.azure.com', port=443): Max retries exceeded with url: /language/analyze-text/jobs?api-version=2023-04-01 (Caused by NameResolutionError(\"<urllib3.connection.HTTPSConnection object at 0x000002BDBDA8E850>: Failed to resolve 'demo-langservice-mij.cognitiveservices.azure.com' ([Errno 11001] getaddrinfo failed)\"))", "exc_info": "Traceback (most recent call last):\n  File \"C:\\Celebal data\\Clients\\Telecom Egypt\\Extract summary\\telecomnew\\telecomnew\\08.06.24_telEg_summ_pipeline\\tempvenv\\Lib\\site-packages\\urllib3\\connection.py\", line 198, in _new_conn\n    sock = connection.create_connection(\n           ^^^^^^^^^^^^^^^^^^^^^^^^^^^^^\n  File \"C:\\Celebal data\\Clients\\Telecom Egypt\\Extract summary\\telecomnew\\telecomnew\\08.06.24_telEg_summ_pipeline\\tempvenv\\Lib\\site-packages\\urllib3\\util\\connection.py\", line 60, in create_connection\n    for res in socket.getaddrinfo(host, port, family, socket.SOCK_STREAM):\n               ^^^^^^^^^^^^^^^^^^^^^^^^^^^^^^^^^^^^^^^^^^^^^^^^^^^^^^^^^^\n  File \"C:\\Users\\MaharshiJasraj\\AppData\\Local\\Programs\\Python\\Python311\\Lib\\socket.py\", line 962, in getaddrinfo\n    for res in _socket.getaddrinfo(host, port, family, type, proto, flags):\n               ^^^^^^^^^^^^^^^^^^^^^^^^^^^^^^^^^^^^^^^^^^^^^^^^^^^^^^^^^^^\nsocket.gaierror: [Errno 11001] getaddrinfo failed\n\nThe above exception was the direct cause of the following exception:\n\nTraceback (most recent call last):\n  File \"C:\\Celebal data\\Clients\\Telecom Egypt\\Extract summary\\telecomnew\\telecomnew\\08.06.24_telEg_summ_pipeline\\tempvenv\\Lib\\site-packages\\urllib3\\connectionpool.py\", line 793, in urlopen\n    response = self._make_request(\n               ^^^^^^^^^^^^^^^^^^^\n  File \"C:\\Celebal data\\Clients\\Telecom Egypt\\Extract summary\\telecomnew\\telecomnew\\08.06.24_telEg_summ_pipeline\\tempvenv\\Lib\\site-packages\\urllib3\\connectionpool.py\", line 491, in _make_request\n    raise new_e\n  File \"C:\\Celebal data\\Clients\\Telecom Egypt\\Extract summary\\telecomnew\\telecomnew\\08.06.24_telEg_summ_pipeline\\tempvenv\\Lib\\site-packages\\urllib3\\connectionpool.py\", line 467, in _make_request\n    self._validate_conn(conn)\n  File \"C:\\Celebal data\\Clients\\Telecom Egypt\\Extract summary\\telecomnew\\telecomnew\\08.06.24_telEg_summ_pipeline\\tempvenv\\Lib\\site-packages\\urllib3\\connectionpool.py\", line 1099, in _validate_conn\n    conn.connect()\n  File \"C:\\Celebal data\\Clients\\Telecom Egypt\\Extract summary\\telecomnew\\telecomnew\\08.06.24_telEg_summ_pipeline\\tempvenv\\Lib\\site-packages\\urllib3\\connection.py\", line 616, in connect\n    self.sock = sock = self._new_conn()\n                       ^^^^^^^^^^^^^^^^\n  File \"C:\\Celebal data\\Clients\\Telecom Egypt\\Extract summary\\telecomnew\\telecomnew\\08.06.24_telEg_summ_pipeline\\tempvenv\\Lib\\site-packages\\urllib3\\connection.py\", line 205, in _new_conn\n    raise NameResolutionError(self.host, self, e) from e\nurllib3.exceptions.NameResolutionError: <urllib3.connection.HTTPSConnection object at 0x000002BDBDA8E850>: Failed to resolve 'demo-langservice-mij.cognitiveservices.azure.com' ([Errno 11001] getaddrinfo failed)\n\nThe above exception was the direct cause of the following exception:\n\nTraceback (most recent call last):\n  File \"C:\\Celebal data\\Clients\\Telecom Egypt\\Extract summary\\telecomnew\\telecomnew\\08.06.24_telEg_summ_pipeline\\tempvenv\\Lib\\site-packages\\requests\\adapters.py\", line 667, in send\n    resp = conn.urlopen(\n           ^^^^^^^^^^^^^\n  File \"C:\\Celebal data\\Clients\\Telecom Egypt\\Extract summary\\telecomnew\\telecomnew\\08.06.24_telEg_summ_pipeline\\tempvenv\\Lib\\site-packages\\urllib3\\connectionpool.py\", line 847, in urlopen\n    retries = retries.increment(\n              ^^^^^^^^^^^^^^^^^^\n  File \"C:\\Celebal data\\Clients\\Telecom Egypt\\Extract summary\\telecomnew\\telecomnew\\08.06.24_telEg_summ_pipeline\\tempvenv\\Lib\\site-packages\\urllib3\\util\\retry.py\", line 515, in increment\n    raise MaxRetryError(_pool, url, reason) from reason  # type: ignore[arg-type]\n    ^^^^^^^^^^^^^^^^^^^^^^^^^^^^^^^^^^^^^^^^^^^^^^^^^^^\nurllib3.exceptions.MaxRetryError: HTTPSConnectionPool(host='demo-langservice-mij.cognitiveservices.azure.com', port=443): Max retries exceeded with url: /language/analyze-text/jobs?api-version=2023-04-01 (Caused by NameResolutionError(\"<urllib3.connection.HTTPSConnection object at 0x000002BDBDA8E850>: Failed to resolve 'demo-langservice-mij.cognitiveservices.azure.com' ([Errno 11001] getaddrinfo failed)\"))\n\nDuring handling of the above exception, another exception occurred:\n\nTraceback (most recent call last):\n  File \"C:\\Celebal data\\Clients\\Telecom Egypt\\Extract summary\\telecomnew\\telecomnew\\08.06.24_telEg_summ_pipeline\\main.py\", line 198, in get_kpis\n    summarisation_result = summarisation_obj.abstractive_summarisation_helper(call)\n                           ^^^^^^^^^^^^^^^^^^^^^^^^^^^^^^^^^^^^^^^^^^^^^^^^^^^^^^^^\n  File \"C:\\Celebal data\\Clients\\Telecom Egypt\\Extract summary\\telecomnew\\telecomnew\\08.06.24_telEg_summ_pipeline\\src\\adapters\\summarisation.py\", line 239, in abstractive_summarisation_helper\n    res = requests.post(url = self.url, headers= headers, json= data)\n          ^^^^^^^^^^^^^^^^^^^^^^^^^^^^^^^^^^^^^^^^^^^^^^^^^^^^^^^^^^^\n  File \"C:\\Celebal data\\Clients\\Telecom Egypt\\Extract summary\\telecomnew\\telecomnew\\08.06.24_telEg_summ_pipeline\\tempvenv\\Lib\\site-packages\\requests\\api.py\", line 115, in post\n    return request(\"post\", url, data=data, json=json, **kwargs)\n           ^^^^^^^^^^^^^^^^^^^^^^^^^^^^^^^^^^^^^^^^^^^^^^^^^^^^\n  File \"C:\\Celebal data\\Clients\\Telecom Egypt\\Extract summary\\telecomnew\\telecomnew\\08.06.24_telEg_summ_pipeline\\tempvenv\\Lib\\site-packages\\requests\\api.py\", line 59, in request\n    return session.request(method=method, url=url, **kwargs)\n           ^^^^^^^^^^^^^^^^^^^^^^^^^^^^^^^^^^^^^^^^^^^^^^^^^\n  File \"C:\\Celebal data\\Clients\\Telecom Egypt\\Extract summary\\telecomnew\\telecomnew\\08.06.24_telEg_summ_pipeline\\tempvenv\\Lib\\site-packages\\requests\\sessions.py\", line 589, in request\n    resp = self.send(prep, **send_kwargs)\n           ^^^^^^^^^^^^^^^^^^^^^^^^^^^^^^\n  File \"C:\\Celebal data\\Clients\\Telecom Egypt\\Extract summary\\telecomnew\\telecomnew\\08.06.24_telEg_summ_pipeline\\tempvenv\\Lib\\site-packages\\requests\\sessions.py\", line 703, in send\n    r = adapter.send(request, **kwargs)\n        ^^^^^^^^^^^^^^^^^^^^^^^^^^^^^^^\n  File \"C:\\Celebal data\\Clients\\Telecom Egypt\\Extract summary\\telecomnew\\telecomnew\\08.06.24_telEg_summ_pipeline\\tempvenv\\Lib\\site-packages\\requests\\adapters.py\", line 700, in send\n    raise ConnectionError(e, request=request)\nrequests.exceptions.ConnectionError: HTTPSConnectionPool(host='demo-langservice-mij.cognitiveservices.azure.com', port=443): Max retries exceeded with url: /language/analyze-text/jobs?api-version=2023-04-01 (Caused by NameResolutionError(\"<urllib3.connection.HTTPSConnection object at 0x000002BDBDA8E850>: Failed to resolve 'demo-langservice-mij.cognitiveservices.azure.com' ([Errno 11001] getaddrinfo failed)\"))", "location": "main.py - pipeline_after_transcription"}
{"asctime": "2024-06-09 T02:29:18+0530", "message": "An Error Occured: 'NoneType' object is not subscriptable", "exc_info": "Traceback (most recent call last):\n  File \"C:\\Celebal data\\Clients\\Telecom Egypt\\Extract summary\\telecomnew\\telecomnew\\08.06.24_telEg_summ_pipeline\\main.py\", line 294, in add_summarization_to_mapping\n    print(f\"adding the data to the mapping for key : {summarized_key} with value {summarized_text['summary']}\")\n                                                                                  ~~~~~~~~~~~~~~~^^^^^^^^^^^\nTypeError: 'NoneType' object is not subscriptable", "location": "main.py - add_summarization_to_mapping"}
{"asctime": "2024-06-09 T02:29:18+0530", "message": "An Error Occured: 'NoneType' object is not subscriptable", "exc_info": "Traceback (most recent call last):\n  File \"C:\\Celebal data\\Clients\\Telecom Egypt\\Extract summary\\telecomnew\\telecomnew\\08.06.24_telEg_summ_pipeline\\main.py\", line 400, in pipeline_after_transcription\n    merged_output[\"result\"][\"summary\"] = result[\"summary\"]\n                                         ~~~~~~^^^^^^^^^^^\nTypeError: 'NoneType' object is not subscriptable", "location": "main.py - pipeline_after_transcription"}
{"asctime": "2024-06-09 T02:31:04+0530", "message": "An Error Occured: HTTPSConnectionPool(host='demo-langservice-mij.cognitiveservices.azure.com', port=443): Max retries exceeded with url: /language/analyze-text/jobs?api-version=2023-04-01 (Caused by NameResolutionError(\"<urllib3.connection.HTTPSConnection object at 0x000002BDBDA3F710>: Failed to resolve 'demo-langservice-mij.cognitiveservices.azure.com' ([Errno 11001] getaddrinfo failed)\"))", "exc_info": "Traceback (most recent call last):\n  File \"C:\\Celebal data\\Clients\\Telecom Egypt\\Extract summary\\telecomnew\\telecomnew\\08.06.24_telEg_summ_pipeline\\tempvenv\\Lib\\site-packages\\urllib3\\connection.py\", line 198, in _new_conn\n    sock = connection.create_connection(\n           ^^^^^^^^^^^^^^^^^^^^^^^^^^^^^\n  File \"C:\\Celebal data\\Clients\\Telecom Egypt\\Extract summary\\telecomnew\\telecomnew\\08.06.24_telEg_summ_pipeline\\tempvenv\\Lib\\site-packages\\urllib3\\util\\connection.py\", line 60, in create_connection\n    for res in socket.getaddrinfo(host, port, family, socket.SOCK_STREAM):\n               ^^^^^^^^^^^^^^^^^^^^^^^^^^^^^^^^^^^^^^^^^^^^^^^^^^^^^^^^^^\n  File \"C:\\Users\\MaharshiJasraj\\AppData\\Local\\Programs\\Python\\Python311\\Lib\\socket.py\", line 962, in getaddrinfo\n    for res in _socket.getaddrinfo(host, port, family, type, proto, flags):\n               ^^^^^^^^^^^^^^^^^^^^^^^^^^^^^^^^^^^^^^^^^^^^^^^^^^^^^^^^^^^\nsocket.gaierror: [Errno 11001] getaddrinfo failed\n\nThe above exception was the direct cause of the following exception:\n\nTraceback (most recent call last):\n  File \"C:\\Celebal data\\Clients\\Telecom Egypt\\Extract summary\\telecomnew\\telecomnew\\08.06.24_telEg_summ_pipeline\\tempvenv\\Lib\\site-packages\\urllib3\\connectionpool.py\", line 793, in urlopen\n    response = self._make_request(\n               ^^^^^^^^^^^^^^^^^^^\n  File \"C:\\Celebal data\\Clients\\Telecom Egypt\\Extract summary\\telecomnew\\telecomnew\\08.06.24_telEg_summ_pipeline\\tempvenv\\Lib\\site-packages\\urllib3\\connectionpool.py\", line 491, in _make_request\n    raise new_e\n  File \"C:\\Celebal data\\Clients\\Telecom Egypt\\Extract summary\\telecomnew\\telecomnew\\08.06.24_telEg_summ_pipeline\\tempvenv\\Lib\\site-packages\\urllib3\\connectionpool.py\", line 467, in _make_request\n    self._validate_conn(conn)\n  File \"C:\\Celebal data\\Clients\\Telecom Egypt\\Extract summary\\telecomnew\\telecomnew\\08.06.24_telEg_summ_pipeline\\tempvenv\\Lib\\site-packages\\urllib3\\connectionpool.py\", line 1099, in _validate_conn\n    conn.connect()\n  File \"C:\\Celebal data\\Clients\\Telecom Egypt\\Extract summary\\telecomnew\\telecomnew\\08.06.24_telEg_summ_pipeline\\tempvenv\\Lib\\site-packages\\urllib3\\connection.py\", line 616, in connect\n    self.sock = sock = self._new_conn()\n                       ^^^^^^^^^^^^^^^^\n  File \"C:\\Celebal data\\Clients\\Telecom Egypt\\Extract summary\\telecomnew\\telecomnew\\08.06.24_telEg_summ_pipeline\\tempvenv\\Lib\\site-packages\\urllib3\\connection.py\", line 205, in _new_conn\n    raise NameResolutionError(self.host, self, e) from e\nurllib3.exceptions.NameResolutionError: <urllib3.connection.HTTPSConnection object at 0x000002BDBDA3F710>: Failed to resolve 'demo-langservice-mij.cognitiveservices.azure.com' ([Errno 11001] getaddrinfo failed)\n\nThe above exception was the direct cause of the following exception:\n\nTraceback (most recent call last):\n  File \"C:\\Celebal data\\Clients\\Telecom Egypt\\Extract summary\\telecomnew\\telecomnew\\08.06.24_telEg_summ_pipeline\\tempvenv\\Lib\\site-packages\\requests\\adapters.py\", line 667, in send\n    resp = conn.urlopen(\n           ^^^^^^^^^^^^^\n  File \"C:\\Celebal data\\Clients\\Telecom Egypt\\Extract summary\\telecomnew\\telecomnew\\08.06.24_telEg_summ_pipeline\\tempvenv\\Lib\\site-packages\\urllib3\\connectionpool.py\", line 847, in urlopen\n    retries = retries.increment(\n              ^^^^^^^^^^^^^^^^^^\n  File \"C:\\Celebal data\\Clients\\Telecom Egypt\\Extract summary\\telecomnew\\telecomnew\\08.06.24_telEg_summ_pipeline\\tempvenv\\Lib\\site-packages\\urllib3\\util\\retry.py\", line 515, in increment\n    raise MaxRetryError(_pool, url, reason) from reason  # type: ignore[arg-type]\n    ^^^^^^^^^^^^^^^^^^^^^^^^^^^^^^^^^^^^^^^^^^^^^^^^^^^\nurllib3.exceptions.MaxRetryError: HTTPSConnectionPool(host='demo-langservice-mij.cognitiveservices.azure.com', port=443): Max retries exceeded with url: /language/analyze-text/jobs?api-version=2023-04-01 (Caused by NameResolutionError(\"<urllib3.connection.HTTPSConnection object at 0x000002BDBDA3F710>: Failed to resolve 'demo-langservice-mij.cognitiveservices.azure.com' ([Errno 11001] getaddrinfo failed)\"))\n\nDuring handling of the above exception, another exception occurred:\n\nTraceback (most recent call last):\n  File \"C:\\Celebal data\\Clients\\Telecom Egypt\\Extract summary\\telecomnew\\telecomnew\\08.06.24_telEg_summ_pipeline\\main.py\", line 198, in get_kpis\n    summarisation_result = summarisation_obj.abstractive_summarisation_helper(call)\n                           ^^^^^^^^^^^^^^^^^^^^^^^^^^^^^^^^^^^^^^^^^^^^^^^^^^^^^^^^\n  File \"C:\\Celebal data\\Clients\\Telecom Egypt\\Extract summary\\telecomnew\\telecomnew\\08.06.24_telEg_summ_pipeline\\src\\adapters\\summarisation.py\", line 239, in abstractive_summarisation_helper\n    res = requests.post(url = self.url, headers= headers, json= data)\n          ^^^^^^^^^^^^^^^^^^^^^^^^^^^^^^^^^^^^^^^^^^^^^^^^^^^^^^^^^^^\n  File \"C:\\Celebal data\\Clients\\Telecom Egypt\\Extract summary\\telecomnew\\telecomnew\\08.06.24_telEg_summ_pipeline\\tempvenv\\Lib\\site-packages\\requests\\api.py\", line 115, in post\n    return request(\"post\", url, data=data, json=json, **kwargs)\n           ^^^^^^^^^^^^^^^^^^^^^^^^^^^^^^^^^^^^^^^^^^^^^^^^^^^^\n  File \"C:\\Celebal data\\Clients\\Telecom Egypt\\Extract summary\\telecomnew\\telecomnew\\08.06.24_telEg_summ_pipeline\\tempvenv\\Lib\\site-packages\\requests\\api.py\", line 59, in request\n    return session.request(method=method, url=url, **kwargs)\n           ^^^^^^^^^^^^^^^^^^^^^^^^^^^^^^^^^^^^^^^^^^^^^^^^^\n  File \"C:\\Celebal data\\Clients\\Telecom Egypt\\Extract summary\\telecomnew\\telecomnew\\08.06.24_telEg_summ_pipeline\\tempvenv\\Lib\\site-packages\\requests\\sessions.py\", line 589, in request\n    resp = self.send(prep, **send_kwargs)\n           ^^^^^^^^^^^^^^^^^^^^^^^^^^^^^^\n  File \"C:\\Celebal data\\Clients\\Telecom Egypt\\Extract summary\\telecomnew\\telecomnew\\08.06.24_telEg_summ_pipeline\\tempvenv\\Lib\\site-packages\\requests\\sessions.py\", line 703, in send\n    r = adapter.send(request, **kwargs)\n        ^^^^^^^^^^^^^^^^^^^^^^^^^^^^^^^\n  File \"C:\\Celebal data\\Clients\\Telecom Egypt\\Extract summary\\telecomnew\\telecomnew\\08.06.24_telEg_summ_pipeline\\tempvenv\\Lib\\site-packages\\requests\\adapters.py\", line 700, in send\n    raise ConnectionError(e, request=request)\nrequests.exceptions.ConnectionError: HTTPSConnectionPool(host='demo-langservice-mij.cognitiveservices.azure.com', port=443): Max retries exceeded with url: /language/analyze-text/jobs?api-version=2023-04-01 (Caused by NameResolutionError(\"<urllib3.connection.HTTPSConnection object at 0x000002BDBDA3F710>: Failed to resolve 'demo-langservice-mij.cognitiveservices.azure.com' ([Errno 11001] getaddrinfo failed)\"))", "location": "main.py - pipeline_after_transcription"}
{"asctime": "2024-06-09 T02:31:04+0530", "message": "An Error Occured: 'NoneType' object is not subscriptable", "exc_info": "Traceback (most recent call last):\n  File \"C:\\Celebal data\\Clients\\Telecom Egypt\\Extract summary\\telecomnew\\telecomnew\\08.06.24_telEg_summ_pipeline\\main.py\", line 294, in add_summarization_to_mapping\n    print(f\"adding the data to the mapping for key : {summarized_key} with value {summarized_text['summary']}\")\n                                                                                  ~~~~~~~~~~~~~~~^^^^^^^^^^^\nTypeError: 'NoneType' object is not subscriptable", "location": "main.py - add_summarization_to_mapping"}
{"asctime": "2024-06-09 T02:31:04+0530", "message": "An Error Occured: 'NoneType' object is not subscriptable", "exc_info": "Traceback (most recent call last):\n  File \"C:\\Celebal data\\Clients\\Telecom Egypt\\Extract summary\\telecomnew\\telecomnew\\08.06.24_telEg_summ_pipeline\\main.py\", line 400, in pipeline_after_transcription\n    merged_output[\"result\"][\"summary\"] = result[\"summary\"]\n                                         ~~~~~~^^^^^^^^^^^\nTypeError: 'NoneType' object is not subscriptable", "location": "main.py - pipeline_after_transcription"}
{"asctime": "2024-06-09 T02:36:11+0530", "message": "An Error Occurred: 'summarization_en'", "exc_info": "Traceback (most recent call last):\n  File \"C:\\Celebal data\\Clients\\Telecom Egypt\\Extract summary\\telecomnew\\telecomnew\\08.06.24_telEg_summ_pipeline\\main.py\", line 332, in add_mapping_to_excel\n    summarization_en_ls.append(call_data['summarization_en'])\n                               ~~~~~~~~~^^^^^^^^^^^^^^^^^^^^\nKeyError: 'summarization_en'", "location": "main.py - add_mapping_to_excel"}
{"asctime": "2024-06-09 T12:18:18+0530", "message": "An Error Occured: HTTPSConnectionPool(host='demo-langservice-mij.cognitiveservices.azure.com', port=443): Max retries exceeded with url: /language/analyze-text/jobs?api-version=2023-04-01 (Caused by NameResolutionError(\"<urllib3.connection.HTTPSConnection object at 0x000001DC54166150>: Failed to resolve 'demo-langservice-mij.cognitiveservices.azure.com' ([Errno 11001] getaddrinfo failed)\"))", "exc_info": "Traceback (most recent call last):\n  File \"C:\\Celebal data\\Clients\\Telecom Egypt\\Extract summary\\telecomnew\\telecomnew\\08.06.24_telEg_summ_pipeline\\tempvenv\\Lib\\site-packages\\urllib3\\connection.py\", line 198, in _new_conn\n    sock = connection.create_connection(\n           ^^^^^^^^^^^^^^^^^^^^^^^^^^^^^\n  File \"C:\\Celebal data\\Clients\\Telecom Egypt\\Extract summary\\telecomnew\\telecomnew\\08.06.24_telEg_summ_pipeline\\tempvenv\\Lib\\site-packages\\urllib3\\util\\connection.py\", line 60, in create_connection\n    for res in socket.getaddrinfo(host, port, family, socket.SOCK_STREAM):\n               ^^^^^^^^^^^^^^^^^^^^^^^^^^^^^^^^^^^^^^^^^^^^^^^^^^^^^^^^^^\n  File \"C:\\Users\\MaharshiJasraj\\AppData\\Local\\Programs\\Python\\Python311\\Lib\\socket.py\", line 962, in getaddrinfo\n    for res in _socket.getaddrinfo(host, port, family, type, proto, flags):\n               ^^^^^^^^^^^^^^^^^^^^^^^^^^^^^^^^^^^^^^^^^^^^^^^^^^^^^^^^^^^\nsocket.gaierror: [Errno 11001] getaddrinfo failed\n\nThe above exception was the direct cause of the following exception:\n\nTraceback (most recent call last):\n  File \"C:\\Celebal data\\Clients\\Telecom Egypt\\Extract summary\\telecomnew\\telecomnew\\08.06.24_telEg_summ_pipeline\\tempvenv\\Lib\\site-packages\\urllib3\\connectionpool.py\", line 793, in urlopen\n    response = self._make_request(\n               ^^^^^^^^^^^^^^^^^^^\n  File \"C:\\Celebal data\\Clients\\Telecom Egypt\\Extract summary\\telecomnew\\telecomnew\\08.06.24_telEg_summ_pipeline\\tempvenv\\Lib\\site-packages\\urllib3\\connectionpool.py\", line 491, in _make_request\n    raise new_e\n  File \"C:\\Celebal data\\Clients\\Telecom Egypt\\Extract summary\\telecomnew\\telecomnew\\08.06.24_telEg_summ_pipeline\\tempvenv\\Lib\\site-packages\\urllib3\\connectionpool.py\", line 467, in _make_request\n    self._validate_conn(conn)\n  File \"C:\\Celebal data\\Clients\\Telecom Egypt\\Extract summary\\telecomnew\\telecomnew\\08.06.24_telEg_summ_pipeline\\tempvenv\\Lib\\site-packages\\urllib3\\connectionpool.py\", line 1099, in _validate_conn\n    conn.connect()\n  File \"C:\\Celebal data\\Clients\\Telecom Egypt\\Extract summary\\telecomnew\\telecomnew\\08.06.24_telEg_summ_pipeline\\tempvenv\\Lib\\site-packages\\urllib3\\connection.py\", line 616, in connect\n    self.sock = sock = self._new_conn()\n                       ^^^^^^^^^^^^^^^^\n  File \"C:\\Celebal data\\Clients\\Telecom Egypt\\Extract summary\\telecomnew\\telecomnew\\08.06.24_telEg_summ_pipeline\\tempvenv\\Lib\\site-packages\\urllib3\\connection.py\", line 205, in _new_conn\n    raise NameResolutionError(self.host, self, e) from e\nurllib3.exceptions.NameResolutionError: <urllib3.connection.HTTPSConnection object at 0x000001DC54166150>: Failed to resolve 'demo-langservice-mij.cognitiveservices.azure.com' ([Errno 11001] getaddrinfo failed)\n\nThe above exception was the direct cause of the following exception:\n\nTraceback (most recent call last):\n  File \"C:\\Celebal data\\Clients\\Telecom Egypt\\Extract summary\\telecomnew\\telecomnew\\08.06.24_telEg_summ_pipeline\\tempvenv\\Lib\\site-packages\\requests\\adapters.py\", line 667, in send\n    resp = conn.urlopen(\n           ^^^^^^^^^^^^^\n  File \"C:\\Celebal data\\Clients\\Telecom Egypt\\Extract summary\\telecomnew\\telecomnew\\08.06.24_telEg_summ_pipeline\\tempvenv\\Lib\\site-packages\\urllib3\\connectionpool.py\", line 847, in urlopen\n    retries = retries.increment(\n              ^^^^^^^^^^^^^^^^^^\n  File \"C:\\Celebal data\\Clients\\Telecom Egypt\\Extract summary\\telecomnew\\telecomnew\\08.06.24_telEg_summ_pipeline\\tempvenv\\Lib\\site-packages\\urllib3\\util\\retry.py\", line 515, in increment\n    raise MaxRetryError(_pool, url, reason) from reason  # type: ignore[arg-type]\n    ^^^^^^^^^^^^^^^^^^^^^^^^^^^^^^^^^^^^^^^^^^^^^^^^^^^\nurllib3.exceptions.MaxRetryError: HTTPSConnectionPool(host='demo-langservice-mij.cognitiveservices.azure.com', port=443): Max retries exceeded with url: /language/analyze-text/jobs?api-version=2023-04-01 (Caused by NameResolutionError(\"<urllib3.connection.HTTPSConnection object at 0x000001DC54166150>: Failed to resolve 'demo-langservice-mij.cognitiveservices.azure.com' ([Errno 11001] getaddrinfo failed)\"))\n\nDuring handling of the above exception, another exception occurred:\n\nTraceback (most recent call last):\n  File \"C:\\Celebal data\\Clients\\Telecom Egypt\\Extract summary\\telecomnew\\telecomnew\\08.06.24_telEg_summ_pipeline\\main.py\", line 198, in get_kpis\n    summarisation_result = summarisation_obj.abstractive_summarisation_helper(call)\n                           ^^^^^^^^^^^^^^^^^^^^^^^^^^^^^^^^^^^^^^^^^^^^^^^^^^^^^^^^\n  File \"C:\\Celebal data\\Clients\\Telecom Egypt\\Extract summary\\telecomnew\\telecomnew\\08.06.24_telEg_summ_pipeline\\src\\adapters\\summarisation.py\", line 239, in abstractive_summarisation_helper\n    res = requests.post(url = self.url, headers= headers, json= data)\n          ^^^^^^^^^^^^^^^^^^^^^^^^^^^^^^^^^^^^^^^^^^^^^^^^^^^^^^^^^^^\n  File \"C:\\Celebal data\\Clients\\Telecom Egypt\\Extract summary\\telecomnew\\telecomnew\\08.06.24_telEg_summ_pipeline\\tempvenv\\Lib\\site-packages\\requests\\api.py\", line 115, in post\n    return request(\"post\", url, data=data, json=json, **kwargs)\n           ^^^^^^^^^^^^^^^^^^^^^^^^^^^^^^^^^^^^^^^^^^^^^^^^^^^^\n  File \"C:\\Celebal data\\Clients\\Telecom Egypt\\Extract summary\\telecomnew\\telecomnew\\08.06.24_telEg_summ_pipeline\\tempvenv\\Lib\\site-packages\\requests\\api.py\", line 59, in request\n    return session.request(method=method, url=url, **kwargs)\n           ^^^^^^^^^^^^^^^^^^^^^^^^^^^^^^^^^^^^^^^^^^^^^^^^^\n  File \"C:\\Celebal data\\Clients\\Telecom Egypt\\Extract summary\\telecomnew\\telecomnew\\08.06.24_telEg_summ_pipeline\\tempvenv\\Lib\\site-packages\\requests\\sessions.py\", line 589, in request\n    resp = self.send(prep, **send_kwargs)\n           ^^^^^^^^^^^^^^^^^^^^^^^^^^^^^^\n  File \"C:\\Celebal data\\Clients\\Telecom Egypt\\Extract summary\\telecomnew\\telecomnew\\08.06.24_telEg_summ_pipeline\\tempvenv\\Lib\\site-packages\\requests\\sessions.py\", line 703, in send\n    r = adapter.send(request, **kwargs)\n        ^^^^^^^^^^^^^^^^^^^^^^^^^^^^^^^\n  File \"C:\\Celebal data\\Clients\\Telecom Egypt\\Extract summary\\telecomnew\\telecomnew\\08.06.24_telEg_summ_pipeline\\tempvenv\\Lib\\site-packages\\requests\\adapters.py\", line 700, in send\n    raise ConnectionError(e, request=request)\nrequests.exceptions.ConnectionError: HTTPSConnectionPool(host='demo-langservice-mij.cognitiveservices.azure.com', port=443): Max retries exceeded with url: /language/analyze-text/jobs?api-version=2023-04-01 (Caused by NameResolutionError(\"<urllib3.connection.HTTPSConnection object at 0x000001DC54166150>: Failed to resolve 'demo-langservice-mij.cognitiveservices.azure.com' ([Errno 11001] getaddrinfo failed)\"))", "location": "main.py - pipeline_after_transcription"}
{"asctime": "2024-06-09 T12:18:19+0530", "message": "An Error Occured: 'NoneType' object is not subscriptable", "exc_info": "Traceback (most recent call last):\n  File \"C:\\Celebal data\\Clients\\Telecom Egypt\\Extract summary\\telecomnew\\telecomnew\\08.06.24_telEg_summ_pipeline\\main.py\", line 294, in add_summarization_to_mapping\n    print(f\"adding the data to the mapping for key : {summarized_key} with value {summarized_text['summary']}\")\n                                                                                  ~~~~~~~~~~~~~~~^^^^^^^^^^^\nTypeError: 'NoneType' object is not subscriptable", "location": "main.py - add_summarization_to_mapping"}
{"asctime": "2024-06-09 T12:18:19+0530", "message": "An Error Occured: 'NoneType' object is not subscriptable", "exc_info": "Traceback (most recent call last):\n  File \"C:\\Celebal data\\Clients\\Telecom Egypt\\Extract summary\\telecomnew\\telecomnew\\08.06.24_telEg_summ_pipeline\\main.py\", line 419, in pipeline_after_transcription\n    merged_output[\"result\"][\"summary\"] = result[\"summary\"]\n                                         ~~~~~~^^^^^^^^^^^\nTypeError: 'NoneType' object is not subscriptable", "location": "main.py - pipeline_after_transcription"}
{"asctime": "2024-06-10 T16:11:54+0530", "message": "An Error Occured ..", "exc_info": "Traceback (most recent call last):\n  File \"C:\\Celebal data\\Clients\\Telecom Egypt\\Extract summary\\summary_pipeline\\main.py\", line 131, in audios_main\n    print(f\"got the data for audio: {filename}\", index, agent_id, agent_name, call_date, comment)\n                                                 ^^^^^\nUnboundLocalError: cannot access local variable 'index' where it is not associated with a value", "location": "main.py-audios_main"}
{"asctime": "2024-06-10 T16:15:41+0530", "message": "An Error Occured ..", "exc_info": "Traceback (most recent call last):\n  File \"C:\\Celebal data\\Clients\\Telecom Egypt\\Extract summary\\summary_pipeline\\main.py\", line 161, in audios_main\n    print(f\"got the data for audio: {filename}\", index, agent_id, agent_name, call_date, comment)\n                                                 ^^^^^\nUnboundLocalError: cannot access local variable 'index' where it is not associated with a value", "location": "main.py-audios_main"}
{"asctime": "2024-06-10 T16:17:53+0530", "message": "An Error Occured ..", "exc_info": "Traceback (most recent call last):\n  File \"C:\\Celebal data\\Clients\\Telecom Egypt\\Extract summary\\summary_pipeline\\main.py\", line 166, in audios_main\n    print(f\"got the data for audio: {filename}\", index, agent_id, agent_name, call_date, comment)\n                                                 ^^^^^\nUnboundLocalError: cannot access local variable 'index' where it is not associated with a value", "location": "main.py-audios_main"}
{"asctime": "2024-06-10 T16:18:40+0530", "message": "An Error Occured ..", "exc_info": "Traceback (most recent call last):\n  File \"C:\\Celebal data\\Clients\\Telecom Egypt\\Extract summary\\summary_pipeline\\main.py\", line 169, in audios_main\n    print(f\"got the data for audio: {filename}\", index, agent_id, agent_name, call_date, comment)\n                                                 ^^^^^\nUnboundLocalError: cannot access local variable 'index' where it is not associated with a value", "location": "main.py-audios_main"}
{"asctime": "2024-06-10 T16:21:40+0530", "message": "An Error Occured ..", "exc_info": "Traceback (most recent call last):\n  File \"C:\\Celebal data\\Clients\\Telecom Egypt\\Extract summary\\summary_pipeline\\main.py\", line 169, in audios_main\n    print(f\"got the data for audio: {filename}\", index, agent_id, agent_name, call_date, comment)\n                                                 ^^^^^\nUnboundLocalError: cannot access local variable 'index' where it is not associated with a value", "location": "main.py-audios_main"}
{"asctime": "2024-06-10 T16:25:22+0530", "message": "An Error Occured ..", "exc_info": "Traceback (most recent call last):\n  File \"C:\\Celebal data\\Clients\\Telecom Egypt\\Extract summary\\summary_pipeline\\main.py\", line 118, in audios_main\n    print(sheet2_res[\"sheetname\"])\n          ~~~~~~~~~~^^^^^^^^^^^^^\nKeyError: 'sheetname'", "location": "main.py-audios_main"}
{"asctime": "2024-06-10 T16:27:43+0530", "message": "An Error Occured ..", "exc_info": "Traceback (most recent call last):\n  File \"C:\\Celebal data\\Clients\\Telecom Egypt\\Extract summary\\summary_pipeline\\main.py\", line 121, in audios_main\n    print(sheet2_res[\"sheetname\"])\n          ~~~~~~~~~~^^^^^^^^^^^^^\nKeyError: 'sheetname'", "location": "main.py-audios_main"}
{"asctime": "2024-06-10 T16:31:08+0530", "message": "An Error Occured ..", "exc_info": "Traceback (most recent call last):\n  File \"C:\\Celebal data\\Clients\\Telecom Egypt\\Extract summary\\summary_pipeline\\main.py\", line 121, in audios_main\n    print(sheet2_res[\"sheetname\"])\n          ~~~~~~~~~~^^^^^^^^^^^^^\nKeyError: 'sheetname'", "location": "main.py-audios_main"}
{"asctime": "2024-06-10 T16:31:44+0530", "message": "An Error Occured ..", "exc_info": "Traceback (most recent call last):\n  File \"C:\\Celebal data\\Clients\\Telecom Egypt\\Extract summary\\summary_pipeline\\summvenv\\Lib\\site-packages\\pandas\\core\\indexes\\base.py\", line 3805, in get_loc\n    return self._engine.get_loc(casted_key)\n           ^^^^^^^^^^^^^^^^^^^^^^^^^^^^^^^^\n  File \"index.pyx\", line 167, in pandas._libs.index.IndexEngine.get_loc\n  File \"index.pyx\", line 196, in pandas._libs.index.IndexEngine.get_loc\n  File \"pandas\\\\_libs\\\\hashtable_class_helper.pxi\", line 7081, in pandas._libs.hashtable.PyObjectHashTable.get_item\n  File \"pandas\\\\_libs\\\\hashtable_class_helper.pxi\", line 7089, in pandas._libs.hashtable.PyObjectHashTable.get_item\nKeyError: 'Call id'\n\nThe above exception was the direct cause of the following exception:\n\nTraceback (most recent call last):\n  File \"C:\\Celebal data\\Clients\\Telecom Egypt\\Extract summary\\summary_pipeline\\main.py\", line 80, in audios_main\n    sheet1_res, sheet2_res, sheet3_res = source_data_obj.read_data_csv()\n                                         ^^^^^^^^^^^^^^^^^^^^^^^^^^^^^^^\n  File \"C:\\Celebal data\\Clients\\Telecom Egypt\\Extract summary\\summary_pipeline\\src\\starter_pipeline.py\", line 48, in read_data_csv\n    call_id = row[\"Call id\"]\n              ~~~^^^^^^^^^^^\n  File \"C:\\Celebal data\\Clients\\Telecom Egypt\\Extract summary\\summary_pipeline\\summvenv\\Lib\\site-packages\\pandas\\core\\series.py\", line 1121, in __getitem__\n    return self._get_value(key)\n           ^^^^^^^^^^^^^^^^^^^^\n  File \"C:\\Celebal data\\Clients\\Telecom Egypt\\Extract summary\\summary_pipeline\\summvenv\\Lib\\site-packages\\pandas\\core\\series.py\", line 1237, in _get_value\n    loc = self.index.get_loc(label)\n          ^^^^^^^^^^^^^^^^^^^^^^^^^\n  File \"C:\\Celebal data\\Clients\\Telecom Egypt\\Extract summary\\summary_pipeline\\summvenv\\Lib\\site-packages\\pandas\\core\\indexes\\base.py\", line 3812, in get_loc\n    raise KeyError(key) from err\nKeyError: 'Call id'", "location": "main.py-audios_main"}
{"asctime": "2024-06-10 T16:34:36+0530", "message": "An Error Occured ..", "exc_info": "Traceback (most recent call last):\n  File \"C:\\Celebal data\\Clients\\Telecom Egypt\\Extract summary\\summary_pipeline\\summvenv\\Lib\\site-packages\\pandas\\core\\indexes\\base.py\", line 3805, in get_loc\n    return self._engine.get_loc(casted_key)\n           ^^^^^^^^^^^^^^^^^^^^^^^^^^^^^^^^\n  File \"index.pyx\", line 167, in pandas._libs.index.IndexEngine.get_loc\n  File \"index.pyx\", line 196, in pandas._libs.index.IndexEngine.get_loc\n  File \"pandas\\\\_libs\\\\hashtable_class_helper.pxi\", line 7081, in pandas._libs.hashtable.PyObjectHashTable.get_item\n  File \"pandas\\\\_libs\\\\hashtable_class_helper.pxi\", line 7089, in pandas._libs.hashtable.PyObjectHashTable.get_item\nKeyError: 'Agent name'\n\nThe above exception was the direct cause of the following exception:\n\nTraceback (most recent call last):\n  File \"C:\\Celebal data\\Clients\\Telecom Egypt\\Extract summary\\summary_pipeline\\main.py\", line 80, in audios_main\n    sheet1_res, sheet2_res, sheet3_res = source_data_obj.read_data_csv()\n                                         ^^^^^^^^^^^^^^^^^^^^^^^^^^^^^^^\n  File \"C:\\Celebal data\\Clients\\Telecom Egypt\\Extract summary\\summary_pipeline\\src\\starter_pipeline.py\", line 50, in read_data_csv\n    agent_name = row[\"Agent name\"]\n                 ~~~^^^^^^^^^^^^^^\n  File \"C:\\Celebal data\\Clients\\Telecom Egypt\\Extract summary\\summary_pipeline\\summvenv\\Lib\\site-packages\\pandas\\core\\series.py\", line 1121, in __getitem__\n    return self._get_value(key)\n           ^^^^^^^^^^^^^^^^^^^^\n  File \"C:\\Celebal data\\Clients\\Telecom Egypt\\Extract summary\\summary_pipeline\\summvenv\\Lib\\site-packages\\pandas\\core\\series.py\", line 1237, in _get_value\n    loc = self.index.get_loc(label)\n          ^^^^^^^^^^^^^^^^^^^^^^^^^\n  File \"C:\\Celebal data\\Clients\\Telecom Egypt\\Extract summary\\summary_pipeline\\summvenv\\Lib\\site-packages\\pandas\\core\\indexes\\base.py\", line 3812, in get_loc\n    raise KeyError(key) from err\nKeyError: 'Agent name'", "location": "main.py-audios_main"}
{"asctime": "2024-06-10 T16:36:08+0530", "message": "An Error Occured ..", "exc_info": "Traceback (most recent call last):\n  File \"C:\\Celebal data\\Clients\\Telecom Egypt\\Extract summary\\summary_pipeline\\summvenv\\Lib\\site-packages\\pandas\\core\\indexes\\base.py\", line 3805, in get_loc\n    return self._engine.get_loc(casted_key)\n           ^^^^^^^^^^^^^^^^^^^^^^^^^^^^^^^^\n  File \"index.pyx\", line 167, in pandas._libs.index.IndexEngine.get_loc\n  File \"index.pyx\", line 196, in pandas._libs.index.IndexEngine.get_loc\n  File \"pandas\\\\_libs\\\\hashtable_class_helper.pxi\", line 7081, in pandas._libs.hashtable.PyObjectHashTable.get_item\n  File \"pandas\\\\_libs\\\\hashtable_class_helper.pxi\", line 7089, in pandas._libs.hashtable.PyObjectHashTable.get_item\nKeyError: 'Agent id'\n\nThe above exception was the direct cause of the following exception:\n\nTraceback (most recent call last):\n  File \"C:\\Celebal data\\Clients\\Telecom Egypt\\Extract summary\\summary_pipeline\\main.py\", line 80, in audios_main\n    sheet1_res, sheet2_res, sheet3_res = source_data_obj.read_data_csv()\n                                         ^^^^^^^^^^^^^^^^^^^^^^^^^^^^^^^\n  File \"C:\\Celebal data\\Clients\\Telecom Egypt\\Extract summary\\summary_pipeline\\src\\starter_pipeline.py\", line 49, in read_data_csv\n    agent_id = row[\"Agent id\"]\n               ~~~^^^^^^^^^^^^\n  File \"C:\\Celebal data\\Clients\\Telecom Egypt\\Extract summary\\summary_pipeline\\summvenv\\Lib\\site-packages\\pandas\\core\\series.py\", line 1121, in __getitem__\n    return self._get_value(key)\n           ^^^^^^^^^^^^^^^^^^^^\n  File \"C:\\Celebal data\\Clients\\Telecom Egypt\\Extract summary\\summary_pipeline\\summvenv\\Lib\\site-packages\\pandas\\core\\series.py\", line 1237, in _get_value\n    loc = self.index.get_loc(label)\n          ^^^^^^^^^^^^^^^^^^^^^^^^^\n  File \"C:\\Celebal data\\Clients\\Telecom Egypt\\Extract summary\\summary_pipeline\\summvenv\\Lib\\site-packages\\pandas\\core\\indexes\\base.py\", line 3812, in get_loc\n    raise KeyError(key) from err\nKeyError: 'Agent id'", "location": "main.py-audios_main"}
{"asctime": "2024-06-10 T16:38:11+0530", "message": "An Error Occured ..", "exc_info": "Traceback (most recent call last):\n  File \"C:\\Celebal data\\Clients\\Telecom Egypt\\Extract summary\\summary_pipeline\\summvenv\\Lib\\site-packages\\pandas\\core\\indexes\\base.py\", line 3805, in get_loc\n    return self._engine.get_loc(casted_key)\n           ^^^^^^^^^^^^^^^^^^^^^^^^^^^^^^^^\n  File \"index.pyx\", line 167, in pandas._libs.index.IndexEngine.get_loc\n  File \"index.pyx\", line 196, in pandas._libs.index.IndexEngine.get_loc\n  File \"pandas\\\\_libs\\\\hashtable_class_helper.pxi\", line 7081, in pandas._libs.hashtable.PyObjectHashTable.get_item\n  File \"pandas\\\\_libs\\\\hashtable_class_helper.pxi\", line 7089, in pandas._libs.hashtable.PyObjectHashTable.get_item\nKeyError: 'Agent id'\n\nThe above exception was the direct cause of the following exception:\n\nTraceback (most recent call last):\n  File \"C:\\Celebal data\\Clients\\Telecom Egypt\\Extract summary\\summary_pipeline\\main.py\", line 80, in audios_main\n    sheet1_res, sheet2_res, sheet3_res = source_data_obj.read_data_csv()\n                                         ^^^^^^^^^^^^^^^^^^^^^^^^^^^^^^^\n  File \"C:\\Celebal data\\Clients\\Telecom Egypt\\Extract summary\\summary_pipeline\\src\\starter_pipeline.py\", line 49, in read_data_csv\n    agent_id = row[\"Agent id\"]\n               ~~~^^^^^^^^^^^^\n  File \"C:\\Celebal data\\Clients\\Telecom Egypt\\Extract summary\\summary_pipeline\\summvenv\\Lib\\site-packages\\pandas\\core\\series.py\", line 1121, in __getitem__\n    return self._get_value(key)\n           ^^^^^^^^^^^^^^^^^^^^\n  File \"C:\\Celebal data\\Clients\\Telecom Egypt\\Extract summary\\summary_pipeline\\summvenv\\Lib\\site-packages\\pandas\\core\\series.py\", line 1237, in _get_value\n    loc = self.index.get_loc(label)\n          ^^^^^^^^^^^^^^^^^^^^^^^^^\n  File \"C:\\Celebal data\\Clients\\Telecom Egypt\\Extract summary\\summary_pipeline\\summvenv\\Lib\\site-packages\\pandas\\core\\indexes\\base.py\", line 3812, in get_loc\n    raise KeyError(key) from err\nKeyError: 'Agent id'", "location": "main.py-audios_main"}
{"asctime": "2024-06-10 T16:40:02+0530", "message": "An Error Occured ..", "exc_info": "Traceback (most recent call last):\n  File \"C:\\Celebal data\\Clients\\Telecom Egypt\\Extract summary\\summary_pipeline\\summvenv\\Lib\\site-packages\\pandas\\core\\indexes\\base.py\", line 3805, in get_loc\n    return self._engine.get_loc(casted_key)\n           ^^^^^^^^^^^^^^^^^^^^^^^^^^^^^^^^\n  File \"index.pyx\", line 167, in pandas._libs.index.IndexEngine.get_loc\n  File \"index.pyx\", line 196, in pandas._libs.index.IndexEngine.get_loc\n  File \"pandas\\\\_libs\\\\hashtable_class_helper.pxi\", line 7081, in pandas._libs.hashtable.PyObjectHashTable.get_item\n  File \"pandas\\\\_libs\\\\hashtable_class_helper.pxi\", line 7089, in pandas._libs.hashtable.PyObjectHashTable.get_item\nKeyError: 'Call Date '\n\nThe above exception was the direct cause of the following exception:\n\nTraceback (most recent call last):\n  File \"C:\\Celebal data\\Clients\\Telecom Egypt\\Extract summary\\summary_pipeline\\main.py\", line 80, in audios_main\n    sheet1_res, sheet2_res, sheet3_res = source_data_obj.read_data_csv()\n                                         ^^^^^^^^^^^^^^^^^^^^^^^^^^^^^^^\n  File \"C:\\Celebal data\\Clients\\Telecom Egypt\\Extract summary\\summary_pipeline\\src\\starter_pipeline.py\", line 51, in read_data_csv\n    call_date = row[\"Call Date \"]\n                ~~~^^^^^^^^^^^^^^\n  File \"C:\\Celebal data\\Clients\\Telecom Egypt\\Extract summary\\summary_pipeline\\summvenv\\Lib\\site-packages\\pandas\\core\\series.py\", line 1121, in __getitem__\n    return self._get_value(key)\n           ^^^^^^^^^^^^^^^^^^^^\n  File \"C:\\Celebal data\\Clients\\Telecom Egypt\\Extract summary\\summary_pipeline\\summvenv\\Lib\\site-packages\\pandas\\core\\series.py\", line 1237, in _get_value\n    loc = self.index.get_loc(label)\n          ^^^^^^^^^^^^^^^^^^^^^^^^^\n  File \"C:\\Celebal data\\Clients\\Telecom Egypt\\Extract summary\\summary_pipeline\\summvenv\\Lib\\site-packages\\pandas\\core\\indexes\\base.py\", line 3812, in get_loc\n    raise KeyError(key) from err\nKeyError: 'Call Date '", "location": "main.py-audios_main"}
{"asctime": "2024-06-10 T16:42:48+0530", "message": "An Error Occured ..", "exc_info": "Traceback (most recent call last):\n  File \"C:\\Celebal data\\Clients\\Telecom Egypt\\Extract summary\\summary_pipeline\\summvenv\\Lib\\site-packages\\pandas\\core\\indexes\\base.py\", line 3805, in get_loc\n    return self._engine.get_loc(casted_key)\n           ^^^^^^^^^^^^^^^^^^^^^^^^^^^^^^^^\n  File \"index.pyx\", line 167, in pandas._libs.index.IndexEngine.get_loc\n  File \"index.pyx\", line 196, in pandas._libs.index.IndexEngine.get_loc\n  File \"pandas\\\\_libs\\\\hashtable_class_helper.pxi\", line 7081, in pandas._libs.hashtable.PyObjectHashTable.get_item\n  File \"pandas\\\\_libs\\\\hashtable_class_helper.pxi\", line 7089, in pandas._libs.hashtable.PyObjectHashTable.get_item\nKeyError: 'Call Date '\n\nThe above exception was the direct cause of the following exception:\n\nTraceback (most recent call last):\n  File \"C:\\Celebal data\\Clients\\Telecom Egypt\\Extract summary\\summary_pipeline\\main.py\", line 80, in audios_main\n    sheet1_res, sheet2_res, sheet3_res = source_data_obj.read_data_csv()\n                                         ^^^^^^^^^^^^^^^^^^^^^^^^^^^^^^^\n  File \"C:\\Celebal data\\Clients\\Telecom Egypt\\Extract summary\\summary_pipeline\\src\\starter_pipeline.py\", line 51, in read_data_csv\n    call_date = row[\"Call Date \"]\n                ~~~^^^^^^^^^^^^^^\n  File \"C:\\Celebal data\\Clients\\Telecom Egypt\\Extract summary\\summary_pipeline\\summvenv\\Lib\\site-packages\\pandas\\core\\series.py\", line 1121, in __getitem__\n    return self._get_value(key)\n           ^^^^^^^^^^^^^^^^^^^^\n  File \"C:\\Celebal data\\Clients\\Telecom Egypt\\Extract summary\\summary_pipeline\\summvenv\\Lib\\site-packages\\pandas\\core\\series.py\", line 1237, in _get_value\n    loc = self.index.get_loc(label)\n          ^^^^^^^^^^^^^^^^^^^^^^^^^\n  File \"C:\\Celebal data\\Clients\\Telecom Egypt\\Extract summary\\summary_pipeline\\summvenv\\Lib\\site-packages\\pandas\\core\\indexes\\base.py\", line 3812, in get_loc\n    raise KeyError(key) from err\nKeyError: 'Call Date '", "location": "main.py-audios_main"}
{"asctime": "2024-06-10 T16:43:19+0530", "message": "An Error Occured ..", "exc_info": "Traceback (most recent call last):\n  File \"C:\\Celebal data\\Clients\\Telecom Egypt\\Extract summary\\summary_pipeline\\main.py\", line 172, in audios_main\n    print(f\"got the data for audio: {filename}\", index, agent_id, agent_name, call_date, comment)\n                                                 ^^^^^\nUnboundLocalError: cannot access local variable 'index' where it is not associated with a value", "location": "main.py-audios_main"}
{"asctime": "2024-06-10 T16:48:27+0530", "message": "An Error Occured ..", "exc_info": "Traceback (most recent call last):\n  File \"C:\\Celebal data\\Clients\\Telecom Egypt\\Extract summary\\summary_pipeline\\main.py\", line 172, in audios_main\n    print(f\"got the data for audio: {filename}\", index, agent_id, agent_name, call_date, comment)\n                                                 ^^^^^\nUnboundLocalError: cannot access local variable 'index' where it is not associated with a value", "location": "main.py-audios_main"}
{"asctime": "2024-06-10 T16:49:56+0530", "message": "An Error Occured ..", "exc_info": "Traceback (most recent call last):\n  File \"C:\\Celebal data\\Clients\\Telecom Egypt\\Extract summary\\summary_pipeline\\main.py\", line 172, in audios_main\n    print(f\"got the data for audio: {filename}\", index, agent_id, agent_name, call_date, comment)\n                                                 ^^^^^\nUnboundLocalError: cannot access local variable 'index' where it is not associated with a value", "location": "main.py-audios_main"}
{"asctime": "2024-06-10 T16:50:35+0530", "message": "An Error Occured ..", "exc_info": "Traceback (most recent call last):\n  File \"C:\\Celebal data\\Clients\\Telecom Egypt\\Extract summary\\summary_pipeline\\main.py\", line 172, in audios_main\n    print(f\"got the data for audio: {filename}\", index, agent_id, agent_name, call_date, comment)\n                                                 ^^^^^\nUnboundLocalError: cannot access local variable 'index' where it is not associated with a value", "location": "main.py-audios_main"}
{"asctime": "2024-06-10 T16:52:13+0530", "message": "An Error Occured ..", "exc_info": "Traceback (most recent call last):\n  File \"C:\\Celebal data\\Clients\\Telecom Egypt\\Extract summary\\summary_pipeline\\main.py\", line 174, in audios_main\n    print(f\"got the data for audio: {filename}\", index, agent_id, agent_name, call_date, comment)\n                                                 ^^^^^\nUnboundLocalError: cannot access local variable 'index' where it is not associated with a value", "location": "main.py-audios_main"}
{"asctime": "2024-06-10 T16:56:14+0530", "message": "An Error Occured ..", "exc_info": "Traceback (most recent call last):\n  File \"C:\\Celebal data\\Clients\\Telecom Egypt\\Extract summary\\summary_pipeline\\main.py\", line 196, in audios_main\n    print(f\"got the data for audio: {filename}\", index, agent_id, agent_name, call_date, comment)\n                                                 ^^^^^\nUnboundLocalError: cannot access local variable 'index' where it is not associated with a value", "location": "main.py-audios_main"}
{"asctime": "2024-06-10 T17:00:09+0530", "message": "An Error Occured: ('Connection aborted.', ConnectionResetError(10054, 'An existing connection was forcibly closed by the remote host', None, 10054, None))", "exc_info": "Traceback (most recent call last):\n  File \"C:\\Celebal data\\Clients\\Telecom Egypt\\Extract summary\\summary_pipeline\\summvenv\\Lib\\site-packages\\urllib3\\connectionpool.py\", line 793, in urlopen\n    response = self._make_request(\n               ^^^^^^^^^^^^^^^^^^^\n  File \"C:\\Celebal data\\Clients\\Telecom Egypt\\Extract summary\\summary_pipeline\\summvenv\\Lib\\site-packages\\urllib3\\connectionpool.py\", line 491, in _make_request\n    raise new_e\n  File \"C:\\Celebal data\\Clients\\Telecom Egypt\\Extract summary\\summary_pipeline\\summvenv\\Lib\\site-packages\\urllib3\\connectionpool.py\", line 467, in _make_request\n    self._validate_conn(conn)\n  File \"C:\\Celebal data\\Clients\\Telecom Egypt\\Extract summary\\summary_pipeline\\summvenv\\Lib\\site-packages\\urllib3\\connectionpool.py\", line 1099, in _validate_conn\n    conn.connect()\n  File \"C:\\Celebal data\\Clients\\Telecom Egypt\\Extract summary\\summary_pipeline\\summvenv\\Lib\\site-packages\\urllib3\\connection.py\", line 653, in connect\n    sock_and_verified = _ssl_wrap_socket_and_match_hostname(\n                        ^^^^^^^^^^^^^^^^^^^^^^^^^^^^^^^^^^^^\n  File \"C:\\Celebal data\\Clients\\Telecom Egypt\\Extract summary\\summary_pipeline\\summvenv\\Lib\\site-packages\\urllib3\\connection.py\", line 806, in _ssl_wrap_socket_and_match_hostname\n    ssl_sock = ssl_wrap_socket(\n               ^^^^^^^^^^^^^^^^\n  File \"C:\\Celebal data\\Clients\\Telecom Egypt\\Extract summary\\summary_pipeline\\summvenv\\Lib\\site-packages\\urllib3\\util\\ssl_.py\", line 465, in ssl_wrap_socket\n    ssl_sock = _ssl_wrap_socket_impl(sock, context, tls_in_tls, server_hostname)\n               ^^^^^^^^^^^^^^^^^^^^^^^^^^^^^^^^^^^^^^^^^^^^^^^^^^^^^^^^^^^^^^^^^\n  File \"C:\\Celebal data\\Clients\\Telecom Egypt\\Extract summary\\summary_pipeline\\summvenv\\Lib\\site-packages\\urllib3\\util\\ssl_.py\", line 509, in _ssl_wrap_socket_impl\n    return ssl_context.wrap_socket(sock, server_hostname=server_hostname)\n           ^^^^^^^^^^^^^^^^^^^^^^^^^^^^^^^^^^^^^^^^^^^^^^^^^^^^^^^^^^^^^^\n  File \"C:\\Users\\MaharshiJasraj\\AppData\\Local\\Programs\\Python\\Python311\\Lib\\ssl.py\", line 517, in wrap_socket\n    return self.sslsocket_class._create(\n           ^^^^^^^^^^^^^^^^^^^^^^^^^^^^^\n  File \"C:\\Users\\MaharshiJasraj\\AppData\\Local\\Programs\\Python\\Python311\\Lib\\ssl.py\", line 1075, in _create\n    self.do_handshake()\n  File \"C:\\Users\\MaharshiJasraj\\AppData\\Local\\Programs\\Python\\Python311\\Lib\\ssl.py\", line 1346, in do_handshake\n    self._sslobj.do_handshake()\nConnectionResetError: [WinError 10054] An existing connection was forcibly closed by the remote host\n\nDuring handling of the above exception, another exception occurred:\n\nTraceback (most recent call last):\n  File \"C:\\Celebal data\\Clients\\Telecom Egypt\\Extract summary\\summary_pipeline\\summvenv\\Lib\\site-packages\\requests\\adapters.py\", line 667, in send\n    resp = conn.urlopen(\n           ^^^^^^^^^^^^^\n  File \"C:\\Celebal data\\Clients\\Telecom Egypt\\Extract summary\\summary_pipeline\\summvenv\\Lib\\site-packages\\urllib3\\connectionpool.py\", line 847, in urlopen\n    retries = retries.increment(\n              ^^^^^^^^^^^^^^^^^^\n  File \"C:\\Celebal data\\Clients\\Telecom Egypt\\Extract summary\\summary_pipeline\\summvenv\\Lib\\site-packages\\urllib3\\util\\retry.py\", line 470, in increment\n    raise reraise(type(error), error, _stacktrace)\n          ^^^^^^^^^^^^^^^^^^^^^^^^^^^^^^^^^^^^^^^^\n  File \"C:\\Celebal data\\Clients\\Telecom Egypt\\Extract summary\\summary_pipeline\\summvenv\\Lib\\site-packages\\urllib3\\util\\util.py\", line 38, in reraise\n    raise value.with_traceback(tb)\n  File \"C:\\Celebal data\\Clients\\Telecom Egypt\\Extract summary\\summary_pipeline\\summvenv\\Lib\\site-packages\\urllib3\\connectionpool.py\", line 793, in urlopen\n    response = self._make_request(\n               ^^^^^^^^^^^^^^^^^^^\n  File \"C:\\Celebal data\\Clients\\Telecom Egypt\\Extract summary\\summary_pipeline\\summvenv\\Lib\\site-packages\\urllib3\\connectionpool.py\", line 491, in _make_request\n    raise new_e\n  File \"C:\\Celebal data\\Clients\\Telecom Egypt\\Extract summary\\summary_pipeline\\summvenv\\Lib\\site-packages\\urllib3\\connectionpool.py\", line 467, in _make_request\n    self._validate_conn(conn)\n  File \"C:\\Celebal data\\Clients\\Telecom Egypt\\Extract summary\\summary_pipeline\\summvenv\\Lib\\site-packages\\urllib3\\connectionpool.py\", line 1099, in _validate_conn\n    conn.connect()\n  File \"C:\\Celebal data\\Clients\\Telecom Egypt\\Extract summary\\summary_pipeline\\summvenv\\Lib\\site-packages\\urllib3\\connection.py\", line 653, in connect\n    sock_and_verified = _ssl_wrap_socket_and_match_hostname(\n                        ^^^^^^^^^^^^^^^^^^^^^^^^^^^^^^^^^^^^\n  File \"C:\\Celebal data\\Clients\\Telecom Egypt\\Extract summary\\summary_pipeline\\summvenv\\Lib\\site-packages\\urllib3\\connection.py\", line 806, in _ssl_wrap_socket_and_match_hostname\n    ssl_sock = ssl_wrap_socket(\n               ^^^^^^^^^^^^^^^^\n  File \"C:\\Celebal data\\Clients\\Telecom Egypt\\Extract summary\\summary_pipeline\\summvenv\\Lib\\site-packages\\urllib3\\util\\ssl_.py\", line 465, in ssl_wrap_socket\n    ssl_sock = _ssl_wrap_socket_impl(sock, context, tls_in_tls, server_hostname)\n               ^^^^^^^^^^^^^^^^^^^^^^^^^^^^^^^^^^^^^^^^^^^^^^^^^^^^^^^^^^^^^^^^^\n  File \"C:\\Celebal data\\Clients\\Telecom Egypt\\Extract summary\\summary_pipeline\\summvenv\\Lib\\site-packages\\urllib3\\util\\ssl_.py\", line 509, in _ssl_wrap_socket_impl\n    return ssl_context.wrap_socket(sock, server_hostname=server_hostname)\n           ^^^^^^^^^^^^^^^^^^^^^^^^^^^^^^^^^^^^^^^^^^^^^^^^^^^^^^^^^^^^^^\n  File \"C:\\Users\\MaharshiJasraj\\AppData\\Local\\Programs\\Python\\Python311\\Lib\\ssl.py\", line 517, in wrap_socket\n    return self.sslsocket_class._create(\n           ^^^^^^^^^^^^^^^^^^^^^^^^^^^^^\n  File \"C:\\Users\\MaharshiJasraj\\AppData\\Local\\Programs\\Python\\Python311\\Lib\\ssl.py\", line 1075, in _create\n    self.do_handshake()\n  File \"C:\\Users\\MaharshiJasraj\\AppData\\Local\\Programs\\Python\\Python311\\Lib\\ssl.py\", line 1346, in do_handshake\n    self._sslobj.do_handshake()\nurllib3.exceptions.ProtocolError: ('Connection aborted.', ConnectionResetError(10054, 'An existing connection was forcibly closed by the remote host', None, 10054, None))\n\nDuring handling of the above exception, another exception occurred:\n\nTraceback (most recent call last):\n  File \"C:\\Celebal data\\Clients\\Telecom Egypt\\Extract summary\\summary_pipeline\\main.py\", line 267, in get_kpis\n    summarisation_result = summarisation_obj.abstractive_summarisation_helper(call)\n                           ^^^^^^^^^^^^^^^^^^^^^^^^^^^^^^^^^^^^^^^^^^^^^^^^^^^^^^^^\n  File \"C:\\Celebal data\\Clients\\Telecom Egypt\\Extract summary\\summary_pipeline\\src\\adapters\\summarisation.py\", line 239, in abstractive_summarisation_helper\n    res = requests.post(url = self.url, headers= headers, json= data)\n          ^^^^^^^^^^^^^^^^^^^^^^^^^^^^^^^^^^^^^^^^^^^^^^^^^^^^^^^^^^^\n  File \"C:\\Celebal data\\Clients\\Telecom Egypt\\Extract summary\\summary_pipeline\\summvenv\\Lib\\site-packages\\requests\\api.py\", line 115, in post\n    return request(\"post\", url, data=data, json=json, **kwargs)\n           ^^^^^^^^^^^^^^^^^^^^^^^^^^^^^^^^^^^^^^^^^^^^^^^^^^^^\n  File \"C:\\Celebal data\\Clients\\Telecom Egypt\\Extract summary\\summary_pipeline\\summvenv\\Lib\\site-packages\\requests\\api.py\", line 59, in request\n    return session.request(method=method, url=url, **kwargs)\n           ^^^^^^^^^^^^^^^^^^^^^^^^^^^^^^^^^^^^^^^^^^^^^^^^^\n  File \"C:\\Celebal data\\Clients\\Telecom Egypt\\Extract summary\\summary_pipeline\\summvenv\\Lib\\site-packages\\requests\\sessions.py\", line 589, in request\n    resp = self.send(prep, **send_kwargs)\n           ^^^^^^^^^^^^^^^^^^^^^^^^^^^^^^\n  File \"C:\\Celebal data\\Clients\\Telecom Egypt\\Extract summary\\summary_pipeline\\summvenv\\Lib\\site-packages\\requests\\sessions.py\", line 703, in send\n    r = adapter.send(request, **kwargs)\n        ^^^^^^^^^^^^^^^^^^^^^^^^^^^^^^^\n  File \"C:\\Celebal data\\Clients\\Telecom Egypt\\Extract summary\\summary_pipeline\\summvenv\\Lib\\site-packages\\requests\\adapters.py\", line 682, in send\n    raise ConnectionError(err, request=request)\nrequests.exceptions.ConnectionError: ('Connection aborted.', ConnectionResetError(10054, 'An existing connection was forcibly closed by the remote host', None, 10054, None))", "location": "main.py - pipeline_after_transcription"}
{"asctime": "2024-06-10 T17:00:09+0530", "message": "An Error Occured: 'Main' object has no attribute 'summarisation_result'", "exc_info": "Traceback (most recent call last):\n  File \"C:\\Celebal data\\Clients\\Telecom Egypt\\Extract summary\\summary_pipeline\\main.py\", line 313, in get_kpis_arabic\n    eng_summ_result = self.summarisation_result\n                      ^^^^^^^^^^^^^^^^^^^^^^^^^\nAttributeError: 'Main' object has no attribute 'summarisation_result'", "location": "main.py - pipeline_after_transcription"}
{"asctime": "2024-06-10 T17:00:09+0530", "message": "An Error Occured: 'NoneType' object is not subscriptable", "exc_info": "Traceback (most recent call last):\n  File \"C:\\Celebal data\\Clients\\Telecom Egypt\\Extract summary\\summary_pipeline\\main.py\", line 363, in add_summarization_to_mapping\n    print(f\"adding the data to the mapping for key : {summarized_key} with value {summarized_text['summary']}\")\n                                                                                  ~~~~~~~~~~~~~~~^^^^^^^^^^^\nTypeError: 'NoneType' object is not subscriptable", "location": "main.py - add_summarization_to_mapping"}
{"asctime": "2024-06-10 T17:00:09+0530", "message": "An Error Occured: 'NoneType' object is not subscriptable", "exc_info": "Traceback (most recent call last):\n  File \"C:\\Celebal data\\Clients\\Telecom Egypt\\Extract summary\\summary_pipeline\\main.py\", line 363, in add_summarization_to_mapping\n    print(f\"adding the data to the mapping for key : {summarized_key} with value {summarized_text['summary']}\")\n                                                                                  ~~~~~~~~~~~~~~~^^^^^^^^^^^\nTypeError: 'NoneType' object is not subscriptable", "location": "main.py - add_summarization_to_mapping"}
{"asctime": "2024-06-10 T17:00:09+0530", "message": "An Error Occured: 'NoneType' object is not subscriptable", "exc_info": "Traceback (most recent call last):\n  File \"C:\\Celebal data\\Clients\\Telecom Egypt\\Extract summary\\summary_pipeline\\main.py\", line 456, in pipeline_after_transcription\n    merged_output[\"result\"][\"summary\"] = result[\"summary\"]\n                                         ~~~~~~^^^^^^^^^^^\nTypeError: 'NoneType' object is not subscriptable", "location": "main.py - pipeline_after_transcription"}
{"asctime": "2024-06-10 T17:09:05+0530", "message": "An Error Occurred: [Errno 2] No such file or directory: 'C:\\\\Celebal data\\\\Clients\\\\Telecom Egypt\\\\Extract summary\\\\summary_pipeline/data/audio_analytics/158062039transcript_output_english.json'", "exc_info": "Traceback (most recent call last):\n  File \"C:\\Celebal data\\Clients\\Telecom Egypt\\Extract summary\\summary_pipeline\\main.py\", line 399, in add_mapping_to_excel\n    with open(transcription_path, \"r\", encoding=\"utf-8\") as tp:\n         ^^^^^^^^^^^^^^^^^^^^^^^^^^^^^^^^^^^^^^^^^^^^^^^\nFileNotFoundError: [Errno 2] No such file or directory: 'C:\\\\Celebal data\\\\Clients\\\\Telecom Egypt\\\\Extract summary\\\\summary_pipeline/data/audio_analytics/158062039transcript_output_english.json'", "location": "main.py - add_mapping_to_excel"}
{"asctime": "2024-06-10 T17:20:42+0530", "message": "An Error Occurred: [Errno 2] No such file or directory: 'C:\\\\Celebal data\\\\Clients\\\\Telecom Egypt\\\\Extract summary\\\\summary_pipeline/data/audio_analytics/158062039transcript_output_english.json'", "exc_info": "Traceback (most recent call last):\n  File \"C:\\Celebal data\\Clients\\Telecom Egypt\\Extract summary\\summary_pipeline\\main.py\", line 401, in add_mapping_to_excel\n    with open(transcription_path, \"r\", encoding=\"utf-8\") as tp:\n         ^^^^^^^^^^^^^^^^^^^^^^^^^^^^^^^^^^^^^^^^^^^^^^^\nFileNotFoundError: [Errno 2] No such file or directory: 'C:\\\\Celebal data\\\\Clients\\\\Telecom Egypt\\\\Extract summary\\\\summary_pipeline/data/audio_analytics/158062039transcript_output_english.json'", "location": "main.py - add_mapping_to_excel"}
