{"asctime": "2024-06-04 T23:39:37+0530", "message": "An Error Occured ..", "exc_info": "Traceback (most recent call last):\n  File \"C:\\Celebal data\\Clients\\Telecom Egypt\\fastapi\\Telecom%20Egypt%20Internal\\main.py\", line 688, in power_bi_report_main_helper\n    agent_percentage, customer_percentage = utilization_precentage(transcription_path)\n                                            ^^^^^^^^^^^^^^^^^^^^^^^^^^^^^^^^^^^^^^^^^^\n  File \"C:\\Celebal data\\Clients\\Telecom Egypt\\fastapi\\Telecom%20Egypt%20Internal\\src\\utils.py\", line 63, in utilization_precentage\n    transcript_data = json.load(fh)\n                      ^^^^^^^^^^^^^\n  File \"C:\\Users\\MaharshiJasraj\\AppData\\Local\\Programs\\Python\\Python311\\Lib\\json\\__init__.py\", line 293, in load\n    return loads(fp.read(),\n                 ^^^^^^^^^\n  File \"C:\\Users\\MaharshiJasraj\\AppData\\Local\\Programs\\Python\\Python311\\Lib\\encodings\\cp1252.py\", line 23, in decode\n    return codecs.charmap_decode(input,self.errors,decoding_table)[0]\n           ^^^^^^^^^^^^^^^^^^^^^^^^^^^^^^^^^^^^^^^^^^^^^^^^^^^^^^^\nUnicodeDecodeError: 'charmap' codec can't decode byte 0x81 in position 305: character maps to <undefined>", "location": "main.py - power_bi_report_main_helper"}
{"asctime": "2024-06-05 T00:03:22+0530", "message": "An Error Occured ..", "exc_info": "Traceback (most recent call last):\n  File \"C:\\Celebal data\\Clients\\Telecom Egypt\\fastapi\\Telecom%20Egypt%20Internal\\tel_venv\\Lib\\site-packages\\urllib3\\connection.py\", line 198, in _new_conn\n    sock = connection.create_connection(\n           ^^^^^^^^^^^^^^^^^^^^^^^^^^^^^\n  File \"C:\\Celebal data\\Clients\\Telecom Egypt\\fastapi\\Telecom%20Egypt%20Internal\\tel_venv\\Lib\\site-packages\\urllib3\\util\\connection.py\", line 60, in create_connection\n    for res in socket.getaddrinfo(host, port, family, socket.SOCK_STREAM):\n               ^^^^^^^^^^^^^^^^^^^^^^^^^^^^^^^^^^^^^^^^^^^^^^^^^^^^^^^^^^\n  File \"C:\\Users\\MaharshiJasraj\\AppData\\Local\\Programs\\Python\\Python311\\Lib\\socket.py\", line 962, in getaddrinfo\n    for res in _socket.getaddrinfo(host, port, family, type, proto, flags):\n               ^^^^^^^^^^^^^^^^^^^^^^^^^^^^^^^^^^^^^^^^^^^^^^^^^^^^^^^^^^^\nsocket.gaierror: [Errno 11001] getaddrinfo failed\n\nThe above exception was the direct cause of the following exception:\n\nTraceback (most recent call last):\n  File \"C:\\Celebal data\\Clients\\Telecom Egypt\\fastapi\\Telecom%20Egypt%20Internal\\tel_venv\\Lib\\site-packages\\urllib3\\connectionpool.py\", line 793, in urlopen\n    response = self._make_request(\n               ^^^^^^^^^^^^^^^^^^^\n  File \"C:\\Celebal data\\Clients\\Telecom Egypt\\fastapi\\Telecom%20Egypt%20Internal\\tel_venv\\Lib\\site-packages\\urllib3\\connectionpool.py\", line 491, in _make_request\n    raise new_e\n  File \"C:\\Celebal data\\Clients\\Telecom Egypt\\fastapi\\Telecom%20Egypt%20Internal\\tel_venv\\Lib\\site-packages\\urllib3\\connectionpool.py\", line 467, in _make_request\n    self._validate_conn(conn)\n  File \"C:\\Celebal data\\Clients\\Telecom Egypt\\fastapi\\Telecom%20Egypt%20Internal\\tel_venv\\Lib\\site-packages\\urllib3\\connectionpool.py\", line 1099, in _validate_conn\n    conn.connect()\n  File \"C:\\Celebal data\\Clients\\Telecom Egypt\\fastapi\\Telecom%20Egypt%20Internal\\tel_venv\\Lib\\site-packages\\urllib3\\connection.py\", line 616, in connect\n    self.sock = sock = self._new_conn()\n                       ^^^^^^^^^^^^^^^^\n  File \"C:\\Celebal data\\Clients\\Telecom Egypt\\fastapi\\Telecom%20Egypt%20Internal\\tel_venv\\Lib\\site-packages\\urllib3\\connection.py\", line 205, in _new_conn\n    raise NameResolutionError(self.host, self, e) from e\nurllib3.exceptions.NameResolutionError: <urllib3.connection.HTTPSConnection object at 0x0000027AAA563DD0>: Failed to resolve 'demo-langservice-mij.cognitiveservices.azure.com' ([Errno 11001] getaddrinfo failed)\n\nThe above exception was the direct cause of the following exception:\n\nTraceback (most recent call last):\n  File \"C:\\Celebal data\\Clients\\Telecom Egypt\\fastapi\\Telecom%20Egypt%20Internal\\tel_venv\\Lib\\site-packages\\requests\\adapters.py\", line 486, in send\n    resp = conn.urlopen(\n           ^^^^^^^^^^^^^\n  File \"C:\\Celebal data\\Clients\\Telecom Egypt\\fastapi\\Telecom%20Egypt%20Internal\\tel_venv\\Lib\\site-packages\\urllib3\\connectionpool.py\", line 847, in urlopen\n    retries = retries.increment(\n              ^^^^^^^^^^^^^^^^^^\n  File \"C:\\Celebal data\\Clients\\Telecom Egypt\\fastapi\\Telecom%20Egypt%20Internal\\tel_venv\\Lib\\site-packages\\urllib3\\util\\retry.py\", line 515, in increment\n    raise MaxRetryError(_pool, url, reason) from reason  # type: ignore[arg-type]\n    ^^^^^^^^^^^^^^^^^^^^^^^^^^^^^^^^^^^^^^^^^^^^^^^^^^^\nurllib3.exceptions.MaxRetryError: HTTPSConnectionPool(host='demo-langservice-mij.cognitiveservices.azure.com', port=443): Max retries exceeded with url: //language/:analyze-text?api-version=2023-04-15-preview (Caused by NameResolutionError(\"<urllib3.connection.HTTPSConnection object at 0x0000027AAA563DD0>: Failed to resolve 'demo-langservice-mij.cognitiveservices.azure.com' ([Errno 11001] getaddrinfo failed)\"))\n\nDuring handling of the above exception, another exception occurred:\n\nTraceback (most recent call last):\n  File \"C:\\Celebal data\\Clients\\Telecom Egypt\\fastapi\\Telecom%20Egypt%20Internal\\src\\adapters\\sentiment_analysis.py\", line 47, in send_request\n    sentiment_response = requests.post(url= url, json=data, headers= headers)\n                         ^^^^^^^^^^^^^^^^^^^^^^^^^^^^^^^^^^^^^^^^^^^^^^^^^^^^\n  File \"C:\\Celebal data\\Clients\\Telecom Egypt\\fastapi\\Telecom%20Egypt%20Internal\\tel_venv\\Lib\\site-packages\\requests\\api.py\", line 115, in post\n    return request(\"post\", url, data=data, json=json, **kwargs)\n           ^^^^^^^^^^^^^^^^^^^^^^^^^^^^^^^^^^^^^^^^^^^^^^^^^^^^\n  File \"C:\\Celebal data\\Clients\\Telecom Egypt\\fastapi\\Telecom%20Egypt%20Internal\\tel_venv\\Lib\\site-packages\\requests\\api.py\", line 59, in request\n    return session.request(method=method, url=url, **kwargs)\n           ^^^^^^^^^^^^^^^^^^^^^^^^^^^^^^^^^^^^^^^^^^^^^^^^^\n  File \"C:\\Celebal data\\Clients\\Telecom Egypt\\fastapi\\Telecom%20Egypt%20Internal\\tel_venv\\Lib\\site-packages\\requests\\sessions.py\", line 589, in request\n    resp = self.send(prep, **send_kwargs)\n           ^^^^^^^^^^^^^^^^^^^^^^^^^^^^^^\n  File \"C:\\Celebal data\\Clients\\Telecom Egypt\\fastapi\\Telecom%20Egypt%20Internal\\tel_venv\\Lib\\site-packages\\requests\\sessions.py\", line 703, in send\n    r = adapter.send(request, **kwargs)\n        ^^^^^^^^^^^^^^^^^^^^^^^^^^^^^^^\n  File \"C:\\Celebal data\\Clients\\Telecom Egypt\\fastapi\\Telecom%20Egypt%20Internal\\tel_venv\\Lib\\site-packages\\requests\\adapters.py\", line 519, in send\n    raise ConnectionError(e, request=request)\nrequests.exceptions.ConnectionError: HTTPSConnectionPool(host='demo-langservice-mij.cognitiveservices.azure.com', port=443): Max retries exceeded with url: //language/:analyze-text?api-version=2023-04-15-preview (Caused by NameResolutionError(\"<urllib3.connection.HTTPSConnection object at 0x0000027AAA563DD0>: Failed to resolve 'demo-langservice-mij.cognitiveservices.azure.com' ([Errno 11001] getaddrinfo failed)\"))", "location": "sentiment_analysis.py - send_request"}
{"asctime": "2024-06-05 T00:03:22+0530", "message": "An Error Occured ..", "exc_info": "Traceback (most recent call last):\n  File \"C:\\Celebal data\\Clients\\Telecom Egypt\\fastapi\\Telecom%20Egypt%20Internal\\src\\adapters\\sentiment_analysis.py\", line 108, in sentiment_helper\n    sentiment_result = json.loads(sentiment_response.text)\n                                  ^^^^^^^^^^^^^^^^^^^^^^^\nAttributeError: 'NoneType' object has no attribute 'text'", "location": "sentiment_analysis.py - sentiment_helper"}
{"asctime": "2024-06-05 T00:03:22+0530", "message": "An Error Occured ..", "exc_info": "Traceback (most recent call last):\n  File \"C:\\Celebal data\\Clients\\Telecom Egypt\\fastapi\\Telecom%20Egypt%20Internal\\src\\adapters\\sentiment_analysis.py\", line 139, in sentiment_pipeline\n    if result[\"status\"] == \"success\":\n       ~~~~~~^^^^^^^^^^\nTypeError: 'NoneType' object is not subscriptable", "location": "sentiment_analysis.py - sentiment_pipeline"}
{"asctime": "2024-06-05 T00:03:33+0530", "message": "An Error Occured ..", "exc_info": "Traceback (most recent call last):\n  File \"C:\\Celebal data\\Clients\\Telecom Egypt\\fastapi\\Telecom%20Egypt%20Internal\\tel_venv\\Lib\\site-packages\\urllib3\\connection.py\", line 198, in _new_conn\n    sock = connection.create_connection(\n           ^^^^^^^^^^^^^^^^^^^^^^^^^^^^^\n  File \"C:\\Celebal data\\Clients\\Telecom Egypt\\fastapi\\Telecom%20Egypt%20Internal\\tel_venv\\Lib\\site-packages\\urllib3\\util\\connection.py\", line 60, in create_connection\n    for res in socket.getaddrinfo(host, port, family, socket.SOCK_STREAM):\n               ^^^^^^^^^^^^^^^^^^^^^^^^^^^^^^^^^^^^^^^^^^^^^^^^^^^^^^^^^^\n  File \"C:\\Users\\MaharshiJasraj\\AppData\\Local\\Programs\\Python\\Python311\\Lib\\socket.py\", line 962, in getaddrinfo\n    for res in _socket.getaddrinfo(host, port, family, type, proto, flags):\n               ^^^^^^^^^^^^^^^^^^^^^^^^^^^^^^^^^^^^^^^^^^^^^^^^^^^^^^^^^^^\nsocket.gaierror: [Errno 11001] getaddrinfo failed\n\nThe above exception was the direct cause of the following exception:\n\nTraceback (most recent call last):\n  File \"C:\\Celebal data\\Clients\\Telecom Egypt\\fastapi\\Telecom%20Egypt%20Internal\\tel_venv\\Lib\\site-packages\\urllib3\\connectionpool.py\", line 793, in urlopen\n    response = self._make_request(\n               ^^^^^^^^^^^^^^^^^^^\n  File \"C:\\Celebal data\\Clients\\Telecom Egypt\\fastapi\\Telecom%20Egypt%20Internal\\tel_venv\\Lib\\site-packages\\urllib3\\connectionpool.py\", line 491, in _make_request\n    raise new_e\n  File \"C:\\Celebal data\\Clients\\Telecom Egypt\\fastapi\\Telecom%20Egypt%20Internal\\tel_venv\\Lib\\site-packages\\urllib3\\connectionpool.py\", line 467, in _make_request\n    self._validate_conn(conn)\n  File \"C:\\Celebal data\\Clients\\Telecom Egypt\\fastapi\\Telecom%20Egypt%20Internal\\tel_venv\\Lib\\site-packages\\urllib3\\connectionpool.py\", line 1099, in _validate_conn\n    conn.connect()\n  File \"C:\\Celebal data\\Clients\\Telecom Egypt\\fastapi\\Telecom%20Egypt%20Internal\\tel_venv\\Lib\\site-packages\\urllib3\\connection.py\", line 616, in connect\n    self.sock = sock = self._new_conn()\n                       ^^^^^^^^^^^^^^^^\n  File \"C:\\Celebal data\\Clients\\Telecom Egypt\\fastapi\\Telecom%20Egypt%20Internal\\tel_venv\\Lib\\site-packages\\urllib3\\connection.py\", line 205, in _new_conn\n    raise NameResolutionError(self.host, self, e) from e\nurllib3.exceptions.NameResolutionError: <urllib3.connection.HTTPSConnection object at 0x0000027AAA551F50>: Failed to resolve 'demo-langservice-mij.cognitiveservices.azure.com' ([Errno 11001] getaddrinfo failed)\n\nThe above exception was the direct cause of the following exception:\n\nTraceback (most recent call last):\n  File \"C:\\Celebal data\\Clients\\Telecom Egypt\\fastapi\\Telecom%20Egypt%20Internal\\tel_venv\\Lib\\site-packages\\requests\\adapters.py\", line 486, in send\n    resp = conn.urlopen(\n           ^^^^^^^^^^^^^\n  File \"C:\\Celebal data\\Clients\\Telecom Egypt\\fastapi\\Telecom%20Egypt%20Internal\\tel_venv\\Lib\\site-packages\\urllib3\\connectionpool.py\", line 847, in urlopen\n    retries = retries.increment(\n              ^^^^^^^^^^^^^^^^^^\n  File \"C:\\Celebal data\\Clients\\Telecom Egypt\\fastapi\\Telecom%20Egypt%20Internal\\tel_venv\\Lib\\site-packages\\urllib3\\util\\retry.py\", line 515, in increment\n    raise MaxRetryError(_pool, url, reason) from reason  # type: ignore[arg-type]\n    ^^^^^^^^^^^^^^^^^^^^^^^^^^^^^^^^^^^^^^^^^^^^^^^^^^^\nurllib3.exceptions.MaxRetryError: HTTPSConnectionPool(host='demo-langservice-mij.cognitiveservices.azure.com', port=443): Max retries exceeded with url: //language/:analyze-text?api-version=2022-05-01 (Caused by NameResolutionError(\"<urllib3.connection.HTTPSConnection object at 0x0000027AAA551F50>: Failed to resolve 'demo-langservice-mij.cognitiveservices.azure.com' ([Errno 11001] getaddrinfo failed)\"))\n\nDuring handling of the above exception, another exception occurred:\n\nTraceback (most recent call last):\n  File \"C:\\Celebal data\\Clients\\Telecom Egypt\\fastapi\\Telecom%20Egypt%20Internal\\src\\adapters\\keyPhrase.py\", line 41, in send_request\n    response = requests.post(url= url, json= data, headers= headers)\n               ^^^^^^^^^^^^^^^^^^^^^^^^^^^^^^^^^^^^^^^^^^^^^^^^^^^^^\n  File \"C:\\Celebal data\\Clients\\Telecom Egypt\\fastapi\\Telecom%20Egypt%20Internal\\tel_venv\\Lib\\site-packages\\requests\\api.py\", line 115, in post\n    return request(\"post\", url, data=data, json=json, **kwargs)\n           ^^^^^^^^^^^^^^^^^^^^^^^^^^^^^^^^^^^^^^^^^^^^^^^^^^^^\n  File \"C:\\Celebal data\\Clients\\Telecom Egypt\\fastapi\\Telecom%20Egypt%20Internal\\tel_venv\\Lib\\site-packages\\requests\\api.py\", line 59, in request\n    return session.request(method=method, url=url, **kwargs)\n           ^^^^^^^^^^^^^^^^^^^^^^^^^^^^^^^^^^^^^^^^^^^^^^^^^\n  File \"C:\\Celebal data\\Clients\\Telecom Egypt\\fastapi\\Telecom%20Egypt%20Internal\\tel_venv\\Lib\\site-packages\\requests\\sessions.py\", line 589, in request\n    resp = self.send(prep, **send_kwargs)\n           ^^^^^^^^^^^^^^^^^^^^^^^^^^^^^^\n  File \"C:\\Celebal data\\Clients\\Telecom Egypt\\fastapi\\Telecom%20Egypt%20Internal\\tel_venv\\Lib\\site-packages\\requests\\sessions.py\", line 703, in send\n    r = adapter.send(request, **kwargs)\n        ^^^^^^^^^^^^^^^^^^^^^^^^^^^^^^^\n  File \"C:\\Celebal data\\Clients\\Telecom Egypt\\fastapi\\Telecom%20Egypt%20Internal\\tel_venv\\Lib\\site-packages\\requests\\adapters.py\", line 519, in send\n    raise ConnectionError(e, request=request)\nrequests.exceptions.ConnectionError: HTTPSConnectionPool(host='demo-langservice-mij.cognitiveservices.azure.com', port=443): Max retries exceeded with url: //language/:analyze-text?api-version=2022-05-01 (Caused by NameResolutionError(\"<urllib3.connection.HTTPSConnection object at 0x0000027AAA551F50>: Failed to resolve 'demo-langservice-mij.cognitiveservices.azure.com' ([Errno 11001] getaddrinfo failed)\"))", "location": "KeyPhrase.py - send_request"}
{"asctime": "2024-06-05 T00:03:33+0530", "message": "An Error Occured ..", "exc_info": "Traceback (most recent call last):\n  File \"C:\\Celebal data\\Clients\\Telecom Egypt\\fastapi\\Telecom%20Egypt%20Internal\\src\\adapters\\keyPhrase.py\", line 53, in keyPhrase_helper\n    if response.status_code == 401:\n       ^^^^^^^^^^^^^^^^^^^^\nAttributeError: 'NoneType' object has no attribute 'status_code'", "location": "KeyPhrase.py - keyPhrase_helper"}
{"asctime": "2024-06-05 T00:03:33+0530", "message": "An Error Occured ..", "exc_info": "Traceback (most recent call last):\n  File \"C:\\Celebal data\\Clients\\Telecom Egypt\\fastapi\\Telecom%20Egypt%20Internal\\src\\adapters\\keyPhrase.py\", line 81, in keyPhrase_pipeline\n    if result[\"status\"] == \"success\":\n       ~~~~~~^^^^^^^^^^\nTypeError: 'NoneType' object is not subscriptable", "location": "KeyPhrase.py - keyPhrase_pipeline"}
{"asctime": "2024-06-05 T00:03:33+0530", "message": "An Error Occured: 'NoneType' object is not iterable", "exc_info": "Traceback (most recent call last):\n  File \"C:\\Celebal data\\Clients\\Telecom Egypt\\fastapi\\Telecom%20Egypt%20Internal\\main.py\", line 346, in pipeline_after_transcription\n    for ls in arabic_result[\"keyPhrases_ls\"]:\nTypeError: 'NoneType' object is not iterable", "location": "main.py - pipeline_after_transcription"}
{"asctime": "2024-06-05 T00:07:18+0530", "message": "An Error Occured ..", "exc_info": "Traceback (most recent call last):\n  File \"C:\\Celebal data\\Clients\\Telecom Egypt\\fastapi\\Telecom%20Egypt%20Internal\\tel_venv\\Lib\\site-packages\\urllib3\\connection.py\", line 198, in _new_conn\n    sock = connection.create_connection(\n           ^^^^^^^^^^^^^^^^^^^^^^^^^^^^^\n  File \"C:\\Celebal data\\Clients\\Telecom Egypt\\fastapi\\Telecom%20Egypt%20Internal\\tel_venv\\Lib\\site-packages\\urllib3\\util\\connection.py\", line 60, in create_connection\n    for res in socket.getaddrinfo(host, port, family, socket.SOCK_STREAM):\n               ^^^^^^^^^^^^^^^^^^^^^^^^^^^^^^^^^^^^^^^^^^^^^^^^^^^^^^^^^^\n  File \"C:\\Users\\MaharshiJasraj\\AppData\\Local\\Programs\\Python\\Python311\\Lib\\socket.py\", line 962, in getaddrinfo\n    for res in _socket.getaddrinfo(host, port, family, type, proto, flags):\n               ^^^^^^^^^^^^^^^^^^^^^^^^^^^^^^^^^^^^^^^^^^^^^^^^^^^^^^^^^^^\nsocket.gaierror: [Errno 11001] getaddrinfo failed\n\nThe above exception was the direct cause of the following exception:\n\nTraceback (most recent call last):\n  File \"C:\\Celebal data\\Clients\\Telecom Egypt\\fastapi\\Telecom%20Egypt%20Internal\\tel_venv\\Lib\\site-packages\\urllib3\\connectionpool.py\", line 793, in urlopen\n    response = self._make_request(\n               ^^^^^^^^^^^^^^^^^^^\n  File \"C:\\Celebal data\\Clients\\Telecom Egypt\\fastapi\\Telecom%20Egypt%20Internal\\tel_venv\\Lib\\site-packages\\urllib3\\connectionpool.py\", line 491, in _make_request\n    raise new_e\n  File \"C:\\Celebal data\\Clients\\Telecom Egypt\\fastapi\\Telecom%20Egypt%20Internal\\tel_venv\\Lib\\site-packages\\urllib3\\connectionpool.py\", line 467, in _make_request\n    self._validate_conn(conn)\n  File \"C:\\Celebal data\\Clients\\Telecom Egypt\\fastapi\\Telecom%20Egypt%20Internal\\tel_venv\\Lib\\site-packages\\urllib3\\connectionpool.py\", line 1099, in _validate_conn\n    conn.connect()\n  File \"C:\\Celebal data\\Clients\\Telecom Egypt\\fastapi\\Telecom%20Egypt%20Internal\\tel_venv\\Lib\\site-packages\\urllib3\\connection.py\", line 616, in connect\n    self.sock = sock = self._new_conn()\n                       ^^^^^^^^^^^^^^^^\n  File \"C:\\Celebal data\\Clients\\Telecom Egypt\\fastapi\\Telecom%20Egypt%20Internal\\tel_venv\\Lib\\site-packages\\urllib3\\connection.py\", line 205, in _new_conn\n    raise NameResolutionError(self.host, self, e) from e\nurllib3.exceptions.NameResolutionError: <urllib3.connection.HTTPSConnection object at 0x0000027AAA579510>: Failed to resolve 'demo-langservice-mij.cognitiveservices.azure.com' ([Errno 11001] getaddrinfo failed)\n\nThe above exception was the direct cause of the following exception:\n\nTraceback (most recent call last):\n  File \"C:\\Celebal data\\Clients\\Telecom Egypt\\fastapi\\Telecom%20Egypt%20Internal\\tel_venv\\Lib\\site-packages\\requests\\adapters.py\", line 486, in send\n    resp = conn.urlopen(\n           ^^^^^^^^^^^^^\n  File \"C:\\Celebal data\\Clients\\Telecom Egypt\\fastapi\\Telecom%20Egypt%20Internal\\tel_venv\\Lib\\site-packages\\urllib3\\connectionpool.py\", line 847, in urlopen\n    retries = retries.increment(\n              ^^^^^^^^^^^^^^^^^^\n  File \"C:\\Celebal data\\Clients\\Telecom Egypt\\fastapi\\Telecom%20Egypt%20Internal\\tel_venv\\Lib\\site-packages\\urllib3\\util\\retry.py\", line 515, in increment\n    raise MaxRetryError(_pool, url, reason) from reason  # type: ignore[arg-type]\n    ^^^^^^^^^^^^^^^^^^^^^^^^^^^^^^^^^^^^^^^^^^^^^^^^^^^\nurllib3.exceptions.MaxRetryError: HTTPSConnectionPool(host='demo-langservice-mij.cognitiveservices.azure.com', port=443): Max retries exceeded with url: //language/:analyze-text?api-version=2022-05-01 (Caused by NameResolutionError(\"<urllib3.connection.HTTPSConnection object at 0x0000027AAA579510>: Failed to resolve 'demo-langservice-mij.cognitiveservices.azure.com' ([Errno 11001] getaddrinfo failed)\"))\n\nDuring handling of the above exception, another exception occurred:\n\nTraceback (most recent call last):\n  File \"C:\\Celebal data\\Clients\\Telecom Egypt\\fastapi\\Telecom%20Egypt%20Internal\\src\\adapters\\keyPhrase.py\", line 41, in send_request\n    response = requests.post(url= url, json= data, headers= headers)\n               ^^^^^^^^^^^^^^^^^^^^^^^^^^^^^^^^^^^^^^^^^^^^^^^^^^^^^\n  File \"C:\\Celebal data\\Clients\\Telecom Egypt\\fastapi\\Telecom%20Egypt%20Internal\\tel_venv\\Lib\\site-packages\\requests\\api.py\", line 115, in post\n    return request(\"post\", url, data=data, json=json, **kwargs)\n           ^^^^^^^^^^^^^^^^^^^^^^^^^^^^^^^^^^^^^^^^^^^^^^^^^^^^\n  File \"C:\\Celebal data\\Clients\\Telecom Egypt\\fastapi\\Telecom%20Egypt%20Internal\\tel_venv\\Lib\\site-packages\\requests\\api.py\", line 59, in request\n    return session.request(method=method, url=url, **kwargs)\n           ^^^^^^^^^^^^^^^^^^^^^^^^^^^^^^^^^^^^^^^^^^^^^^^^^\n  File \"C:\\Celebal data\\Clients\\Telecom Egypt\\fastapi\\Telecom%20Egypt%20Internal\\tel_venv\\Lib\\site-packages\\requests\\sessions.py\", line 589, in request\n    resp = self.send(prep, **send_kwargs)\n           ^^^^^^^^^^^^^^^^^^^^^^^^^^^^^^\n  File \"C:\\Celebal data\\Clients\\Telecom Egypt\\fastapi\\Telecom%20Egypt%20Internal\\tel_venv\\Lib\\site-packages\\requests\\sessions.py\", line 703, in send\n    r = adapter.send(request, **kwargs)\n        ^^^^^^^^^^^^^^^^^^^^^^^^^^^^^^^\n  File \"C:\\Celebal data\\Clients\\Telecom Egypt\\fastapi\\Telecom%20Egypt%20Internal\\tel_venv\\Lib\\site-packages\\requests\\adapters.py\", line 519, in send\n    raise ConnectionError(e, request=request)\nrequests.exceptions.ConnectionError: HTTPSConnectionPool(host='demo-langservice-mij.cognitiveservices.azure.com', port=443): Max retries exceeded with url: //language/:analyze-text?api-version=2022-05-01 (Caused by NameResolutionError(\"<urllib3.connection.HTTPSConnection object at 0x0000027AAA579510>: Failed to resolve 'demo-langservice-mij.cognitiveservices.azure.com' ([Errno 11001] getaddrinfo failed)\"))", "location": "KeyPhrase.py - send_request"}
{"asctime": "2024-06-05 T00:07:18+0530", "message": "An Error Occured ..", "exc_info": "Traceback (most recent call last):\n  File \"C:\\Celebal data\\Clients\\Telecom Egypt\\fastapi\\Telecom%20Egypt%20Internal\\src\\adapters\\keyPhrase.py\", line 53, in keyPhrase_helper\n    if response.status_code == 401:\n       ^^^^^^^^^^^^^^^^^^^^\nAttributeError: 'NoneType' object has no attribute 'status_code'", "location": "KeyPhrase.py - keyPhrase_helper"}
{"asctime": "2024-06-05 T00:07:18+0530", "message": "An Error Occured ..", "exc_info": "Traceback (most recent call last):\n  File \"C:\\Celebal data\\Clients\\Telecom Egypt\\fastapi\\Telecom%20Egypt%20Internal\\src\\adapters\\keyPhrase.py\", line 81, in keyPhrase_pipeline\n    if result[\"status\"] == \"success\":\n       ~~~~~~^^^^^^^^^^\nTypeError: 'NoneType' object is not subscriptable", "location": "KeyPhrase.py - keyPhrase_pipeline"}
{"asctime": "2024-06-05 T00:07:18+0530", "message": "An Error Occured: 'NoneType' object is not iterable", "exc_info": "Traceback (most recent call last):\n  File \"C:\\Celebal data\\Clients\\Telecom Egypt\\fastapi\\Telecom%20Egypt%20Internal\\main.py\", line 346, in pipeline_after_transcription\n    for ls in arabic_result[\"keyPhrases_ls\"]:\nTypeError: 'NoneType' object is not iterable", "location": "main.py - pipeline_after_transcription"}
{"asctime": "2024-06-05 T00:11:56+0530", "message": "An Error Occured ..", "exc_info": "Traceback (most recent call last):\n  File \"C:\\Celebal data\\Clients\\Telecom Egypt\\fastapi\\Telecom%20Egypt%20Internal\\tel_venv\\Lib\\site-packages\\urllib3\\connection.py\", line 198, in _new_conn\n    sock = connection.create_connection(\n           ^^^^^^^^^^^^^^^^^^^^^^^^^^^^^\n  File \"C:\\Celebal data\\Clients\\Telecom Egypt\\fastapi\\Telecom%20Egypt%20Internal\\tel_venv\\Lib\\site-packages\\urllib3\\util\\connection.py\", line 60, in create_connection\n    for res in socket.getaddrinfo(host, port, family, socket.SOCK_STREAM):\n               ^^^^^^^^^^^^^^^^^^^^^^^^^^^^^^^^^^^^^^^^^^^^^^^^^^^^^^^^^^\n  File \"C:\\Users\\MaharshiJasraj\\AppData\\Local\\Programs\\Python\\Python311\\Lib\\socket.py\", line 962, in getaddrinfo\n    for res in _socket.getaddrinfo(host, port, family, type, proto, flags):\n               ^^^^^^^^^^^^^^^^^^^^^^^^^^^^^^^^^^^^^^^^^^^^^^^^^^^^^^^^^^^\nsocket.gaierror: [Errno 11001] getaddrinfo failed\n\nThe above exception was the direct cause of the following exception:\n\nTraceback (most recent call last):\n  File \"C:\\Celebal data\\Clients\\Telecom Egypt\\fastapi\\Telecom%20Egypt%20Internal\\tel_venv\\Lib\\site-packages\\urllib3\\connectionpool.py\", line 793, in urlopen\n    response = self._make_request(\n               ^^^^^^^^^^^^^^^^^^^\n  File \"C:\\Celebal data\\Clients\\Telecom Egypt\\fastapi\\Telecom%20Egypt%20Internal\\tel_venv\\Lib\\site-packages\\urllib3\\connectionpool.py\", line 491, in _make_request\n    raise new_e\n  File \"C:\\Celebal data\\Clients\\Telecom Egypt\\fastapi\\Telecom%20Egypt%20Internal\\tel_venv\\Lib\\site-packages\\urllib3\\connectionpool.py\", line 467, in _make_request\n    self._validate_conn(conn)\n  File \"C:\\Celebal data\\Clients\\Telecom Egypt\\fastapi\\Telecom%20Egypt%20Internal\\tel_venv\\Lib\\site-packages\\urllib3\\connectionpool.py\", line 1099, in _validate_conn\n    conn.connect()\n  File \"C:\\Celebal data\\Clients\\Telecom Egypt\\fastapi\\Telecom%20Egypt%20Internal\\tel_venv\\Lib\\site-packages\\urllib3\\connection.py\", line 616, in connect\n    self.sock = sock = self._new_conn()\n                       ^^^^^^^^^^^^^^^^\n  File \"C:\\Celebal data\\Clients\\Telecom Egypt\\fastapi\\Telecom%20Egypt%20Internal\\tel_venv\\Lib\\site-packages\\urllib3\\connection.py\", line 205, in _new_conn\n    raise NameResolutionError(self.host, self, e) from e\nurllib3.exceptions.NameResolutionError: <urllib3.connection.HTTPSConnection object at 0x0000027AAA55EAD0>: Failed to resolve 'demo-langservice-mij.cognitiveservices.azure.com' ([Errno 11001] getaddrinfo failed)\n\nThe above exception was the direct cause of the following exception:\n\nTraceback (most recent call last):\n  File \"C:\\Celebal data\\Clients\\Telecom Egypt\\fastapi\\Telecom%20Egypt%20Internal\\tel_venv\\Lib\\site-packages\\requests\\adapters.py\", line 486, in send\n    resp = conn.urlopen(\n           ^^^^^^^^^^^^^\n  File \"C:\\Celebal data\\Clients\\Telecom Egypt\\fastapi\\Telecom%20Egypt%20Internal\\tel_venv\\Lib\\site-packages\\urllib3\\connectionpool.py\", line 847, in urlopen\n    retries = retries.increment(\n              ^^^^^^^^^^^^^^^^^^\n  File \"C:\\Celebal data\\Clients\\Telecom Egypt\\fastapi\\Telecom%20Egypt%20Internal\\tel_venv\\Lib\\site-packages\\urllib3\\util\\retry.py\", line 515, in increment\n    raise MaxRetryError(_pool, url, reason) from reason  # type: ignore[arg-type]\n    ^^^^^^^^^^^^^^^^^^^^^^^^^^^^^^^^^^^^^^^^^^^^^^^^^^^\nurllib3.exceptions.MaxRetryError: HTTPSConnectionPool(host='demo-langservice-mij.cognitiveservices.azure.com', port=443): Max retries exceeded with url: //language/:analyze-text?api-version=2022-05-01 (Caused by NameResolutionError(\"<urllib3.connection.HTTPSConnection object at 0x0000027AAA55EAD0>: Failed to resolve 'demo-langservice-mij.cognitiveservices.azure.com' ([Errno 11001] getaddrinfo failed)\"))\n\nDuring handling of the above exception, another exception occurred:\n\nTraceback (most recent call last):\n  File \"C:\\Celebal data\\Clients\\Telecom Egypt\\fastapi\\Telecom%20Egypt%20Internal\\src\\adapters\\keyPhrase.py\", line 41, in send_request\n    response = requests.post(url= url, json= data, headers= headers)\n               ^^^^^^^^^^^^^^^^^^^^^^^^^^^^^^^^^^^^^^^^^^^^^^^^^^^^^\n  File \"C:\\Celebal data\\Clients\\Telecom Egypt\\fastapi\\Telecom%20Egypt%20Internal\\tel_venv\\Lib\\site-packages\\requests\\api.py\", line 115, in post\n    return request(\"post\", url, data=data, json=json, **kwargs)\n           ^^^^^^^^^^^^^^^^^^^^^^^^^^^^^^^^^^^^^^^^^^^^^^^^^^^^\n  File \"C:\\Celebal data\\Clients\\Telecom Egypt\\fastapi\\Telecom%20Egypt%20Internal\\tel_venv\\Lib\\site-packages\\requests\\api.py\", line 59, in request\n    return session.request(method=method, url=url, **kwargs)\n           ^^^^^^^^^^^^^^^^^^^^^^^^^^^^^^^^^^^^^^^^^^^^^^^^^\n  File \"C:\\Celebal data\\Clients\\Telecom Egypt\\fastapi\\Telecom%20Egypt%20Internal\\tel_venv\\Lib\\site-packages\\requests\\sessions.py\", line 589, in request\n    resp = self.send(prep, **send_kwargs)\n           ^^^^^^^^^^^^^^^^^^^^^^^^^^^^^^\n  File \"C:\\Celebal data\\Clients\\Telecom Egypt\\fastapi\\Telecom%20Egypt%20Internal\\tel_venv\\Lib\\site-packages\\requests\\sessions.py\", line 703, in send\n    r = adapter.send(request, **kwargs)\n        ^^^^^^^^^^^^^^^^^^^^^^^^^^^^^^^\n  File \"C:\\Celebal data\\Clients\\Telecom Egypt\\fastapi\\Telecom%20Egypt%20Internal\\tel_venv\\Lib\\site-packages\\requests\\adapters.py\", line 519, in send\n    raise ConnectionError(e, request=request)\nrequests.exceptions.ConnectionError: HTTPSConnectionPool(host='demo-langservice-mij.cognitiveservices.azure.com', port=443): Max retries exceeded with url: //language/:analyze-text?api-version=2022-05-01 (Caused by NameResolutionError(\"<urllib3.connection.HTTPSConnection object at 0x0000027AAA55EAD0>: Failed to resolve 'demo-langservice-mij.cognitiveservices.azure.com' ([Errno 11001] getaddrinfo failed)\"))", "location": "KeyPhrase.py - send_request"}
{"asctime": "2024-06-05 T00:11:56+0530", "message": "An Error Occured ..", "exc_info": "Traceback (most recent call last):\n  File \"C:\\Celebal data\\Clients\\Telecom Egypt\\fastapi\\Telecom%20Egypt%20Internal\\src\\adapters\\keyPhrase.py\", line 53, in keyPhrase_helper\n    if response.status_code == 401:\n       ^^^^^^^^^^^^^^^^^^^^\nAttributeError: 'NoneType' object has no attribute 'status_code'", "location": "KeyPhrase.py - keyPhrase_helper"}
{"asctime": "2024-06-05 T00:11:56+0530", "message": "An Error Occured ..", "exc_info": "Traceback (most recent call last):\n  File \"C:\\Celebal data\\Clients\\Telecom Egypt\\fastapi\\Telecom%20Egypt%20Internal\\src\\adapters\\keyPhrase.py\", line 81, in keyPhrase_pipeline\n    if result[\"status\"] == \"success\":\n       ~~~~~~^^^^^^^^^^\nTypeError: 'NoneType' object is not subscriptable", "location": "KeyPhrase.py - keyPhrase_pipeline"}
{"asctime": "2024-06-05 T00:11:56+0530", "message": "An Error Occured: 'NoneType' object is not iterable", "exc_info": "Traceback (most recent call last):\n  File \"C:\\Celebal data\\Clients\\Telecom Egypt\\fastapi\\Telecom%20Egypt%20Internal\\main.py\", line 346, in pipeline_after_transcription\n    for ls in arabic_result[\"keyPhrases_ls\"]:\nTypeError: 'NoneType' object is not iterable", "location": "main.py - pipeline_after_transcription"}
{"asctime": "2024-06-05 T00:15:00+0530", "message": "An Error Occured ..", "exc_info": "Traceback (most recent call last):\n  File \"C:\\Celebal data\\Clients\\Telecom Egypt\\fastapi\\Telecom%20Egypt%20Internal\\tel_venv\\Lib\\site-packages\\urllib3\\connection.py\", line 198, in _new_conn\n    sock = connection.create_connection(\n           ^^^^^^^^^^^^^^^^^^^^^^^^^^^^^\n  File \"C:\\Celebal data\\Clients\\Telecom Egypt\\fastapi\\Telecom%20Egypt%20Internal\\tel_venv\\Lib\\site-packages\\urllib3\\util\\connection.py\", line 60, in create_connection\n    for res in socket.getaddrinfo(host, port, family, socket.SOCK_STREAM):\n               ^^^^^^^^^^^^^^^^^^^^^^^^^^^^^^^^^^^^^^^^^^^^^^^^^^^^^^^^^^\n  File \"C:\\Users\\MaharshiJasraj\\AppData\\Local\\Programs\\Python\\Python311\\Lib\\socket.py\", line 962, in getaddrinfo\n    for res in _socket.getaddrinfo(host, port, family, type, proto, flags):\n               ^^^^^^^^^^^^^^^^^^^^^^^^^^^^^^^^^^^^^^^^^^^^^^^^^^^^^^^^^^^\nsocket.gaierror: [Errno 11001] getaddrinfo failed\n\nThe above exception was the direct cause of the following exception:\n\nTraceback (most recent call last):\n  File \"C:\\Celebal data\\Clients\\Telecom Egypt\\fastapi\\Telecom%20Egypt%20Internal\\tel_venv\\Lib\\site-packages\\urllib3\\connectionpool.py\", line 793, in urlopen\n    response = self._make_request(\n               ^^^^^^^^^^^^^^^^^^^\n  File \"C:\\Celebal data\\Clients\\Telecom Egypt\\fastapi\\Telecom%20Egypt%20Internal\\tel_venv\\Lib\\site-packages\\urllib3\\connectionpool.py\", line 491, in _make_request\n    raise new_e\n  File \"C:\\Celebal data\\Clients\\Telecom Egypt\\fastapi\\Telecom%20Egypt%20Internal\\tel_venv\\Lib\\site-packages\\urllib3\\connectionpool.py\", line 467, in _make_request\n    self._validate_conn(conn)\n  File \"C:\\Celebal data\\Clients\\Telecom Egypt\\fastapi\\Telecom%20Egypt%20Internal\\tel_venv\\Lib\\site-packages\\urllib3\\connectionpool.py\", line 1099, in _validate_conn\n    conn.connect()\n  File \"C:\\Celebal data\\Clients\\Telecom Egypt\\fastapi\\Telecom%20Egypt%20Internal\\tel_venv\\Lib\\site-packages\\urllib3\\connection.py\", line 616, in connect\n    self.sock = sock = self._new_conn()\n                       ^^^^^^^^^^^^^^^^\n  File \"C:\\Celebal data\\Clients\\Telecom Egypt\\fastapi\\Telecom%20Egypt%20Internal\\tel_venv\\Lib\\site-packages\\urllib3\\connection.py\", line 205, in _new_conn\n    raise NameResolutionError(self.host, self, e) from e\nurllib3.exceptions.NameResolutionError: <urllib3.connection.HTTPSConnection object at 0x0000027AAA543790>: Failed to resolve 'demo-langservice-mij.cognitiveservices.azure.com' ([Errno 11001] getaddrinfo failed)\n\nThe above exception was the direct cause of the following exception:\n\nTraceback (most recent call last):\n  File \"C:\\Celebal data\\Clients\\Telecom Egypt\\fastapi\\Telecom%20Egypt%20Internal\\tel_venv\\Lib\\site-packages\\requests\\adapters.py\", line 486, in send\n    resp = conn.urlopen(\n           ^^^^^^^^^^^^^\n  File \"C:\\Celebal data\\Clients\\Telecom Egypt\\fastapi\\Telecom%20Egypt%20Internal\\tel_venv\\Lib\\site-packages\\urllib3\\connectionpool.py\", line 847, in urlopen\n    retries = retries.increment(\n              ^^^^^^^^^^^^^^^^^^\n  File \"C:\\Celebal data\\Clients\\Telecom Egypt\\fastapi\\Telecom%20Egypt%20Internal\\tel_venv\\Lib\\site-packages\\urllib3\\util\\retry.py\", line 515, in increment\n    raise MaxRetryError(_pool, url, reason) from reason  # type: ignore[arg-type]\n    ^^^^^^^^^^^^^^^^^^^^^^^^^^^^^^^^^^^^^^^^^^^^^^^^^^^\nurllib3.exceptions.MaxRetryError: HTTPSConnectionPool(host='demo-langservice-mij.cognitiveservices.azure.com', port=443): Max retries exceeded with url: //language/:analyze-text?api-version=2022-05-01 (Caused by NameResolutionError(\"<urllib3.connection.HTTPSConnection object at 0x0000027AAA543790>: Failed to resolve 'demo-langservice-mij.cognitiveservices.azure.com' ([Errno 11001] getaddrinfo failed)\"))\n\nDuring handling of the above exception, another exception occurred:\n\nTraceback (most recent call last):\n  File \"C:\\Celebal data\\Clients\\Telecom Egypt\\fastapi\\Telecom%20Egypt%20Internal\\src\\adapters\\keyPhrase.py\", line 41, in send_request\n    response = requests.post(url= url, json= data, headers= headers)\n               ^^^^^^^^^^^^^^^^^^^^^^^^^^^^^^^^^^^^^^^^^^^^^^^^^^^^^\n  File \"C:\\Celebal data\\Clients\\Telecom Egypt\\fastapi\\Telecom%20Egypt%20Internal\\tel_venv\\Lib\\site-packages\\requests\\api.py\", line 115, in post\n    return request(\"post\", url, data=data, json=json, **kwargs)\n           ^^^^^^^^^^^^^^^^^^^^^^^^^^^^^^^^^^^^^^^^^^^^^^^^^^^^\n  File \"C:\\Celebal data\\Clients\\Telecom Egypt\\fastapi\\Telecom%20Egypt%20Internal\\tel_venv\\Lib\\site-packages\\requests\\api.py\", line 59, in request\n    return session.request(method=method, url=url, **kwargs)\n           ^^^^^^^^^^^^^^^^^^^^^^^^^^^^^^^^^^^^^^^^^^^^^^^^^\n  File \"C:\\Celebal data\\Clients\\Telecom Egypt\\fastapi\\Telecom%20Egypt%20Internal\\tel_venv\\Lib\\site-packages\\requests\\sessions.py\", line 589, in request\n    resp = self.send(prep, **send_kwargs)\n           ^^^^^^^^^^^^^^^^^^^^^^^^^^^^^^\n  File \"C:\\Celebal data\\Clients\\Telecom Egypt\\fastapi\\Telecom%20Egypt%20Internal\\tel_venv\\Lib\\site-packages\\requests\\sessions.py\", line 703, in send\n    r = adapter.send(request, **kwargs)\n        ^^^^^^^^^^^^^^^^^^^^^^^^^^^^^^^\n  File \"C:\\Celebal data\\Clients\\Telecom Egypt\\fastapi\\Telecom%20Egypt%20Internal\\tel_venv\\Lib\\site-packages\\requests\\adapters.py\", line 519, in send\n    raise ConnectionError(e, request=request)\nrequests.exceptions.ConnectionError: HTTPSConnectionPool(host='demo-langservice-mij.cognitiveservices.azure.com', port=443): Max retries exceeded with url: //language/:analyze-text?api-version=2022-05-01 (Caused by NameResolutionError(\"<urllib3.connection.HTTPSConnection object at 0x0000027AAA543790>: Failed to resolve 'demo-langservice-mij.cognitiveservices.azure.com' ([Errno 11001] getaddrinfo failed)\"))", "location": "KeyPhrase.py - send_request"}
{"asctime": "2024-06-05 T00:15:00+0530", "message": "An Error Occured ..", "exc_info": "Traceback (most recent call last):\n  File \"C:\\Celebal data\\Clients\\Telecom Egypt\\fastapi\\Telecom%20Egypt%20Internal\\src\\adapters\\keyPhrase.py\", line 53, in keyPhrase_helper\n    if response.status_code == 401:\n       ^^^^^^^^^^^^^^^^^^^^\nAttributeError: 'NoneType' object has no attribute 'status_code'", "location": "KeyPhrase.py - keyPhrase_helper"}
{"asctime": "2024-06-05 T00:15:00+0530", "message": "An Error Occured ..", "exc_info": "Traceback (most recent call last):\n  File \"C:\\Celebal data\\Clients\\Telecom Egypt\\fastapi\\Telecom%20Egypt%20Internal\\src\\adapters\\keyPhrase.py\", line 81, in keyPhrase_pipeline\n    if result[\"status\"] == \"success\":\n       ~~~~~~^^^^^^^^^^\nTypeError: 'NoneType' object is not subscriptable", "location": "KeyPhrase.py - keyPhrase_pipeline"}
{"asctime": "2024-06-05 T00:15:43+0530", "message": "An Error Occured: 'NoneType' object is not iterable", "exc_info": "Traceback (most recent call last):\n  File \"C:\\Celebal data\\Clients\\Telecom Egypt\\fastapi\\Telecom%20Egypt%20Internal\\main.py\", line 337, in pipeline_after_transcription\n    for ls in result[\"keyPhrases_ls\"]:\nTypeError: 'NoneType' object is not iterable", "location": "main.py - pipeline_after_transcription"}
