{"asctime": "2024-06-07 T18:15:22+0530", "message": "An Error Occured ..", "exc_info": "Traceback (most recent call last):\n  File \"C:\\Celebal data\\Clients\\Telecom Egypt\\fastapi\\Telecom%20Egypt%20Internal\\src\\audio\\audio.py\", line 45, in audio_processing\n    sound = AudioSegment.from_mp3(input_path)\n            ^^^^^^^^^^^^^^^^^^^^^^^^^^^^^^^^^\n  File \"C:\\Celebal data\\Clients\\Telecom Egypt\\fastapi\\Telecom%20Egypt%20Internal\\tel_venv\\Lib\\site-packages\\pydub\\audio_segment.py\", line 796, in from_mp3\n    return cls.from_file(file, 'mp3', parameters=parameters)\n           ^^^^^^^^^^^^^^^^^^^^^^^^^^^^^^^^^^^^^^^^^^^^^^^^^\n  File \"C:\\Celebal data\\Clients\\Telecom Egypt\\fastapi\\Telecom%20Egypt%20Internal\\tel_venv\\Lib\\site-packages\\pydub\\audio_segment.py\", line 651, in from_file\n    file, close_file = _fd_or_path_or_tempfile(file, 'rb', tempfile=False)\n                       ^^^^^^^^^^^^^^^^^^^^^^^^^^^^^^^^^^^^^^^^^^^^^^^^^^^\n  File \"C:\\Celebal data\\Clients\\Telecom Egypt\\fastapi\\Telecom%20Egypt%20Internal\\tel_venv\\Lib\\site-packages\\pydub\\utils.py\", line 60, in _fd_or_path_or_tempfile\n    fd = open(fd, mode=mode)\n         ^^^^^^^^^^^^^^^^^^^\nFileNotFoundError: [Errno 2] No such file or directory: 'C:\\\\Celebal data\\\\Clients\\\\Telecom Egypt\\\\fastapi\\\\Telecom%20Egypt%20Internal/source/calls/161316483.wav'", "location": "audio.py - audio_processing"}
{"asctime": "2024-06-07 T18:15:22+0530", "message": "An Error Occured ..", "exc_info": "Traceback (most recent call last):\n  File \"C:\\Celebal data\\Clients\\Telecom Egypt\\fastapi\\Telecom%20Egypt%20Internal\\tel_venv\\Lib\\site-packages\\mutagen\\_util.py\", line 251, in _openfile\n    fileobj = open(filename, \"rb+\" if writable else \"rb\")\n              ^^^^^^^^^^^^^^^^^^^^^^^^^^^^^^^^^^^^^^^^^^^\nFileNotFoundError: [Errno 2] No such file or directory: 'C:\\\\Celebal data\\\\Clients\\\\Telecom Egypt\\\\fastapi\\\\Telecom%20Egypt%20Internal/data/processed_data/161316483.wav'\n\nDuring handling of the above exception, another exception occurred:\n\nTraceback (most recent call last):\n  File \"C:\\Celebal data\\Clients\\Telecom Egypt\\fastapi\\Telecom%20Egypt%20Internal\\main.py\", line 39, in add_to_mapping\n    audio_atrs = get_audio_attrs_for_report(audio_path=audio_file_path)\n                 ^^^^^^^^^^^^^^^^^^^^^^^^^^^^^^^^^^^^^^^^^^^^^^^^^^^^^^\n  File \"C:\\Celebal data\\Clients\\Telecom Egypt\\fastapi\\Telecom%20Egypt%20Internal\\src\\audio\\audio.py\", line 120, in get_audio_attrs_for_report\n    duration = get_audio_duration_in_seconds(path= audio_path)\n               ^^^^^^^^^^^^^^^^^^^^^^^^^^^^^^^^^^^^^^^^^^^^^^^\n  File \"C:\\Celebal data\\Clients\\Telecom Egypt\\fastapi\\Telecom%20Egypt%20Internal\\src\\audio\\audio.py\", line 87, in get_audio_duration_in_seconds\n    audio = WAVE(path)\n           ^^^^^^^^^^\n  File \"C:\\Celebal data\\Clients\\Telecom Egypt\\fastapi\\Telecom%20Egypt%20Internal\\tel_venv\\Lib\\site-packages\\mutagen\\_file.py\", line 48, in __init__\n    self.load(*args, **kwargs)\n  File \"C:\\Celebal data\\Clients\\Telecom Egypt\\fastapi\\Telecom%20Egypt%20Internal\\tel_venv\\Lib\\site-packages\\mutagen\\_util.py\", line 185, in wrapper\n    return func(*args, **kwargs)\n           ^^^^^^^^^^^^^^^^^^^^^\n  File \"C:\\Celebal data\\Clients\\Telecom Egypt\\fastapi\\Telecom%20Egypt%20Internal\\tel_venv\\Lib\\site-packages\\mutagen\\_util.py\", line 154, in wrapper\n    with _openfile(self, filething, filename, fileobj,\n  File \"C:\\Users\\MaharshiJasraj\\AppData\\Local\\Programs\\Python\\Python311\\Lib\\contextlib.py\", line 137, in __enter__\n    return next(self.gen)\n           ^^^^^^^^^^^^^^\n  File \"C:\\Celebal data\\Clients\\Telecom Egypt\\fastapi\\Telecom%20Egypt%20Internal\\tel_venv\\Lib\\site-packages\\mutagen\\_util.py\", line 272, in _openfile\n    raise MutagenError(e)\nmutagen.MutagenError: [Errno 2] No such file or directory: 'C:\\\\Celebal data\\\\Clients\\\\Telecom Egypt\\\\fastapi\\\\Telecom%20Egypt%20Internal/data/processed_data/161316483.wav'", "location": "main.py - add_to_mapping"}
{"asctime": "2024-06-07 T18:15:23+0530", "message": "An Error Occured ..", "exc_info": "Traceback (most recent call last):\n  File \"C:\\Celebal data\\Clients\\Telecom Egypt\\fastapi\\Telecom%20Egypt%20Internal\\src\\adapters\\transcription.py\", line 44, in recognize_from_file\n    conversation_transcriber = speechsdk.transcription.ConversationTranscriber(speech_config=speech_config, audio_config=audio_config)\n                               ^^^^^^^^^^^^^^^^^^^^^^^^^^^^^^^^^^^^^^^^^^^^^^^^^^^^^^^^^^^^^^^^^^^^^^^^^^^^^^^^^^^^^^^^^^^^^^^^^^^^^^^\n  File \"C:\\Celebal data\\Clients\\Telecom Egypt\\fastapi\\Telecom%20Egypt%20Internal\\tel_venv\\Lib\\site-packages\\azure\\cognitiveservices\\speech\\transcription.py\", line 136, in __init__\n    _call_hr_fn(\n  File \"C:\\Celebal data\\Clients\\Telecom Egypt\\fastapi\\Telecom%20Egypt%20Internal\\tel_venv\\Lib\\site-packages\\azure\\cognitiveservices\\speech\\interop.py\", line 62, in _call_hr_fn\n    _raise_if_failed(hr)\n  File \"C:\\Celebal data\\Clients\\Telecom Egypt\\fastapi\\Telecom%20Egypt%20Internal\\tel_venv\\Lib\\site-packages\\azure\\cognitiveservices\\speech\\interop.py\", line 55, in _raise_if_failed\n    __try_get_error(_spx_handle(hr))\n  File \"C:\\Celebal data\\Clients\\Telecom Egypt\\fastapi\\Telecom%20Egypt%20Internal\\tel_venv\\Lib\\site-packages\\azure\\cognitiveservices\\speech\\interop.py\", line 50, in __try_get_error\n    raise RuntimeError(message)\nRuntimeError: Exception with error code: \n[CALL STACK BEGIN]\n\n    > pal_string_to_wstring\n    - pal_string_to_wstring\n    - pal_string_to_wstring\n    - pal_string_to_wstring\n    - pal_string_to_wstring\n    - pal_string_to_wstring\n    - pal_string_to_wstring\n    - pal_string_to_wstring\n    - pal_string_to_wstring\n    - pal_string_to_wstring\n    - pal_string_to_wstring\n    - pal_string_to_wstring\n    - pal_string_to_wstring\n    - pal_string_to_wstring\n    - pal_string_to_wstring\n    - recognizer_create_speech_recognizer_from_config\n\n[CALL STACK END]\n\nException with an error code: 0x8 (SPXERR_FILE_OPEN_FAILED)", "location": "transcription.py - recognize_from_file"}
{"asctime": "2024-06-07 T18:15:23+0530", "message": "An Error Occured ..", "exc_info": "Traceback (most recent call last):\n  File \"C:\\Celebal data\\Clients\\Telecom Egypt\\fastapi\\Telecom%20Egypt%20Internal\\src\\adapters\\translator.py\", line 75, in get_translated_transcriptions\n    with open(transcription_jsonPath, 'r', encoding='utf-8') as file:\n         ^^^^^^^^^^^^^^^^^^^^^^^^^^^^^^^^^^^^^^^^^^^^^^^^^^^\nFileNotFoundError: [Errno 2] No such file or directory: 'C:\\\\Celebal data\\\\Clients\\\\Telecom Egypt\\\\fastapi\\\\Telecom%20Egypt%20Internal/data/audio_analytics/161316483/transcript_output.json'", "location": "main.py - get_translated_transcriptions"}
{"asctime": "2024-06-07 T18:15:23+0530", "message": "An Error Occured: expected str, bytes or os.PathLike object, not NoneType", "exc_info": "Traceback (most recent call last):\n  File \"C:\\Celebal data\\Clients\\Telecom Egypt\\fastapi\\Telecom%20Egypt%20Internal\\main.py\", line 176, in get_kpis\n    with open(transcription_jsonPath, \"r\", encoding=\"utf-8\") as fp:\n         ^^^^^^^^^^^^^^^^^^^^^^^^^^^^^^^^^^^^^^^^^^^^^^^^^^^\nTypeError: expected str, bytes or os.PathLike object, not NoneType", "location": "main.py - pipeline_after_transcription"}
{"asctime": "2024-06-07 T18:15:23+0530", "message": "An Error Occured: [Errno 2] No such file or directory: 'C:\\\\Celebal data\\\\Clients\\\\Telecom Egypt\\\\fastapi\\\\Telecom%20Egypt%20Internal/data/audio_analytics/161316483/transcript_output.json'", "exc_info": "Traceback (most recent call last):\n  File \"C:\\Celebal data\\Clients\\Telecom Egypt\\fastapi\\Telecom%20Egypt%20Internal\\main.py\", line 240, in get_kpis_arabic\n    with open(transciption_jsonpath_arabic, \"r\", encoding=\"utf-8\") as fp:\n         ^^^^^^^^^^^^^^^^^^^^^^^^^^^^^^^^^^^^^^^^^^^^^^^^^^^^^^^^^\nFileNotFoundError: [Errno 2] No such file or directory: 'C:\\\\Celebal data\\\\Clients\\\\Telecom Egypt\\\\fastapi\\\\Telecom%20Egypt%20Internal/data/audio_analytics/161316483/transcript_output.json'", "location": "main.py - pipeline_after_transcription"}
{"asctime": "2024-06-07 T18:15:23+0530", "message": "An Error Occured: 'NoneType' object is not subscriptable", "exc_info": "Traceback (most recent call last):\n  File \"C:\\Celebal data\\Clients\\Telecom Egypt\\fastapi\\Telecom%20Egypt%20Internal\\main.py\", line 332, in pipeline_after_transcription\n    merged_output[\"result\"][\"summary\"] = result[\"summary\"]\n                                         ~~~~~~^^^^^^^^^^^\nTypeError: 'NoneType' object is not subscriptable", "location": "main.py - pipeline_after_transcription"}
{"asctime": "2024-06-07 T18:16:15+0530", "message": "An Error Occured ..", "exc_info": "Traceback (most recent call last):\n  File \"C:\\Celebal data\\Clients\\Telecom Egypt\\fastapi\\Telecom%20Egypt%20Internal\\src\\audio\\audio.py\", line 45, in audio_processing\n    sound = AudioSegment.from_mp3(input_path)\n            ^^^^^^^^^^^^^^^^^^^^^^^^^^^^^^^^^\n  File \"C:\\Celebal data\\Clients\\Telecom Egypt\\fastapi\\Telecom%20Egypt%20Internal\\tel_venv\\Lib\\site-packages\\pydub\\audio_segment.py\", line 796, in from_mp3\n    return cls.from_file(file, 'mp3', parameters=parameters)\n           ^^^^^^^^^^^^^^^^^^^^^^^^^^^^^^^^^^^^^^^^^^^^^^^^^\n  File \"C:\\Celebal data\\Clients\\Telecom Egypt\\fastapi\\Telecom%20Egypt%20Internal\\tel_venv\\Lib\\site-packages\\pydub\\audio_segment.py\", line 651, in from_file\n    file, close_file = _fd_or_path_or_tempfile(file, 'rb', tempfile=False)\n                       ^^^^^^^^^^^^^^^^^^^^^^^^^^^^^^^^^^^^^^^^^^^^^^^^^^^\n  File \"C:\\Celebal data\\Clients\\Telecom Egypt\\fastapi\\Telecom%20Egypt%20Internal\\tel_venv\\Lib\\site-packages\\pydub\\utils.py\", line 60, in _fd_or_path_or_tempfile\n    fd = open(fd, mode=mode)\n         ^^^^^^^^^^^^^^^^^^^\nFileNotFoundError: [Errno 2] No such file or directory: 'C:\\\\Celebal data\\\\Clients\\\\Telecom Egypt\\\\fastapi\\\\Telecom%20Egypt%20Internal/source/calls/161316483.wav'", "location": "audio.py - audio_processing"}
{"asctime": "2024-06-07 T18:16:15+0530", "message": "An Error Occured ..", "exc_info": "Traceback (most recent call last):\n  File \"C:\\Celebal data\\Clients\\Telecom Egypt\\fastapi\\Telecom%20Egypt%20Internal\\tel_venv\\Lib\\site-packages\\mutagen\\_util.py\", line 251, in _openfile\n    fileobj = open(filename, \"rb+\" if writable else \"rb\")\n              ^^^^^^^^^^^^^^^^^^^^^^^^^^^^^^^^^^^^^^^^^^^\nFileNotFoundError: [Errno 2] No such file or directory: 'C:\\\\Celebal data\\\\Clients\\\\Telecom Egypt\\\\fastapi\\\\Telecom%20Egypt%20Internal/data/processed_data/161316483.wav'\n\nDuring handling of the above exception, another exception occurred:\n\nTraceback (most recent call last):\n  File \"C:\\Celebal data\\Clients\\Telecom Egypt\\fastapi\\Telecom%20Egypt%20Internal\\main.py\", line 39, in add_to_mapping\n    audio_atrs = get_audio_attrs_for_report(audio_path=audio_file_path)\n                 ^^^^^^^^^^^^^^^^^^^^^^^^^^^^^^^^^^^^^^^^^^^^^^^^^^^^^^\n  File \"C:\\Celebal data\\Clients\\Telecom Egypt\\fastapi\\Telecom%20Egypt%20Internal\\src\\audio\\audio.py\", line 120, in get_audio_attrs_for_report\n    duration = get_audio_duration_in_seconds(path= audio_path)\n               ^^^^^^^^^^^^^^^^^^^^^^^^^^^^^^^^^^^^^^^^^^^^^^^\n  File \"C:\\Celebal data\\Clients\\Telecom Egypt\\fastapi\\Telecom%20Egypt%20Internal\\src\\audio\\audio.py\", line 87, in get_audio_duration_in_seconds\n    audio = WAVE(path)\n           ^^^^^^^^^^\n  File \"C:\\Celebal data\\Clients\\Telecom Egypt\\fastapi\\Telecom%20Egypt%20Internal\\tel_venv\\Lib\\site-packages\\mutagen\\_file.py\", line 48, in __init__\n    self.load(*args, **kwargs)\n  File \"C:\\Celebal data\\Clients\\Telecom Egypt\\fastapi\\Telecom%20Egypt%20Internal\\tel_venv\\Lib\\site-packages\\mutagen\\_util.py\", line 185, in wrapper\n    return func(*args, **kwargs)\n           ^^^^^^^^^^^^^^^^^^^^^\n  File \"C:\\Celebal data\\Clients\\Telecom Egypt\\fastapi\\Telecom%20Egypt%20Internal\\tel_venv\\Lib\\site-packages\\mutagen\\_util.py\", line 154, in wrapper\n    with _openfile(self, filething, filename, fileobj,\n  File \"C:\\Users\\MaharshiJasraj\\AppData\\Local\\Programs\\Python\\Python311\\Lib\\contextlib.py\", line 137, in __enter__\n    return next(self.gen)\n           ^^^^^^^^^^^^^^\n  File \"C:\\Celebal data\\Clients\\Telecom Egypt\\fastapi\\Telecom%20Egypt%20Internal\\tel_venv\\Lib\\site-packages\\mutagen\\_util.py\", line 272, in _openfile\n    raise MutagenError(e)\nmutagen.MutagenError: [Errno 2] No such file or directory: 'C:\\\\Celebal data\\\\Clients\\\\Telecom Egypt\\\\fastapi\\\\Telecom%20Egypt%20Internal/data/processed_data/161316483.wav'", "location": "main.py - add_to_mapping"}
{"asctime": "2024-06-07 T18:16:15+0530", "message": "An Error Occured ..", "exc_info": "Traceback (most recent call last):\n  File \"C:\\Celebal data\\Clients\\Telecom Egypt\\fastapi\\Telecom%20Egypt%20Internal\\src\\adapters\\transcription.py\", line 44, in recognize_from_file\n    conversation_transcriber = speechsdk.transcription.ConversationTranscriber(speech_config=speech_config, audio_config=audio_config)\n                               ^^^^^^^^^^^^^^^^^^^^^^^^^^^^^^^^^^^^^^^^^^^^^^^^^^^^^^^^^^^^^^^^^^^^^^^^^^^^^^^^^^^^^^^^^^^^^^^^^^^^^^^\n  File \"C:\\Celebal data\\Clients\\Telecom Egypt\\fastapi\\Telecom%20Egypt%20Internal\\tel_venv\\Lib\\site-packages\\azure\\cognitiveservices\\speech\\transcription.py\", line 136, in __init__\n    _call_hr_fn(\n  File \"C:\\Celebal data\\Clients\\Telecom Egypt\\fastapi\\Telecom%20Egypt%20Internal\\tel_venv\\Lib\\site-packages\\azure\\cognitiveservices\\speech\\interop.py\", line 62, in _call_hr_fn\n    _raise_if_failed(hr)\n  File \"C:\\Celebal data\\Clients\\Telecom Egypt\\fastapi\\Telecom%20Egypt%20Internal\\tel_venv\\Lib\\site-packages\\azure\\cognitiveservices\\speech\\interop.py\", line 55, in _raise_if_failed\n    __try_get_error(_spx_handle(hr))\n  File \"C:\\Celebal data\\Clients\\Telecom Egypt\\fastapi\\Telecom%20Egypt%20Internal\\tel_venv\\Lib\\site-packages\\azure\\cognitiveservices\\speech\\interop.py\", line 50, in __try_get_error\n    raise RuntimeError(message)\nRuntimeError: Exception with error code: \n[CALL STACK BEGIN]\n\n    > pal_string_to_wstring\n    - pal_string_to_wstring\n    - pal_string_to_wstring\n    - pal_string_to_wstring\n    - pal_string_to_wstring\n    - pal_string_to_wstring\n    - pal_string_to_wstring\n    - pal_string_to_wstring\n    - pal_string_to_wstring\n    - pal_string_to_wstring\n    - pal_string_to_wstring\n    - pal_string_to_wstring\n    - pal_string_to_wstring\n    - pal_string_to_wstring\n    - pal_string_to_wstring\n    - recognizer_create_speech_recognizer_from_config\n\n[CALL STACK END]\n\nException with an error code: 0x8 (SPXERR_FILE_OPEN_FAILED)", "location": "transcription.py - recognize_from_file"}
{"asctime": "2024-06-07 T18:16:16+0530", "message": "An Error Occured ..", "exc_info": "Traceback (most recent call last):\n  File \"C:\\Celebal data\\Clients\\Telecom Egypt\\fastapi\\Telecom%20Egypt%20Internal\\src\\adapters\\translator.py\", line 75, in get_translated_transcriptions\n    with open(transcription_jsonPath, 'r', encoding='utf-8') as file:\n         ^^^^^^^^^^^^^^^^^^^^^^^^^^^^^^^^^^^^^^^^^^^^^^^^^^^\nFileNotFoundError: [Errno 2] No such file or directory: 'C:\\\\Celebal data\\\\Clients\\\\Telecom Egypt\\\\fastapi\\\\Telecom%20Egypt%20Internal/data/audio_analytics/161316483/transcript_output.json'", "location": "main.py - get_translated_transcriptions"}
{"asctime": "2024-06-07 T18:16:16+0530", "message": "An Error Occured: expected str, bytes or os.PathLike object, not NoneType", "exc_info": "Traceback (most recent call last):\n  File \"C:\\Celebal data\\Clients\\Telecom Egypt\\fastapi\\Telecom%20Egypt%20Internal\\main.py\", line 176, in get_kpis\n    with open(transcription_jsonPath, \"r\", encoding=\"utf-8\") as fp:\n         ^^^^^^^^^^^^^^^^^^^^^^^^^^^^^^^^^^^^^^^^^^^^^^^^^^^\nTypeError: expected str, bytes or os.PathLike object, not NoneType", "location": "main.py - pipeline_after_transcription"}
{"asctime": "2024-06-07 T18:16:16+0530", "message": "An Error Occured: [Errno 2] No such file or directory: 'C:\\\\Celebal data\\\\Clients\\\\Telecom Egypt\\\\fastapi\\\\Telecom%20Egypt%20Internal/data/audio_analytics/161316483/transcript_output.json'", "exc_info": "Traceback (most recent call last):\n  File \"C:\\Celebal data\\Clients\\Telecom Egypt\\fastapi\\Telecom%20Egypt%20Internal\\main.py\", line 240, in get_kpis_arabic\n    with open(transciption_jsonpath_arabic, \"r\", encoding=\"utf-8\") as fp:\n         ^^^^^^^^^^^^^^^^^^^^^^^^^^^^^^^^^^^^^^^^^^^^^^^^^^^^^^^^^\nFileNotFoundError: [Errno 2] No such file or directory: 'C:\\\\Celebal data\\\\Clients\\\\Telecom Egypt\\\\fastapi\\\\Telecom%20Egypt%20Internal/data/audio_analytics/161316483/transcript_output.json'", "location": "main.py - pipeline_after_transcription"}
{"asctime": "2024-06-07 T18:16:16+0530", "message": "An Error Occured: 'NoneType' object is not subscriptable", "exc_info": "Traceback (most recent call last):\n  File \"C:\\Celebal data\\Clients\\Telecom Egypt\\fastapi\\Telecom%20Egypt%20Internal\\main.py\", line 332, in pipeline_after_transcription\n    merged_output[\"result\"][\"summary\"] = result[\"summary\"]\n                                         ~~~~~~^^^^^^^^^^^\nTypeError: 'NoneType' object is not subscriptable", "location": "main.py - pipeline_after_transcription"}
